INFO level - 2024-01-15 15:14:47,280 django.utils.autoreload: "Watching for file changes with StatReloader"
INFO level - 2024-01-15 15:14:57,973 django.utils.autoreload: "C:\Users\kurba\PycharmProjects\AnotherDjango\python_django\mysite\mysite\settings.py changed, reloading."
INFO level - 2024-01-15 15:14:58,474 django.utils.autoreload: "Watching for file changes with StatReloader"
INFO level - 2024-01-15 15:15:05,598 shopapp.views: "Logging for info-level is set"
INFO level - 2024-01-15 15:16:23,689 shopapp.views: "Logging for info-level is set"
INFO level - 2024-01-15 15:25:42,697 django.utils.autoreload: "C:\Users\kurba\PycharmProjects\AnotherDjango\python_django\mysite\mysite\settings.py changed, reloading."
INFO level - 2024-01-15 15:25:43,231 django.utils.autoreload: "Watching for file changes with StatReloader"
INFO level - 2024-01-15 15:25:53,872 django.utils.autoreload: "C:\Users\kurba\PycharmProjects\AnotherDjango\python_django\mysite\mysite\settings.py changed, reloading."
INFO level - 2024-01-15 15:25:54,332 django.utils.autoreload: "Watching for file changes with StatReloader"
INFO level - 2024-01-15 15:26:05,836 django.utils.autoreload: "C:\Users\kurba\PycharmProjects\AnotherDjango\python_django\mysite\mysite\settings.py changed, reloading."
INFO level - 2024-01-15 15:26:06,337 django.utils.autoreload: "Watching for file changes with StatReloader"
INFO level - 2024-01-15 15:26:24,286 django.utils.autoreload: "C:\Users\kurba\PycharmProjects\AnotherDjango\python_django\mysite\mysite\settings.py changed, reloading."
INFO level - 2024-01-15 15:26:24,787 django.utils.autoreload: "Watching for file changes with StatReloader"
INFO level - 2024-01-15 15:26:38,611 django.utils.autoreload: "C:\Users\kurba\PycharmProjects\AnotherDjango\python_django\mysite\mysite\settings.py changed, reloading."
INFO level - 2024-01-15 15:26:39,065 django.utils.autoreload: "Watching for file changes with StatReloader"
INFO level - 2024-01-15 15:26:45,603 django.utils.autoreload: "C:\Users\kurba\PycharmProjects\AnotherDjango\python_django\mysite\mysite\settings.py changed, reloading."
INFO level - 2024-01-15 15:26:46,169 django.utils.autoreload: "Watching for file changes with StatReloader"
INFO level - 2024-01-15 15:26:50,663 django.utils.autoreload: "C:\Users\kurba\PycharmProjects\AnotherDjango\python_django\mysite\mysite\settings.py changed, reloading."
INFO level - 2024-01-15 15:26:51,101 django.utils.autoreload: "Watching for file changes with StatReloader"
INFO level - 2024-01-15 15:27:01,788 django.utils.autoreload: "C:\Users\kurba\PycharmProjects\AnotherDjango\python_django\mysite\mysite\settings.py changed, reloading."
INFO level - 2024-01-15 15:27:02,285 django.utils.autoreload: "Watching for file changes with StatReloader"
INFO level - 2024-01-15 15:27:10,878 django.utils.autoreload: "C:\Users\kurba\PycharmProjects\AnotherDjango\python_django\mysite\mysite\settings.py changed, reloading."
INFO level - 2024-01-15 15:27:11,384 django.utils.autoreload: "Watching for file changes with StatReloader"
INFO level - 2024-01-15 15:27:16,898 django.utils.autoreload: "C:\Users\kurba\PycharmProjects\AnotherDjango\python_django\mysite\mysite\settings.py changed, reloading."
INFO level - 2024-01-15 15:27:17,405 django.utils.autoreload: "Watching for file changes with StatReloader"
INFO level - 2024-01-15 15:28:07,109 django.utils.autoreload: "C:\Users\kurba\PycharmProjects\AnotherDjango\python_django\mysite\mysite\settings.py changed, reloading."
INFO level - 2024-01-15 15:28:07,572 django.utils.autoreload: "Watching for file changes with StatReloader"
INFO level - 2024-01-15 15:28:11,011 django.utils.autoreload: "C:\Users\kurba\PycharmProjects\AnotherDjango\python_django\mysite\mysite\settings.py changed, reloading."
INFO level - 2024-01-15 15:29:13,722 django.utils.autoreload: "Watching for file changes with StatReloader"
INFO level - 2024-01-15 15:29:47,362 shopapp.views: "Logging for info-level is set"
ERROR level - 2024-01-15 15:29:47,762 django.request: "Internal Server Error: /ru/shop/"
Traceback (most recent call last):
  File "C:\Users\kurba\PycharmProjects\AnotherDjango\venv\Lib\site-packages\django\urls\base.py", line 71, in reverse
    extra, resolver = resolver.namespace_dict[ns]
                      ~~~~~~~~~~~~~~~~~~~~~~~^^^^
KeyError: 'djdt'

During handling of the above exception, another exception occurred:

Traceback (most recent call last):
  File "C:\Users\kurba\PycharmProjects\AnotherDjango\venv\Lib\site-packages\django\core\handlers\exception.py", line 55, in inner
    response = get_response(request)
               ^^^^^^^^^^^^^^^^^^^^^
  File "C:\Users\kurba\PycharmProjects\AnotherDjango\venv\Lib\site-packages\debug_toolbar\middleware.py", line 74, in __call__
    rendered = toolbar.render_toolbar()
               ^^^^^^^^^^^^^^^^^^^^^^^^
  File "C:\Users\kurba\PycharmProjects\AnotherDjango\venv\Lib\site-packages\debug_toolbar\toolbar.py", line 82, in render_toolbar
    return render_to_string("debug_toolbar/base.html", context)
           ^^^^^^^^^^^^^^^^^^^^^^^^^^^^^^^^^^^^^^^^^^^^^^^^^^^^
  File "C:\Users\kurba\PycharmProjects\AnotherDjango\venv\Lib\site-packages\django\template\loader.py", line 62, in render_to_string
    return template.render(context, request)
           ^^^^^^^^^^^^^^^^^^^^^^^^^^^^^^^^^
  File "C:\Users\kurba\PycharmProjects\AnotherDjango\venv\Lib\site-packages\django\template\backends\django.py", line 61, in render
    return self.template.render(context)
           ^^^^^^^^^^^^^^^^^^^^^^^^^^^^^
  File "C:\Users\kurba\PycharmProjects\AnotherDjango\venv\Lib\site-packages\django\template\base.py", line 175, in render
    return self._render(context)
           ^^^^^^^^^^^^^^^^^^^^^
  File "C:\Users\kurba\PycharmProjects\AnotherDjango\venv\Lib\site-packages\django\test\utils.py", line 112, in instrumented_test_render
    return self.nodelist.render(context)
           ^^^^^^^^^^^^^^^^^^^^^^^^^^^^^
  File "C:\Users\kurba\PycharmProjects\AnotherDjango\venv\Lib\site-packages\django\template\base.py", line 1005, in render
    return SafeString("".join([node.render_annotated(context) for node in self]))
                              ^^^^^^^^^^^^^^^^^^^^^^^^^^^^^^^^^^^^^^^^^^^^^^^^^
  File "C:\Users\kurba\PycharmProjects\AnotherDjango\venv\Lib\site-packages\django\template\base.py", line 1005, in <listcomp>
    return SafeString("".join([node.render_annotated(context) for node in self]))
                               ^^^^^^^^^^^^^^^^^^^^^^^^^^^^^^
  File "C:\Users\kurba\PycharmProjects\AnotherDjango\venv\Lib\site-packages\django\template\base.py", line 966, in render_annotated
    return self.render(context)
           ^^^^^^^^^^^^^^^^^^^^
  File "C:\Users\kurba\PycharmProjects\AnotherDjango\venv\Lib\site-packages\django\template\defaulttags.py", line 321, in render
    return nodelist.render(context)
           ^^^^^^^^^^^^^^^^^^^^^^^^
  File "C:\Users\kurba\PycharmProjects\AnotherDjango\venv\Lib\site-packages\django\template\base.py", line 1005, in render
    return SafeString("".join([node.render_annotated(context) for node in self]))
                              ^^^^^^^^^^^^^^^^^^^^^^^^^^^^^^^^^^^^^^^^^^^^^^^^^
  File "C:\Users\kurba\PycharmProjects\AnotherDjango\venv\Lib\site-packages\django\template\base.py", line 1005, in <listcomp>
    return SafeString("".join([node.render_annotated(context) for node in self]))
                               ^^^^^^^^^^^^^^^^^^^^^^^^^^^^^^
  File "C:\Users\kurba\PycharmProjects\AnotherDjango\venv\Lib\site-packages\django\template\base.py", line 966, in render_annotated
    return self.render(context)
           ^^^^^^^^^^^^^^^^^^^^
  File "C:\Users\kurba\PycharmProjects\AnotherDjango\venv\Lib\site-packages\django\template\defaulttags.py", line 471, in render
    url = reverse(view_name, args=args, kwargs=kwargs, current_app=current_app)
          ^^^^^^^^^^^^^^^^^^^^^^^^^^^^^^^^^^^^^^^^^^^^^^^^^^^^^^^^^^^^^^^^^^^^^
  File "C:\Users\kurba\PycharmProjects\AnotherDjango\venv\Lib\site-packages\django\urls\base.py", line 82, in reverse
    raise NoReverseMatch("%s is not a registered namespace" % key)
django.urls.exceptions.NoReverseMatch: 'djdt' is not a registered namespace
INFO level - 2024-01-15 15:30:34,314 django.utils.autoreload: "C:\Users\kurba\PycharmProjects\AnotherDjango\python_django\mysite\mysite\settings.py changed, reloading."
INFO level - 2024-01-15 15:30:34,844 django.utils.autoreload: "Watching for file changes with StatReloader"
INFO level - 2024-01-15 15:31:30,248 django.utils.autoreload: "C:\Users\kurba\PycharmProjects\AnotherDjango\python_django\mysite\mysite\urls.py changed, reloading."
INFO level - 2024-01-15 15:31:30,718 django.utils.autoreload: "Watching for file changes with StatReloader"
INFO level - 2024-01-15 15:31:50,709 django.utils.autoreload: "C:\Users\kurba\PycharmProjects\AnotherDjango\python_django\mysite\mysite\urls.py changed, reloading."
INFO level - 2024-01-15 15:31:51,274 django.utils.autoreload: "Watching for file changes with StatReloader"
INFO level - 2024-01-15 15:31:56,769 django.utils.autoreload: "C:\Users\kurba\PycharmProjects\AnotherDjango\python_django\mysite\mysite\urls.py changed, reloading."
INFO level - 2024-01-15 15:31:57,258 django.utils.autoreload: "Watching for file changes with StatReloader"
INFO level - 2024-01-15 15:32:09,874 django.utils.autoreload: "C:\Users\kurba\PycharmProjects\AnotherDjango\python_django\mysite\mysite\urls.py changed, reloading."
INFO level - 2024-01-15 15:32:10,349 django.utils.autoreload: "Watching for file changes with StatReloader"
INFO level - 2024-01-15 15:32:19,826 django.utils.autoreload: "C:\Users\kurba\PycharmProjects\AnotherDjango\python_django\mysite\mysite\urls.py changed, reloading."
INFO level - 2024-01-15 15:32:20,286 django.utils.autoreload: "Watching for file changes with StatReloader"
INFO level - 2024-01-15 15:32:59,840 django.utils.autoreload: "Watching for file changes with StatReloader"
INFO level - 2024-01-15 15:33:03,206 shopapp.views: "Logging for info-level is set"
INFO level - 2024-01-15 23:12:16,551 django.utils.autoreload: "Watching for file changes with StatReloader"
WARNING level - 2024-01-15 23:12:19,590 django.request: "Not Found: /"
INFO level - 2024-01-15 23:13:10,480 django.utils.autoreload: "C:\Users\kurba\PycharmProjects\AnotherDjango\python_django\mysite\shopapp\views.py changed, reloading."
INFO level - 2024-01-15 23:13:11,212 django.utils.autoreload: "Watching for file changes with StatReloader"
INFO level - 2024-01-15 23:13:17,062 shopapp.views: "Logging for info-level is set"
ERROR level - 2024-01-15 23:13:17,121 django.request: "Internal Server Error: /ru/shop/"
Traceback (most recent call last):
  File "C:\Users\kurba\PycharmProjects\AnotherDjango\venv\Lib\site-packages\django\core\handlers\exception.py", line 55, in inner
    response = get_response(request)
               ^^^^^^^^^^^^^^^^^^^^^
  File "C:\Users\kurba\PycharmProjects\AnotherDjango\venv\Lib\site-packages\django\core\handlers\base.py", line 197, in _get_response
    response = wrapped_callback(request, *callback_args, **callback_kwargs)
               ^^^^^^^^^^^^^^^^^^^^^^^^^^^^^^^^^^^^^^^^^^^^^^^^^^^^^^^^^^^^
  File "C:\Users\kurba\PycharmProjects\AnotherDjango\venv\Lib\site-packages\sentry_sdk\integrations\django\views.py", line 84, in sentry_wrapped_callback
    return callback(request, *args, **kwargs)
           ^^^^^^^^^^^^^^^^^^^^^^^^^^^^^^^^^^
  File "C:\Users\kurba\PycharmProjects\AnotherDjango\python_django\mysite\shopapp\views.py", line 47, in shop_index
    print(1/0)
          ~^~
ZeroDivisionError: division by zero
INFO level - 2024-01-15 23:13:33,672 shopapp.views: "Logging for info-level is set"
ERROR level - 2024-01-15 23:13:33,745 django.request: "Internal Server Error: /ru/shop/"
Traceback (most recent call last):
  File "C:\Users\kurba\PycharmProjects\AnotherDjango\venv\Lib\site-packages\django\core\handlers\exception.py", line 55, in inner
    response = get_response(request)
               ^^^^^^^^^^^^^^^^^^^^^
  File "C:\Users\kurba\PycharmProjects\AnotherDjango\venv\Lib\site-packages\django\core\handlers\base.py", line 197, in _get_response
    response = wrapped_callback(request, *callback_args, **callback_kwargs)
               ^^^^^^^^^^^^^^^^^^^^^^^^^^^^^^^^^^^^^^^^^^^^^^^^^^^^^^^^^^^^
  File "C:\Users\kurba\PycharmProjects\AnotherDjango\venv\Lib\site-packages\sentry_sdk\integrations\django\views.py", line 84, in sentry_wrapped_callback
    return callback(request, *args, **kwargs)
           ^^^^^^^^^^^^^^^^^^^^^^^^^^^^^^^^^^
  File "C:\Users\kurba\PycharmProjects\AnotherDjango\python_django\mysite\shopapp\views.py", line 47, in shop_index
    print(1/0)
          ~^~
ZeroDivisionError: division by zero
INFO level - 2024-01-15 23:14:42,913 django.utils.autoreload: "C:\Users\kurba\PycharmProjects\AnotherDjango\python_django\mysite\shopapp\views.py changed, reloading."
INFO level - 2024-01-15 23:14:43,589 django.utils.autoreload: "Watching for file changes with StatReloader"
INFO level - 2024-01-15 23:15:05,925 shopapp.views: "Logging for info-level is set"
INFO level - 2024-01-15 23:19:57,021 shopapp.views: "Logging for info-level is set"
INFO level - 2024-01-18 14:41:18,982 django.utils.autoreload: "Watching for file changes with StatReloader"
INFO level - 2024-01-18 14:49:28,656 django.utils.autoreload: "Watching for file changes with StatReloader"
INFO level - 2024-01-18 14:56:20,826 django.utils.autoreload: "Watching for file changes with StatReloader"
INFO level - 2024-01-18 15:00:43,470 django.utils.autoreload: "C:\Users\kurba\PycharmProjects\AnotherDjango\python_django\mysite\mysite\settings.py changed, reloading."
INFO level - 2024-01-18 15:00:44,349 django.utils.autoreload: "Watching for file changes with StatReloader"
INFO level - 2024-01-18 15:01:35,828 django.utils.autoreload: "C:\Users\kurba\PycharmProjects\AnotherDjango\python_django\mysite\mysite\urls.py changed, reloading."
INFO level - 2024-01-18 15:01:36,914 django.utils.autoreload: "Watching for file changes with StatReloader"
WARNING level - 2024-01-18 15:01:39,441 django.request: "Not Found: /"
ERROR level - 2024-01-18 15:01:51,645 django.request: "Internal Server Error: /sitemap.xml"
Traceback (most recent call last):
  File "C:\Users\kurba\PycharmProjects\AnotherDjango\venv\Lib\site-packages\django\core\handlers\exception.py", line 55, in inner
    response = get_response(request)
               ^^^^^^^^^^^^^^^^^^^^^
  File "C:\Users\kurba\PycharmProjects\AnotherDjango\venv\Lib\site-packages\django\core\handlers\base.py", line 197, in _get_response
    response = wrapped_callback(request, *callback_args, **callback_kwargs)
               ^^^^^^^^^^^^^^^^^^^^^^^^^^^^^^^^^^^^^^^^^^^^^^^^^^^^^^^^^^^^
  File "C:\Users\kurba\PycharmProjects\AnotherDjango\venv\Lib\site-packages\sentry_sdk\integrations\django\views.py", line 84, in sentry_wrapped_callback
    return callback(request, *args, **kwargs)
           ^^^^^^^^^^^^^^^^^^^^^^^^^^^^^^^^^^
  File "C:\Users\kurba\PycharmProjects\AnotherDjango\venv\Lib\site-packages\django\contrib\sitemaps\views.py", line 34, in inner
    response = func(request, *args, **kwargs)
               ^^^^^^^^^^^^^^^^^^^^^^^^^^^^^^
  File "C:\Users\kurba\PycharmProjects\AnotherDjango\venv\Lib\site-packages\django\contrib\sitemaps\views.py", line 128, in sitemap
    urls.extend(site.get_urls(page=page, site=req_site, protocol=req_protocol))
                ^^^^^^^^^^^^^^^^^^^^^^^^^^^^^^^^^^^^^^^^^^^^^^^^^^^^^^^^^^^^^^
  File "C:\Users\kurba\PycharmProjects\AnotherDjango\venv\Lib\site-packages\django\contrib\sitemaps\__init__.py", line 167, in get_urls
    return self._urls(page, protocol, domain)
           ^^^^^^^^^^^^^^^^^^^^^^^^^^^^^^^^^^
  File "C:\Users\kurba\PycharmProjects\AnotherDjango\venv\Lib\site-packages\django\contrib\sitemaps\__init__.py", line 187, in _urls
    loc = f"{protocol}://{domain}{self._location(item)}"
                                  ^^^^^^^^^^^^^^^^^^^^
  File "C:\Users\kurba\PycharmProjects\AnotherDjango\venv\Lib\site-packages\django\contrib\sitemaps\__init__.py", line 122, in _location
    return self._get("location", item)
           ^^^^^^^^^^^^^^^^^^^^^^^^^^^
  File "C:\Users\kurba\PycharmProjects\AnotherDjango\venv\Lib\site-packages\django\contrib\sitemaps\__init__.py", line 92, in _get
    return attr(item)
           ^^^^^^^^^^
  File "C:\Users\kurba\PycharmProjects\AnotherDjango\venv\Lib\site-packages\django\contrib\sitemaps\__init__.py", line 132, in location
    return item.get_absolute_url()
           ^^^^^^^^^^^^^^^^^^^^^^^
  File "C:\Users\kurba\PycharmProjects\AnotherDjango\python_django\mysite\shopapp\models.py", line 27, in get_absolute_url
    return reverse('shopapp:product_detail')
           ^^^^^^^^^^^^^^^^^^^^^^^^^^^^^^^^^
  File "C:\Users\kurba\PycharmProjects\AnotherDjango\venv\Lib\site-packages\django\urls\base.py", line 88, in reverse
    return resolver._reverse_with_prefix(view, prefix, *args, **kwargs)
           ^^^^^^^^^^^^^^^^^^^^^^^^^^^^^^^^^^^^^^^^^^^^^^^^^^^^^^^^^^^^
  File "C:\Users\kurba\PycharmProjects\AnotherDjango\venv\Lib\site-packages\django\urls\resolvers.py", line 828, in _reverse_with_prefix
    raise NoReverseMatch(msg)
django.urls.exceptions.NoReverseMatch: Reverse for 'product_detail' with no arguments not found. 1 pattern(s) tried: ['ru/shop/products/(?P<pk>[0-9]+)/\\Z']
INFO level - 2024-01-18 15:03:58,167 django.utils.autoreload: "C:\Users\kurba\PycharmProjects\AnotherDjango\python_django\mysite\shopapp\models.py changed, reloading."
INFO level - 2024-01-18 15:03:59,024 django.utils.autoreload: "Watching for file changes with StatReloader"
INFO level - 2024-01-18 15:04:07,627 django.utils.autoreload: "C:\Users\kurba\PycharmProjects\AnotherDjango\python_django\mysite\shopapp\models.py changed, reloading."
INFO level - 2024-01-18 15:04:08,332 django.utils.autoreload: "Watching for file changes with StatReloader"
INFO level - 2024-01-18 15:04:45,086 django.utils.autoreload: "C:\Users\kurba\PycharmProjects\AnotherDjango\python_django\mysite\shopapp\models.py changed, reloading."
INFO level - 2024-01-18 15:04:45,886 django.utils.autoreload: "Watching for file changes with StatReloader"
INFO level - 2024-01-18 15:06:45,229 django.utils.autoreload: "C:\Users\kurba\PycharmProjects\AnotherDjango\python_django\mysite\shopapp\sitemap.py changed, reloading."
INFO level - 2024-01-18 15:06:46,124 django.utils.autoreload: "Watching for file changes with StatReloader"
ERROR level - 2024-01-18 15:06:46,799 django.request: "Internal Server Error: /sitemap.xml"
Traceback (most recent call last):
  File "C:\Users\kurba\PycharmProjects\AnotherDjango\venv\Lib\site-packages\django\core\handlers\exception.py", line 55, in inner
    response = get_response(request)
               ^^^^^^^^^^^^^^^^^^^^^
  File "C:\Users\kurba\PycharmProjects\AnotherDjango\venv\Lib\site-packages\django\core\handlers\base.py", line 197, in _get_response
    response = wrapped_callback(request, *callback_args, **callback_kwargs)
               ^^^^^^^^^^^^^^^^^^^^^^^^^^^^^^^^^^^^^^^^^^^^^^^^^^^^^^^^^^^^
  File "C:\Users\kurba\PycharmProjects\AnotherDjango\venv\Lib\site-packages\sentry_sdk\integrations\django\views.py", line 84, in sentry_wrapped_callback
    return callback(request, *args, **kwargs)
           ^^^^^^^^^^^^^^^^^^^^^^^^^^^^^^^^^^
  File "C:\Users\kurba\PycharmProjects\AnotherDjango\venv\Lib\site-packages\django\contrib\sitemaps\views.py", line 34, in inner
    response = func(request, *args, **kwargs)
               ^^^^^^^^^^^^^^^^^^^^^^^^^^^^^^
  File "C:\Users\kurba\PycharmProjects\AnotherDjango\venv\Lib\site-packages\django\contrib\sitemaps\views.py", line 128, in sitemap
    urls.extend(site.get_urls(page=page, site=req_site, protocol=req_protocol))
                ^^^^^^^^^^^^^^^^^^^^^^^^^^^^^^^^^^^^^^^^^^^^^^^^^^^^^^^^^^^^^^
  File "C:\Users\kurba\PycharmProjects\AnotherDjango\venv\Lib\site-packages\django\contrib\sitemaps\__init__.py", line 167, in get_urls
    return self._urls(page, protocol, domain)
           ^^^^^^^^^^^^^^^^^^^^^^^^^^^^^^^^^^
  File "C:\Users\kurba\PycharmProjects\AnotherDjango\venv\Lib\site-packages\django\contrib\sitemaps\__init__.py", line 187, in _urls
    loc = f"{protocol}://{domain}{self._location(item)}"
                                  ^^^^^^^^^^^^^^^^^^^^
  File "C:\Users\kurba\PycharmProjects\AnotherDjango\venv\Lib\site-packages\django\contrib\sitemaps\__init__.py", line 122, in _location
    return self._get("location", item)
           ^^^^^^^^^^^^^^^^^^^^^^^^^^^
  File "C:\Users\kurba\PycharmProjects\AnotherDjango\venv\Lib\site-packages\django\contrib\sitemaps\__init__.py", line 92, in _get
    return attr(item)
           ^^^^^^^^^^
  File "C:\Users\kurba\PycharmProjects\AnotherDjango\python_django\mysite\shopapp\sitemap.py", line 15, in location
    return reverse(item)
           ^^^^^^^^^^^^^
  File "C:\Users\kurba\PycharmProjects\AnotherDjango\venv\Lib\site-packages\django\urls\base.py", line 88, in reverse
    return resolver._reverse_with_prefix(view, prefix, *args, **kwargs)
           ^^^^^^^^^^^^^^^^^^^^^^^^^^^^^^^^^^^^^^^^^^^^^^^^^^^^^^^^^^^^
  File "C:\Users\kurba\PycharmProjects\AnotherDjango\venv\Lib\site-packages\django\urls\resolvers.py", line 828, in _reverse_with_prefix
    raise NoReverseMatch(msg)
django.urls.exceptions.NoReverseMatch: Reverse for 'orders_list' not found. 'orders_list' is not a valid view function or pattern name.
ERROR level - 2024-01-18 15:06:48,387 django.request: "Internal Server Error: /sitemap.xml"
Traceback (most recent call last):
  File "C:\Users\kurba\PycharmProjects\AnotherDjango\venv\Lib\site-packages\django\core\handlers\exception.py", line 55, in inner
    response = get_response(request)
               ^^^^^^^^^^^^^^^^^^^^^
  File "C:\Users\kurba\PycharmProjects\AnotherDjango\venv\Lib\site-packages\django\core\handlers\base.py", line 197, in _get_response
    response = wrapped_callback(request, *callback_args, **callback_kwargs)
               ^^^^^^^^^^^^^^^^^^^^^^^^^^^^^^^^^^^^^^^^^^^^^^^^^^^^^^^^^^^^
  File "C:\Users\kurba\PycharmProjects\AnotherDjango\venv\Lib\site-packages\sentry_sdk\integrations\django\views.py", line 84, in sentry_wrapped_callback
    return callback(request, *args, **kwargs)
           ^^^^^^^^^^^^^^^^^^^^^^^^^^^^^^^^^^
  File "C:\Users\kurba\PycharmProjects\AnotherDjango\venv\Lib\site-packages\django\contrib\sitemaps\views.py", line 34, in inner
    response = func(request, *args, **kwargs)
               ^^^^^^^^^^^^^^^^^^^^^^^^^^^^^^
  File "C:\Users\kurba\PycharmProjects\AnotherDjango\venv\Lib\site-packages\django\contrib\sitemaps\views.py", line 128, in sitemap
    urls.extend(site.get_urls(page=page, site=req_site, protocol=req_protocol))
                ^^^^^^^^^^^^^^^^^^^^^^^^^^^^^^^^^^^^^^^^^^^^^^^^^^^^^^^^^^^^^^
  File "C:\Users\kurba\PycharmProjects\AnotherDjango\venv\Lib\site-packages\django\contrib\sitemaps\__init__.py", line 167, in get_urls
    return self._urls(page, protocol, domain)
           ^^^^^^^^^^^^^^^^^^^^^^^^^^^^^^^^^^
  File "C:\Users\kurba\PycharmProjects\AnotherDjango\venv\Lib\site-packages\django\contrib\sitemaps\__init__.py", line 187, in _urls
    loc = f"{protocol}://{domain}{self._location(item)}"
                                  ^^^^^^^^^^^^^^^^^^^^
  File "C:\Users\kurba\PycharmProjects\AnotherDjango\venv\Lib\site-packages\django\contrib\sitemaps\__init__.py", line 122, in _location
    return self._get("location", item)
           ^^^^^^^^^^^^^^^^^^^^^^^^^^^
  File "C:\Users\kurba\PycharmProjects\AnotherDjango\venv\Lib\site-packages\django\contrib\sitemaps\__init__.py", line 92, in _get
    return attr(item)
           ^^^^^^^^^^
  File "C:\Users\kurba\PycharmProjects\AnotherDjango\python_django\mysite\shopapp\sitemap.py", line 15, in location
    return reverse(item)
           ^^^^^^^^^^^^^
  File "C:\Users\kurba\PycharmProjects\AnotherDjango\venv\Lib\site-packages\django\urls\base.py", line 88, in reverse
    return resolver._reverse_with_prefix(view, prefix, *args, **kwargs)
           ^^^^^^^^^^^^^^^^^^^^^^^^^^^^^^^^^^^^^^^^^^^^^^^^^^^^^^^^^^^^
  File "C:\Users\kurba\PycharmProjects\AnotherDjango\venv\Lib\site-packages\django\urls\resolvers.py", line 828, in _reverse_with_prefix
    raise NoReverseMatch(msg)
django.urls.exceptions.NoReverseMatch: Reverse for 'orders_list' not found. 'orders_list' is not a valid view function or pattern name.
INFO level - 2024-01-18 15:06:56,333 django.utils.autoreload: "C:\Users\kurba\PycharmProjects\AnotherDjango\python_django\mysite\shopapp\sitemap.py changed, reloading."
INFO level - 2024-01-18 15:06:57,264 django.utils.autoreload: "Watching for file changes with StatReloader"
INFO level - 2024-01-18 15:20:40,171 django.utils.autoreload: "C:\Users\kurba\PycharmProjects\AnotherDjango\python_django\mysite\shopapp\sitemap.py changed, reloading."
INFO level - 2024-01-18 15:20:41,036 django.utils.autoreload: "Watching for file changes with StatReloader"
INFO level - 2024-01-18 16:28:29,090 django.utils.autoreload: "C:\Users\kurba\PycharmProjects\AnotherDjango\python_django\mysite\shopapp\models.py changed, reloading."
INFO level - 2024-01-18 16:28:30,170 django.utils.autoreload: "Watching for file changes with StatReloader"
INFO level - 2024-01-18 16:28:37,699 django.utils.autoreload: "C:\Users\kurba\PycharmProjects\AnotherDjango\python_django\mysite\shopapp\models.py changed, reloading."
INFO level - 2024-01-18 16:28:38,418 django.utils.autoreload: "Watching for file changes with StatReloader"
INFO level - 2024-01-18 16:29:53,513 django.utils.autoreload: "C:\Users\kurba\PycharmProjects\AnotherDjango\python_django\mysite\shopapp\models.py changed, reloading."
INFO level - 2024-01-18 16:29:54,193 django.utils.autoreload: "Watching for file changes with StatReloader"
INFO level - 2024-01-18 16:33:18,883 django.utils.autoreload: "C:\Users\kurba\PycharmProjects\AnotherDjango\python_django\mysite\shopapp\sitemap.py changed, reloading."
INFO level - 2024-01-18 16:33:19,679 django.utils.autoreload: "Watching for file changes with StatReloader"
ERROR level - 2024-01-18 16:33:21,504 django.request: "Internal Server Error: /sitemap.xml"
Traceback (most recent call last):
  File "C:\Users\kurba\PycharmProjects\AnotherDjango\venv\Lib\site-packages\django\db\backends\utils.py", line 89, in _execute
    return self.cursor.execute(sql, params)
           ^^^^^^^^^^^^^^^^^^^^^^^^^^^^^^^^
  File "C:\Users\kurba\PycharmProjects\AnotherDjango\venv\Lib\site-packages\django\db\backends\sqlite3\base.py", line 328, in execute
    return super().execute(query, params)
           ^^^^^^^^^^^^^^^^^^^^^^^^^^^^^^
sqlite3.OperationalError: no such column: shopapp_product.updated_at

The above exception was the direct cause of the following exception:

Traceback (most recent call last):
  File "C:\Users\kurba\PycharmProjects\AnotherDjango\venv\Lib\site-packages\django\core\handlers\exception.py", line 55, in inner
    response = get_response(request)
               ^^^^^^^^^^^^^^^^^^^^^
  File "C:\Users\kurba\PycharmProjects\AnotherDjango\venv\Lib\site-packages\django\core\handlers\base.py", line 197, in _get_response
    response = wrapped_callback(request, *callback_args, **callback_kwargs)
               ^^^^^^^^^^^^^^^^^^^^^^^^^^^^^^^^^^^^^^^^^^^^^^^^^^^^^^^^^^^^
  File "C:\Users\kurba\PycharmProjects\AnotherDjango\venv\Lib\site-packages\sentry_sdk\integrations\django\views.py", line 84, in sentry_wrapped_callback
    return callback(request, *args, **kwargs)
           ^^^^^^^^^^^^^^^^^^^^^^^^^^^^^^^^^^
  File "C:\Users\kurba\PycharmProjects\AnotherDjango\venv\Lib\site-packages\django\contrib\sitemaps\views.py", line 34, in inner
    response = func(request, *args, **kwargs)
               ^^^^^^^^^^^^^^^^^^^^^^^^^^^^^^
  File "C:\Users\kurba\PycharmProjects\AnotherDjango\venv\Lib\site-packages\django\contrib\sitemaps\views.py", line 128, in sitemap
    urls.extend(site.get_urls(page=page, site=req_site, protocol=req_protocol))
                ^^^^^^^^^^^^^^^^^^^^^^^^^^^^^^^^^^^^^^^^^^^^^^^^^^^^^^^^^^^^^^
  File "C:\Users\kurba\PycharmProjects\AnotherDjango\venv\Lib\site-packages\django\contrib\sitemaps\__init__.py", line 167, in get_urls
    return self._urls(page, protocol, domain)
           ^^^^^^^^^^^^^^^^^^^^^^^^^^^^^^^^^^
  File "C:\Users\kurba\PycharmProjects\AnotherDjango\venv\Lib\site-packages\django\contrib\sitemaps\__init__.py", line 186, in _urls
    for item in paginator_page.object_list:
  File "C:\Users\kurba\PycharmProjects\AnotherDjango\venv\Lib\site-packages\django\db\models\query.py", line 398, in __iter__
    self._fetch_all()
  File "C:\Users\kurba\PycharmProjects\AnotherDjango\venv\Lib\site-packages\django\db\models\query.py", line 1881, in _fetch_all
    self._result_cache = list(self._iterable_class(self))
                         ^^^^^^^^^^^^^^^^^^^^^^^^^^^^^^^^
  File "C:\Users\kurba\PycharmProjects\AnotherDjango\venv\Lib\site-packages\django\db\models\query.py", line 91, in __iter__
    results = compiler.execute_sql(
              ^^^^^^^^^^^^^^^^^^^^^
  File "C:\Users\kurba\PycharmProjects\AnotherDjango\venv\Lib\site-packages\django\db\models\sql\compiler.py", line 1562, in execute_sql
    cursor.execute(sql, params)
  File "C:\Users\kurba\PycharmProjects\AnotherDjango\venv\Lib\site-packages\debug_toolbar\panels\sql\tracking.py", line 252, in execute
    return self._record(super().execute, sql, params)
           ^^^^^^^^^^^^^^^^^^^^^^^^^^^^^^^^^^^^^^^^^^
  File "C:\Users\kurba\PycharmProjects\AnotherDjango\venv\Lib\site-packages\debug_toolbar\panels\sql\tracking.py", line 177, in _record
    return method(sql, params)
           ^^^^^^^^^^^^^^^^^^^
  File "C:\Users\kurba\PycharmProjects\AnotherDjango\venv\Lib\site-packages\django\db\backends\utils.py", line 102, in execute
    return super().execute(sql, params)
           ^^^^^^^^^^^^^^^^^^^^^^^^^^^^
  File "C:\Users\kurba\PycharmProjects\AnotherDjango\venv\Lib\site-packages\sentry_sdk\integrations\django\__init__.py", line 641, in execute
    result = real_execute(self, sql, params)
             ^^^^^^^^^^^^^^^^^^^^^^^^^^^^^^^
  File "C:\Users\kurba\PycharmProjects\AnotherDjango\venv\Lib\site-packages\django\db\backends\utils.py", line 67, in execute
    return self._execute_with_wrappers(
           ^^^^^^^^^^^^^^^^^^^^^^^^^^^^
  File "C:\Users\kurba\PycharmProjects\AnotherDjango\venv\Lib\site-packages\django\db\backends\utils.py", line 80, in _execute_with_wrappers
    return executor(sql, params, many, context)
           ^^^^^^^^^^^^^^^^^^^^^^^^^^^^^^^^^^^^
  File "C:\Users\kurba\PycharmProjects\AnotherDjango\venv\Lib\site-packages\django\db\backends\utils.py", line 84, in _execute
    with self.db.wrap_database_errors:
  File "C:\Users\kurba\PycharmProjects\AnotherDjango\venv\Lib\site-packages\django\db\utils.py", line 91, in __exit__
    raise dj_exc_value.with_traceback(traceback) from exc_value
  File "C:\Users\kurba\PycharmProjects\AnotherDjango\venv\Lib\site-packages\django\db\backends\utils.py", line 89, in _execute
    return self.cursor.execute(sql, params)
           ^^^^^^^^^^^^^^^^^^^^^^^^^^^^^^^^
  File "C:\Users\kurba\PycharmProjects\AnotherDjango\venv\Lib\site-packages\django\db\backends\sqlite3\base.py", line 328, in execute
    return super().execute(query, params)
           ^^^^^^^^^^^^^^^^^^^^^^^^^^^^^^
django.db.utils.OperationalError: no such column: shopapp_product.updated_at
INFO level - 2024-01-18 16:46:08,374 django.utils.autoreload: "C:\Users\kurba\PycharmProjects\AnotherDjango\python_django\mysite\shopapp\sitemap.py changed, reloading."
INFO level - 2024-01-18 16:46:09,103 django.utils.autoreload: "Watching for file changes with StatReloader"
INFO level - 2024-01-18 16:54:55,560 django.utils.autoreload: "C:\Users\kurba\PycharmProjects\AnotherDjango\python_django\mysite\shopapp\views.py changed, reloading."
INFO level - 2024-01-18 16:54:56,540 django.utils.autoreload: "Watching for file changes with StatReloader"
INFO level - 2024-01-18 16:55:01,052 django.utils.autoreload: "C:\Users\kurba\PycharmProjects\AnotherDjango\python_django\mysite\shopapp\views.py changed, reloading."
INFO level - 2024-01-18 16:55:01,740 django.utils.autoreload: "Watching for file changes with StatReloader"
INFO level - 2024-01-18 16:55:05,067 django.utils.autoreload: "C:\Users\kurba\PycharmProjects\AnotherDjango\python_django\mysite\shopapp\views.py changed, reloading."
INFO level - 2024-01-18 16:55:05,841 django.utils.autoreload: "Watching for file changes with StatReloader"
INFO level - 2024-01-18 16:55:10,324 django.utils.autoreload: "C:\Users\kurba\PycharmProjects\AnotherDjango\python_django\mysite\shopapp\views.py changed, reloading."
INFO level - 2024-01-18 16:55:11,018 django.utils.autoreload: "Watching for file changes with StatReloader"
INFO level - 2024-01-18 16:55:14,551 django.utils.autoreload: "C:\Users\kurba\PycharmProjects\AnotherDjango\python_django\mysite\shopapp\views.py changed, reloading."
INFO level - 2024-01-18 16:55:15,169 django.utils.autoreload: "Watching for file changes with StatReloader"
INFO level - 2024-01-18 16:58:00,223 django.utils.autoreload: "C:\Users\kurba\PycharmProjects\AnotherDjango\python_django\mysite\shopapp\views.py changed, reloading."
INFO level - 2024-01-18 16:58:01,004 django.utils.autoreload: "Watching for file changes with StatReloader"
INFO level - 2024-01-18 16:59:56,274 django.utils.autoreload: "C:\Users\kurba\PycharmProjects\AnotherDjango\python_django\mysite\shopapp\views.py changed, reloading."
INFO level - 2024-01-18 16:59:57,081 django.utils.autoreload: "Watching for file changes with StatReloader"
INFO level - 2024-01-18 17:00:41,034 django.utils.autoreload: "C:\Users\kurba\PycharmProjects\AnotherDjango\python_django\mysite\shopapp\urls.py changed, reloading."
INFO level - 2024-01-18 17:00:41,753 django.utils.autoreload: "Watching for file changes with StatReloader"
INFO level - 2024-01-18 17:01:33,623 django.utils.autoreload: "C:\Users\kurba\PycharmProjects\AnotherDjango\python_django\mysite\shopapp\urls.py changed, reloading."
INFO level - 2024-01-18 17:01:34,398 django.utils.autoreload: "Watching for file changes with StatReloader"
WARNING level - 2024-01-18 17:02:00,079 django.request: "Not Found: /ru/shop/products/latest/feed"
INFO level - 2024-01-18 17:02:20,474 django.utils.autoreload: "C:\Users\kurba\PycharmProjects\AnotherDjango\python_django\mysite\shopapp\urls.py changed, reloading."
INFO level - 2024-01-18 17:02:21,437 django.utils.autoreload: "Watching for file changes with StatReloader"
ERROR level - 2024-01-18 17:02:21,962 django.request: "Internal Server Error: /ru/shop/products/latest/feed"
Traceback (most recent call last):
  File "C:\Users\kurba\PycharmProjects\AnotherDjango\venv\Lib\site-packages\django\core\handlers\exception.py", line 55, in inner
    response = get_response(request)
               ^^^^^^^^^^^^^^^^^^^^^
  File "C:\Users\kurba\PycharmProjects\AnotherDjango\venv\Lib\site-packages\django\core\handlers\base.py", line 197, in _get_response
    response = wrapped_callback(request, *callback_args, **callback_kwargs)
               ^^^^^^^^^^^^^^^^^^^^^^^^^^^^^^^^^^^^^^^^^^^^^^^^^^^^^^^^^^^^
  File "C:\Users\kurba\PycharmProjects\AnotherDjango\venv\Lib\site-packages\sentry_sdk\integrations\django\views.py", line 84, in sentry_wrapped_callback
    return callback(request, *args, **kwargs)
           ^^^^^^^^^^^^^^^^^^^^^^^^^^^^^^^^^^
TypeError: LatestProductsFeed() takes no arguments
INFO level - 2024-01-18 17:02:46,801 django.utils.autoreload: "C:\Users\kurba\PycharmProjects\AnotherDjango\python_django\mysite\shopapp\urls.py changed, reloading."
INFO level - 2024-01-18 17:02:47,649 django.utils.autoreload: "Watching for file changes with StatReloader"
ERROR level - 2024-01-18 17:02:48,283 django.request: "Internal Server Error: /ru/shop/products/latest/feed"
Traceback (most recent call last):
  File "C:\Users\kurba\PycharmProjects\AnotherDjango\venv\Lib\site-packages\django\core\handlers\exception.py", line 55, in inner
    response = get_response(request)
               ^^^^^^^^^^^^^^^^^^^^^
  File "C:\Users\kurba\PycharmProjects\AnotherDjango\venv\Lib\site-packages\django\core\handlers\base.py", line 197, in _get_response
    response = wrapped_callback(request, *callback_args, **callback_kwargs)
               ^^^^^^^^^^^^^^^^^^^^^^^^^^^^^^^^^^^^^^^^^^^^^^^^^^^^^^^^^^^^
  File "C:\Users\kurba\PycharmProjects\AnotherDjango\venv\Lib\site-packages\sentry_sdk\integrations\django\views.py", line 84, in sentry_wrapped_callback
    return callback(request, *args, **kwargs)
           ^^^^^^^^^^^^^^^^^^^^^^^^^^^^^^^^^^
  File "C:\Users\kurba\PycharmProjects\AnotherDjango\venv\Lib\site-packages\django\contrib\syndication\views.py", line 40, in __call__
    feedgen = self.get_feed(obj, request)
              ^^^^^^^^^^^^^^^^^^^^^^^^^^^
  File "C:\Users\kurba\PycharmProjects\AnotherDjango\venv\Lib\site-packages\django\contrib\syndication\views.py", line 143, in get_feed
    link = add_domain(current_site.domain, link, request.is_secure())
           ^^^^^^^^^^^^^^^^^^^^^^^^^^^^^^^^^^^^^^^^^^^^^^^^^^^^^^^^^^
  File "C:\Users\kurba\PycharmProjects\AnotherDjango\venv\Lib\site-packages\django\contrib\syndication\views.py", line 17, in add_domain
    if url.startswith("//"):
       ^^^^^^^^^^^^^^
AttributeError: 'NoneType' object has no attribute 'startswith'
INFO level - 2024-01-18 17:04:02,899 django.utils.autoreload: "C:\Users\kurba\PycharmProjects\AnotherDjango\python_django\mysite\shopapp\views.py changed, reloading."
INFO level - 2024-01-18 17:04:03,842 django.utils.autoreload: "Watching for file changes with StatReloader"
INFO level - 2024-01-18 17:04:31,169 django.utils.autoreload: "C:\Users\kurba\PycharmProjects\AnotherDjango\python_django\mysite\shopapp\views.py changed, reloading."
INFO level - 2024-01-18 17:04:32,056 django.utils.autoreload: "Watching for file changes with StatReloader"
INFO level - 2024-01-18 17:06:40,167 django.utils.autoreload: "Watching for file changes with StatReloader"
WARNING level - 2024-01-18 17:06:42,186 django.request: "Not Found: /"
INFO level - 2024-01-18 17:06:48,097 shopapp.views: "Logging for info-level is set"
WARNING level - 2024-01-18 17:08:09,783 django.request: "Not Found: /ru/shop/latest/feed"
INFO level - 2024-01-18 17:16:10,106 django.utils.autoreload: "C:\Users\kurba\PycharmProjects\AnotherDjango\python_django\mysite\shopapp\forms.py changed, reloading."
INFO level - 2024-01-18 17:16:10,786 django.utils.autoreload: "Watching for file changes with StatReloader"
INFO level - 2024-01-18 17:17:25,510 django.utils.autoreload: "C:\Users\kurba\PycharmProjects\AnotherDjango\python_django\mysite\shopapp\forms.py changed, reloading."
INFO level - 2024-01-18 17:17:26,134 django.utils.autoreload: "Watching for file changes with StatReloader"
INFO level - 2024-01-18 17:19:43,359 django.utils.autoreload: "C:\Users\kurba\PycharmProjects\AnotherDjango\python_django\mysite\shopapp\admin.py changed, reloading."
INFO level - 2024-01-18 17:19:44,033 django.utils.autoreload: "Watching for file changes with StatReloader"
INFO level - 2024-01-18 17:22:10,578 django.utils.autoreload: "C:\Users\kurba\PycharmProjects\AnotherDjango\python_django\mysite\shopapp\admin.py changed, reloading."
INFO level - 2024-01-18 17:22:11,228 django.utils.autoreload: "Watching for file changes with StatReloader"
INFO level - 2024-01-18 17:48:10,716 django.utils.autoreload: "C:\Users\kurba\PycharmProjects\AnotherDjango\python_django\mysite\shopapp\admin.py changed, reloading."
INFO level - 2024-01-18 17:48:11,621 django.utils.autoreload: "Watching for file changes with StatReloader"
INFO level - 2024-01-19 16:53:19,602 django.utils.autoreload: "C:\Users\kurba\PycharmProjects\AnotherDjango\python_django\mysite\shopapp\admin.py changed, reloading."
INFO level - 2024-01-19 16:53:20,489 django.utils.autoreload: "Watching for file changes with StatReloader"
INFO level - 2024-01-19 17:10:35,710 django.utils.autoreload: "C:\Users\kurba\PycharmProjects\AnotherDjango\python_django\mysite\shopapp\admin.py changed, reloading."
INFO level - 2024-01-19 17:10:36,485 django.utils.autoreload: "Watching for file changes with StatReloader"
INFO level - 2024-01-19 17:10:42,146 django.utils.autoreload: "C:\Users\kurba\PycharmProjects\AnotherDjango\python_django\mysite\shopapp\admin.py changed, reloading."
INFO level - 2024-01-19 17:10:42,882 django.utils.autoreload: "Watching for file changes with StatReloader"
INFO level - 2024-01-19 17:11:45,052 django.utils.autoreload: "C:\Users\kurba\PycharmProjects\AnotherDjango\python_django\mysite\shopapp\admin.py changed, reloading."
INFO level - 2024-01-19 17:11:45,883 django.utils.autoreload: "Watching for file changes with StatReloader"
ERROR level - 2024-01-19 17:12:50,376 django.request: "Internal Server Error: /ru/admin/shopapp/order/import-csv"
Traceback (most recent call last):
  File "C:\Users\kurba\PycharmProjects\AnotherDjango\venv\Lib\site-packages\django\core\handlers\exception.py", line 55, in inner
    response = get_response(request)
               ^^^^^^^^^^^^^^^^^^^^^
  File "C:\Users\kurba\PycharmProjects\AnotherDjango\venv\Lib\site-packages\django\core\handlers\base.py", line 204, in _get_response
    self.check_response(response, callback)
  File "C:\Users\kurba\PycharmProjects\AnotherDjango\venv\Lib\site-packages\django\core\handlers\base.py", line 332, in check_response
    raise ValueError(
ValueError: The view shopapp.admin.method.__call__ didn't return an HttpResponse object. It returned None instead.
INFO level - 2024-01-19 17:13:49,015 django.utils.autoreload: "C:\Users\kurba\PycharmProjects\AnotherDjango\python_django\mysite\shopapp\admin.py changed, reloading."
INFO level - 2024-01-19 17:13:49,889 django.utils.autoreload: "Watching for file changes with StatReloader"
ERROR level - 2024-01-19 17:13:51,058 django.request: "Internal Server Error: /ru/admin/shopapp/order/import-csv"
Traceback (most recent call last):
  File "C:\Users\kurba\PycharmProjects\AnotherDjango\venv\Lib\site-packages\django\core\handlers\exception.py", line 55, in inner
    response = get_response(request)
               ^^^^^^^^^^^^^^^^^^^^^
  File "C:\Users\kurba\PycharmProjects\AnotherDjango\venv\Lib\site-packages\django\core\handlers\base.py", line 204, in _get_response
    self.check_response(response, callback)
  File "C:\Users\kurba\PycharmProjects\AnotherDjango\venv\Lib\site-packages\django\core\handlers\base.py", line 332, in check_response
    raise ValueError(
ValueError: The view shopapp.admin.method.__call__ didn't return an HttpResponse object. It returned None instead.
INFO level - 2024-01-19 17:14:34,808 django.utils.autoreload: "C:\Users\kurba\PycharmProjects\AnotherDjango\python_django\mysite\shopapp\admin.py changed, reloading."
INFO level - 2024-01-19 17:14:35,751 django.utils.autoreload: "Watching for file changes with StatReloader"
INFO level - 2024-01-19 18:01:40,333 django.utils.autoreload: "C:\Users\kurba\PycharmProjects\AnotherDjango\python_django\mysite\shopapp\admin.py changed, reloading."
INFO level - 2024-01-19 18:01:41,189 django.utils.autoreload: "Watching for file changes with StatReloader"
INFO level - 2024-01-19 18:01:44,561 django.utils.autoreload: "C:\Users\kurba\PycharmProjects\AnotherDjango\python_django\mysite\shopapp\admin.py changed, reloading."
INFO level - 2024-01-19 18:01:45,266 django.utils.autoreload: "Watching for file changes with StatReloader"
INFO level - 2024-01-19 18:01:52,981 django.utils.autoreload: "C:\Users\kurba\PycharmProjects\AnotherDjango\python_django\mysite\shopapp\admin.py changed, reloading."
INFO level - 2024-01-19 18:01:53,723 django.utils.autoreload: "Watching for file changes with StatReloader"
INFO level - 2024-01-19 18:02:58,382 django.utils.autoreload: "C:\Users\kurba\PycharmProjects\AnotherDjango\python_django\mysite\shopapp\admin.py changed, reloading."
INFO level - 2024-01-19 18:02:59,108 django.utils.autoreload: "Watching for file changes with StatReloader"
INFO level - 2024-01-19 18:04:35,230 django.utils.autoreload: "C:\Users\kurba\PycharmProjects\AnotherDjango\python_django\mysite\shopapp\admin.py changed, reloading."
INFO level - 2024-01-19 18:04:35,978 django.utils.autoreload: "Watching for file changes with StatReloader"
INFO level - 2024-01-19 19:01:22,308 django.utils.autoreload: "C:\Users\kurba\PycharmProjects\AnotherDjango\python_django\mysite\shopapp\admin.py changed, reloading."
INFO level - 2024-01-19 19:01:23,217 django.utils.autoreload: "Watching for file changes with StatReloader"
ERROR level - 2024-01-19 19:02:02,331 django.request: "Internal Server Error: /ru/admin/shopapp/order/import-csv"
Traceback (most recent call last):
  File "C:\Users\kurba\PycharmProjects\AnotherDjango\venv\Lib\site-packages\django\core\handlers\exception.py", line 55, in inner
    response = get_response(request)
               ^^^^^^^^^^^^^^^^^^^^^
  File "C:\Users\kurba\PycharmProjects\AnotherDjango\venv\Lib\site-packages\django\core\handlers\base.py", line 197, in _get_response
    response = wrapped_callback(request, *callback_args, **callback_kwargs)
               ^^^^^^^^^^^^^^^^^^^^^^^^^^^^^^^^^^^^^^^^^^^^^^^^^^^^^^^^^^^^
  File "C:\Users\kurba\PycharmProjects\AnotherDjango\venv\Lib\site-packages\sentry_sdk\integrations\django\views.py", line 84, in sentry_wrapped_callback
    return callback(request, *args, **kwargs)
           ^^^^^^^^^^^^^^^^^^^^^^^^^^^^^^^^^^
  File "C:\Python311\Lib\contextlib.py", line 81, in inner
    return func(*args, **kwds)
           ^^^^^^^^^^^^^^^^^^^
  File "C:\Users\kurba\PycharmProjects\AnotherDjango\python_django\mysite\shopapp\admin.py", line 69, in import_as_CSV
    users = User.objects.value('username').all()
            ^^^^^^^^^^^^^^^^^^
AttributeError: 'UserManager' object has no attribute 'value'
INFO level - 2024-01-19 19:02:15,397 django.utils.autoreload: "C:\Users\kurba\PycharmProjects\AnotherDjango\python_django\mysite\shopapp\admin.py changed, reloading."
INFO level - 2024-01-19 19:02:16,160 django.utils.autoreload: "Watching for file changes with StatReloader"
INFO level - 2024-01-19 19:05:27,146 django.utils.autoreload: "C:\Users\kurba\PycharmProjects\AnotherDjango\python_django\mysite\shopapp\admin.py changed, reloading."
INFO level - 2024-01-19 19:05:27,825 django.utils.autoreload: "Watching for file changes with StatReloader"
INFO level - 2024-01-19 19:09:16,776 django.utils.autoreload: "C:\Users\kurba\PycharmProjects\AnotherDjango\python_django\mysite\shopapp\admin.py changed, reloading."
INFO level - 2024-01-19 19:09:17,380 django.utils.autoreload: "Watching for file changes with StatReloader"
WARNING level - 2024-01-19 19:09:29,093 django.request: "Not Found: /ru/admin/shopapp/import-csv"
INFO level - 2024-01-19 19:13:01,777 django.utils.autoreload: "C:\Users\kurba\PycharmProjects\AnotherDjango\python_django\mysite\shopapp\admin.py changed, reloading."
INFO level - 2024-01-19 19:13:02,462 django.utils.autoreload: "Watching for file changes with StatReloader"
INFO level - 2024-01-19 19:14:12,192 django.utils.autoreload: "C:\Users\kurba\PycharmProjects\AnotherDjango\python_django\mysite\shopapp\admin.py changed, reloading."
INFO level - 2024-01-19 19:14:12,846 django.utils.autoreload: "Watching for file changes with StatReloader"
INFO level - 2024-01-19 19:22:08,797 django.utils.autoreload: "C:\Users\kurba\PycharmProjects\AnotherDjango\python_django\mysite\shopapp\admin.py changed, reloading."
INFO level - 2024-01-19 19:22:09,491 django.utils.autoreload: "Watching for file changes with StatReloader"
INFO level - 2024-01-19 19:24:24,535 django.utils.autoreload: "C:\Users\kurba\PycharmProjects\AnotherDjango\python_django\mysite\shopapp\admin.py changed, reloading."
INFO level - 2024-01-19 19:24:25,221 django.utils.autoreload: "Watching for file changes with StatReloader"
INFO level - 2024-01-19 19:42:24,688 django.utils.autoreload: "C:\Users\kurba\PycharmProjects\AnotherDjango\python_django\mysite\shopapp\admin.py changed, reloading."
INFO level - 2024-01-19 19:42:25,413 django.utils.autoreload: "Watching for file changes with StatReloader"
INFO level - 2024-01-19 19:51:18,016 django.utils.autoreload: "C:\Users\kurba\PycharmProjects\AnotherDjango\python_django\mysite\shopapp\admin.py changed, reloading."
INFO level - 2024-01-19 19:51:18,634 django.utils.autoreload: "Watching for file changes with StatReloader"
INFO level - 2024-01-19 19:56:01,654 django.utils.autoreload: "C:\Users\kurba\PycharmProjects\AnotherDjango\python_django\mysite\shopapp\admin.py changed, reloading."
INFO level - 2024-01-19 19:56:02,282 django.utils.autoreload: "Watching for file changes with StatReloader"
INFO level - 2024-01-19 20:11:57,784 django.utils.autoreload: "C:\Users\kurba\PycharmProjects\AnotherDjango\python_django\mysite\shopapp\admin.py changed, reloading."
INFO level - 2024-01-19 20:11:58,423 django.utils.autoreload: "Watching for file changes with StatReloader"
INFO level - 2024-01-19 20:13:53,124 django.utils.autoreload: "C:\Users\kurba\PycharmProjects\AnotherDjango\python_django\mysite\shopapp\admin.py changed, reloading."
INFO level - 2024-01-19 20:13:53,835 django.utils.autoreload: "Watching for file changes with StatReloader"
INFO level - 2024-01-19 20:34:07,222 django.utils.autoreload: "C:\Users\kurba\PycharmProjects\AnotherDjango\python_django\mysite\shopapp\admin.py changed, reloading."
INFO level - 2024-01-19 20:34:08,473 django.utils.autoreload: "Watching for file changes with StatReloader"
ERROR level - 2024-01-19 20:35:45,607 django.request: "Internal Server Error: /ru/admin/shopapp/order/import-csv"
Traceback (most recent call last):
  File "C:\Users\kurba\PycharmProjects\AnotherDjango\venv\Lib\site-packages\django\core\handlers\exception.py", line 55, in inner
    response = get_response(request)
               ^^^^^^^^^^^^^^^^^^^^^
  File "C:\Users\kurba\PycharmProjects\AnotherDjango\venv\Lib\site-packages\django\core\handlers\base.py", line 197, in _get_response
    response = wrapped_callback(request, *callback_args, **callback_kwargs)
               ^^^^^^^^^^^^^^^^^^^^^^^^^^^^^^^^^^^^^^^^^^^^^^^^^^^^^^^^^^^^
  File "C:\Users\kurba\PycharmProjects\AnotherDjango\venv\Lib\site-packages\sentry_sdk\integrations\django\views.py", line 84, in sentry_wrapped_callback
    return callback(request, *args, **kwargs)
           ^^^^^^^^^^^^^^^^^^^^^^^^^^^^^^^^^^
  File "C:\Users\kurba\PycharmProjects\AnotherDjango\python_django\mysite\shopapp\admin.py", line 94, in import_as_CSV
    self.message_user(request, message=f'Orders in row/rows #{", ".split(unsuccessful)} were not uploaded. \n'
                                                              ^^^^^^^^^^^^^^^^^^^^^^^^
TypeError: must be str or None, not list
INFO level - 2024-01-19 20:36:18,672 django.utils.autoreload: "C:\Users\kurba\PycharmProjects\AnotherDjango\python_django\mysite\shopapp\admin.py changed, reloading."
INFO level - 2024-01-19 20:36:19,586 django.utils.autoreload: "Watching for file changes with StatReloader"
ERROR level - 2024-01-19 20:36:20,891 django.request: "Internal Server Error: /ru/admin/shopapp/order/import-csv"
Traceback (most recent call last):
  File "C:\Users\kurba\PycharmProjects\AnotherDjango\venv\Lib\site-packages\django\core\handlers\exception.py", line 55, in inner
    response = get_response(request)
               ^^^^^^^^^^^^^^^^^^^^^
  File "C:\Users\kurba\PycharmProjects\AnotherDjango\venv\Lib\site-packages\django\core\handlers\base.py", line 197, in _get_response
    response = wrapped_callback(request, *callback_args, **callback_kwargs)
               ^^^^^^^^^^^^^^^^^^^^^^^^^^^^^^^^^^^^^^^^^^^^^^^^^^^^^^^^^^^^
  File "C:\Users\kurba\PycharmProjects\AnotherDjango\venv\Lib\site-packages\sentry_sdk\integrations\django\views.py", line 84, in sentry_wrapped_callback
    return callback(request, *args, **kwargs)
           ^^^^^^^^^^^^^^^^^^^^^^^^^^^^^^^^^^
  File "C:\Users\kurba\PycharmProjects\AnotherDjango\python_django\mysite\shopapp\admin.py", line 94, in import_as_CSV
    self.message_user(request, message=f'Orders in row/rows #{", ".join(unsuccessful)} were not uploaded. \n'
                                                              ^^^^^^^^^^^^^^^^^^^^^^^
TypeError: sequence item 0: expected str instance, int found
INFO level - 2024-01-19 20:36:52,247 django.utils.autoreload: "C:\Users\kurba\PycharmProjects\AnotherDjango\python_django\mysite\shopapp\admin.py changed, reloading."
INFO level - 2024-01-19 20:36:53,157 django.utils.autoreload: "Watching for file changes with StatReloader"
ERROR level - 2024-01-19 20:36:54,334 django.request: "Internal Server Error: /ru/admin/shopapp/order/import-csv"
Traceback (most recent call last):
  File "C:\Users\kurba\PycharmProjects\AnotherDjango\venv\Lib\site-packages\django\core\handlers\exception.py", line 55, in inner
    response = get_response(request)
               ^^^^^^^^^^^^^^^^^^^^^
  File "C:\Users\kurba\PycharmProjects\AnotherDjango\venv\Lib\site-packages\django\core\handlers\base.py", line 197, in _get_response
    response = wrapped_callback(request, *callback_args, **callback_kwargs)
               ^^^^^^^^^^^^^^^^^^^^^^^^^^^^^^^^^^^^^^^^^^^^^^^^^^^^^^^^^^^^
  File "C:\Users\kurba\PycharmProjects\AnotherDjango\venv\Lib\site-packages\sentry_sdk\integrations\django\views.py", line 84, in sentry_wrapped_callback
    return callback(request, *args, **kwargs)
           ^^^^^^^^^^^^^^^^^^^^^^^^^^^^^^^^^^
  File "C:\Users\kurba\PycharmProjects\AnotherDjango\python_django\mysite\shopapp\admin.py", line 90, in import_as_CSV
    unsuccessful = ", ".join(import_orders_from_csv(csv_file))
                   ^^^^^^^^^^^^^^^^^^^^^^^^^^^^^^^^^^^^^^^^^^^
TypeError: sequence item 0: expected str instance, int found
ERROR level - 2024-01-19 20:37:11,923 django.request: "Internal Server Error: /ru/admin/shopapp/order/import-csv"
Traceback (most recent call last):
  File "C:\Users\kurba\PycharmProjects\AnotherDjango\venv\Lib\site-packages\django\core\handlers\exception.py", line 55, in inner
    response = get_response(request)
               ^^^^^^^^^^^^^^^^^^^^^
  File "C:\Users\kurba\PycharmProjects\AnotherDjango\venv\Lib\site-packages\django\core\handlers\base.py", line 197, in _get_response
    response = wrapped_callback(request, *callback_args, **callback_kwargs)
               ^^^^^^^^^^^^^^^^^^^^^^^^^^^^^^^^^^^^^^^^^^^^^^^^^^^^^^^^^^^^
  File "C:\Users\kurba\PycharmProjects\AnotherDjango\venv\Lib\site-packages\sentry_sdk\integrations\django\views.py", line 84, in sentry_wrapped_callback
    return callback(request, *args, **kwargs)
           ^^^^^^^^^^^^^^^^^^^^^^^^^^^^^^^^^^
  File "C:\Users\kurba\PycharmProjects\AnotherDjango\python_django\mysite\shopapp\admin.py", line 90, in import_as_CSV
    unsuccessful = ", ".join(import_orders_from_csv(csv_file))
                   ^^^^^^^^^^^^^^^^^^^^^^^^^^^^^^^^^^^^^^^^^^^
TypeError: sequence item 0: expected str instance, int found
INFO level - 2024-01-19 20:38:29,139 django.utils.autoreload: "C:\Users\kurba\PycharmProjects\AnotherDjango\python_django\mysite\shopapp\admin.py changed, reloading."
INFO level - 2024-01-19 20:38:30,037 django.utils.autoreload: "Watching for file changes with StatReloader"
INFO level - 2024-01-19 20:41:24,695 django.utils.autoreload: "C:\Users\kurba\PycharmProjects\AnotherDjango\python_django\mysite\shopapp\admin.py changed, reloading."
INFO level - 2024-01-19 20:41:25,460 django.utils.autoreload: "Watching for file changes with StatReloader"
INFO level - 2024-01-19 20:41:42,483 django.utils.autoreload: "C:\Users\kurba\PycharmProjects\AnotherDjango\python_django\mysite\shopapp\admin.py changed, reloading."
INFO level - 2024-01-19 20:41:43,244 django.utils.autoreload: "Watching for file changes with StatReloader"
ERROR level - 2024-01-19 20:42:24,015 django.request: "Internal Server Error: /ru/admin/shopapp/order/import-csv"
Traceback (most recent call last):
  File "C:\Users\kurba\PycharmProjects\AnotherDjango\venv\Lib\site-packages\django\core\handlers\exception.py", line 55, in inner
    response = get_response(request)
               ^^^^^^^^^^^^^^^^^^^^^
  File "C:\Users\kurba\PycharmProjects\AnotherDjango\venv\Lib\site-packages\django\core\handlers\base.py", line 197, in _get_response
    response = wrapped_callback(request, *callback_args, **callback_kwargs)
               ^^^^^^^^^^^^^^^^^^^^^^^^^^^^^^^^^^^^^^^^^^^^^^^^^^^^^^^^^^^^
  File "C:\Users\kurba\PycharmProjects\AnotherDjango\venv\Lib\site-packages\sentry_sdk\integrations\django\views.py", line 84, in sentry_wrapped_callback
    return callback(request, *args, **kwargs)
           ^^^^^^^^^^^^^^^^^^^^^^^^^^^^^^^^^^
  File "C:\Users\kurba\PycharmProjects\AnotherDjango\python_django\mysite\shopapp\admin.py", line 96, in import_as_CSV
    unsuccessful = import_orders_from_csv(csv_file)
                   ^^^^^^^^^^^^^^^^^^^^^^^^^^^^^^^^
  File "C:\Python311\Lib\contextlib.py", line 81, in inner
    return func(*args, **kwds)
           ^^^^^^^^^^^^^^^^^^^
  File "C:\Users\kurba\PycharmProjects\AnotherDjango\python_django\mysite\shopapp\admin.py", line 22, in import_orders_from_csv
    for row in DictReader(csv_file):
  File "C:\Python311\Lib\csv.py", line 110, in __next__
    self.fieldnames
  File "C:\Python311\Lib\csv.py", line 97, in fieldnames
    self._fieldnames = next(self.reader)
                       ^^^^^^^^^^^^^^^^^
  File "C:\Python311\Lib\encodings\cp1251.py", line 23, in decode
    return codecs.charmap_decode(input,self.errors,decoding_table)[0]
           ^^^^^^^^^^^^^^^^^^^^^^^^^^^^^^^^^^^^^^^^^^^^^^^^^^^^^^^
UnicodeDecodeError: 'charmap' codec can't decode byte 0x98 in position 624: character maps to <undefined>
INFO level - 2024-01-19 20:46:10,855 django.utils.autoreload: "C:\Users\kurba\PycharmProjects\AnotherDjango\python_django\mysite\shopapp\admin.py changed, reloading."
INFO level - 2024-01-19 20:46:11,599 django.utils.autoreload: "Watching for file changes with StatReloader"
INFO level - 2024-01-19 21:00:44,694 django.utils.autoreload: "C:\Users\kurba\PycharmProjects\AnotherDjango\python_django\mysite\shopapp\admin.py changed, reloading."
INFO level - 2024-01-19 21:00:45,444 django.utils.autoreload: "Watching for file changes with StatReloader"
INFO level - 2024-01-19 21:00:57,404 django.utils.autoreload: "C:\Users\kurba\PycharmProjects\AnotherDjango\python_django\mysite\shopapp\admin.py changed, reloading."
INFO level - 2024-01-19 21:00:58,205 django.utils.autoreload: "Watching for file changes with StatReloader"
INFO level - 2024-01-19 21:13:42,174 django.utils.autoreload: "C:\Users\kurba\PycharmProjects\AnotherDjango\python_django\mysite\shopapp\admin.py changed, reloading."
INFO level - 2024-01-19 21:13:43,013 django.utils.autoreload: "Watching for file changes with StatReloader"
INFO level - 2024-01-19 22:32:43,143 django.utils.autoreload: "C:\Users\kurba\PycharmProjects\AnotherDjango\python_django\mysite\shopapp\admin.py changed, reloading."
INFO level - 2024-01-19 22:32:43,918 django.utils.autoreload: "Watching for file changes with StatReloader"
INFO level - 2024-01-19 22:35:02,157 django.utils.autoreload: "C:\Users\kurba\PycharmProjects\AnotherDjango\python_django\mysite\shopapp\admin.py changed, reloading."
INFO level - 2024-01-19 22:35:02,847 django.utils.autoreload: "Watching for file changes with StatReloader"
INFO level - 2024-01-19 22:35:10,471 django.utils.autoreload: "C:\Users\kurba\PycharmProjects\AnotherDjango\python_django\mysite\shopapp\admin.py changed, reloading."
INFO level - 2024-01-19 22:35:11,097 django.utils.autoreload: "Watching for file changes with StatReloader"
INFO level - 2024-01-19 22:35:17,466 django.utils.autoreload: "C:\Users\kurba\PycharmProjects\AnotherDjango\python_django\mysite\shopapp\admin.py changed, reloading."
INFO level - 2024-01-19 22:35:18,057 django.utils.autoreload: "Watching for file changes with StatReloader"
INFO level - 2024-01-19 22:35:21,538 django.utils.autoreload: "C:\Users\kurba\PycharmProjects\AnotherDjango\python_django\mysite\shopapp\admin.py changed, reloading."
INFO level - 2024-01-19 22:35:22,183 django.utils.autoreload: "Watching for file changes with StatReloader"
INFO level - 2024-01-19 22:35:37,024 django.utils.autoreload: "C:\Users\kurba\PycharmProjects\AnotherDjango\python_django\mysite\shopapp\admin.py changed, reloading."
INFO level - 2024-01-19 22:35:37,632 django.utils.autoreload: "Watching for file changes with StatReloader"
ERROR level - 2024-01-19 22:42:02,342 django.request: "Internal Server Error: /ru/admin/shopapp/order/"
Traceback (most recent call last):
  File "C:\Users\kurba\PycharmProjects\AnotherDjango\venv\Lib\site-packages\django\core\handlers\exception.py", line 55, in inner
    response = get_response(request)
               ^^^^^^^^^^^^^^^^^^^^^
  File "C:\Users\kurba\PycharmProjects\AnotherDjango\venv\Lib\site-packages\django\core\handlers\base.py", line 220, in _get_response
    response = response.render()
               ^^^^^^^^^^^^^^^^^
  File "C:\Users\kurba\PycharmProjects\AnotherDjango\venv\Lib\site-packages\sentry_sdk\integrations\django\views.py", line 38, in sentry_patched_render
    return old_render(self)
           ^^^^^^^^^^^^^^^^
  File "C:\Users\kurba\PycharmProjects\AnotherDjango\venv\Lib\site-packages\django\template\response.py", line 114, in render
    self.content = self.rendered_content
                   ^^^^^^^^^^^^^^^^^^^^^
  File "C:\Users\kurba\PycharmProjects\AnotherDjango\venv\Lib\site-packages\sentry_sdk\integrations\django\templates.py", line 75, in rendered_content
    return real_rendered_content.fget(self)
           ^^^^^^^^^^^^^^^^^^^^^^^^^^^^^^^^
  File "C:\Users\kurba\PycharmProjects\AnotherDjango\venv\Lib\site-packages\django\template\response.py", line 92, in rendered_content
    return template.render(context, self._request)
           ^^^^^^^^^^^^^^^^^^^^^^^^^^^^^^^^^^^^^^^
  File "C:\Users\kurba\PycharmProjects\AnotherDjango\venv\Lib\site-packages\django\template\backends\django.py", line 61, in render
    return self.template.render(context)
           ^^^^^^^^^^^^^^^^^^^^^^^^^^^^^
  File "C:\Users\kurba\PycharmProjects\AnotherDjango\venv\Lib\site-packages\django\template\base.py", line 175, in render
    return self._render(context)
           ^^^^^^^^^^^^^^^^^^^^^
  File "C:\Users\kurba\PycharmProjects\AnotherDjango\venv\Lib\site-packages\django\test\utils.py", line 112, in instrumented_test_render
    return self.nodelist.render(context)
           ^^^^^^^^^^^^^^^^^^^^^^^^^^^^^
  File "C:\Users\kurba\PycharmProjects\AnotherDjango\venv\Lib\site-packages\django\template\base.py", line 1005, in render
    return SafeString("".join([node.render_annotated(context) for node in self]))
                              ^^^^^^^^^^^^^^^^^^^^^^^^^^^^^^^^^^^^^^^^^^^^^^^^^
  File "C:\Users\kurba\PycharmProjects\AnotherDjango\venv\Lib\site-packages\django\template\base.py", line 1005, in <listcomp>
    return SafeString("".join([node.render_annotated(context) for node in self]))
                               ^^^^^^^^^^^^^^^^^^^^^^^^^^^^^^
  File "C:\Users\kurba\PycharmProjects\AnotherDjango\venv\Lib\site-packages\django\template\base.py", line 966, in render_annotated
    return self.render(context)
           ^^^^^^^^^^^^^^^^^^^^
  File "C:\Users\kurba\PycharmProjects\AnotherDjango\venv\Lib\site-packages\django\template\loader_tags.py", line 157, in render
    return compiled_parent._render(context)
           ^^^^^^^^^^^^^^^^^^^^^^^^^^^^^^^^
  File "C:\Users\kurba\PycharmProjects\AnotherDjango\venv\Lib\site-packages\django\test\utils.py", line 112, in instrumented_test_render
    return self.nodelist.render(context)
           ^^^^^^^^^^^^^^^^^^^^^^^^^^^^^
  File "C:\Users\kurba\PycharmProjects\AnotherDjango\venv\Lib\site-packages\django\template\base.py", line 1005, in render
    return SafeString("".join([node.render_annotated(context) for node in self]))
                              ^^^^^^^^^^^^^^^^^^^^^^^^^^^^^^^^^^^^^^^^^^^^^^^^^
  File "C:\Users\kurba\PycharmProjects\AnotherDjango\venv\Lib\site-packages\django\template\base.py", line 1005, in <listcomp>
    return SafeString("".join([node.render_annotated(context) for node in self]))
                               ^^^^^^^^^^^^^^^^^^^^^^^^^^^^^^
  File "C:\Users\kurba\PycharmProjects\AnotherDjango\venv\Lib\site-packages\django\template\base.py", line 966, in render_annotated
    return self.render(context)
           ^^^^^^^^^^^^^^^^^^^^
  File "C:\Users\kurba\PycharmProjects\AnotherDjango\venv\Lib\site-packages\django\template\loader_tags.py", line 157, in render
    return compiled_parent._render(context)
           ^^^^^^^^^^^^^^^^^^^^^^^^^^^^^^^^
  File "C:\Users\kurba\PycharmProjects\AnotherDjango\venv\Lib\site-packages\django\test\utils.py", line 112, in instrumented_test_render
    return self.nodelist.render(context)
           ^^^^^^^^^^^^^^^^^^^^^^^^^^^^^
  File "C:\Users\kurba\PycharmProjects\AnotherDjango\venv\Lib\site-packages\django\template\base.py", line 1005, in render
    return SafeString("".join([node.render_annotated(context) for node in self]))
                              ^^^^^^^^^^^^^^^^^^^^^^^^^^^^^^^^^^^^^^^^^^^^^^^^^
  File "C:\Users\kurba\PycharmProjects\AnotherDjango\venv\Lib\site-packages\django\template\base.py", line 1005, in <listcomp>
    return SafeString("".join([node.render_annotated(context) for node in self]))
                               ^^^^^^^^^^^^^^^^^^^^^^^^^^^^^^
  File "C:\Users\kurba\PycharmProjects\AnotherDjango\venv\Lib\site-packages\django\template\base.py", line 966, in render_annotated
    return self.render(context)
           ^^^^^^^^^^^^^^^^^^^^
  File "C:\Users\kurba\PycharmProjects\AnotherDjango\venv\Lib\site-packages\django\template\loader_tags.py", line 157, in render
    return compiled_parent._render(context)
           ^^^^^^^^^^^^^^^^^^^^^^^^^^^^^^^^
  File "C:\Users\kurba\PycharmProjects\AnotherDjango\venv\Lib\site-packages\django\test\utils.py", line 112, in instrumented_test_render
    return self.nodelist.render(context)
           ^^^^^^^^^^^^^^^^^^^^^^^^^^^^^
  File "C:\Users\kurba\PycharmProjects\AnotherDjango\venv\Lib\site-packages\django\template\base.py", line 1005, in render
    return SafeString("".join([node.render_annotated(context) for node in self]))
                              ^^^^^^^^^^^^^^^^^^^^^^^^^^^^^^^^^^^^^^^^^^^^^^^^^
  File "C:\Users\kurba\PycharmProjects\AnotherDjango\venv\Lib\site-packages\django\template\base.py", line 1005, in <listcomp>
    return SafeString("".join([node.render_annotated(context) for node in self]))
                               ^^^^^^^^^^^^^^^^^^^^^^^^^^^^^^
  File "C:\Users\kurba\PycharmProjects\AnotherDjango\venv\Lib\site-packages\django\template\base.py", line 966, in render_annotated
    return self.render(context)
           ^^^^^^^^^^^^^^^^^^^^
  File "C:\Users\kurba\PycharmProjects\AnotherDjango\venv\Lib\site-packages\django\template\loader_tags.py", line 63, in render
    result = block.nodelist.render(context)
             ^^^^^^^^^^^^^^^^^^^^^^^^^^^^^^
  File "C:\Users\kurba\PycharmProjects\AnotherDjango\venv\Lib\site-packages\django\template\base.py", line 1005, in render
    return SafeString("".join([node.render_annotated(context) for node in self]))
                              ^^^^^^^^^^^^^^^^^^^^^^^^^^^^^^^^^^^^^^^^^^^^^^^^^
  File "C:\Users\kurba\PycharmProjects\AnotherDjango\venv\Lib\site-packages\django\template\base.py", line 1005, in <listcomp>
    return SafeString("".join([node.render_annotated(context) for node in self]))
                               ^^^^^^^^^^^^^^^^^^^^^^^^^^^^^^
  File "C:\Users\kurba\PycharmProjects\AnotherDjango\venv\Lib\site-packages\django\template\base.py", line 966, in render_annotated
    return self.render(context)
           ^^^^^^^^^^^^^^^^^^^^
  File "C:\Users\kurba\PycharmProjects\AnotherDjango\venv\Lib\site-packages\django\template\loader_tags.py", line 63, in render
    result = block.nodelist.render(context)
             ^^^^^^^^^^^^^^^^^^^^^^^^^^^^^^
  File "C:\Users\kurba\PycharmProjects\AnotherDjango\venv\Lib\site-packages\django\template\base.py", line 1005, in render
    return SafeString("".join([node.render_annotated(context) for node in self]))
                              ^^^^^^^^^^^^^^^^^^^^^^^^^^^^^^^^^^^^^^^^^^^^^^^^^
  File "C:\Users\kurba\PycharmProjects\AnotherDjango\venv\Lib\site-packages\django\template\base.py", line 1005, in <listcomp>
    return SafeString("".join([node.render_annotated(context) for node in self]))
                               ^^^^^^^^^^^^^^^^^^^^^^^^^^^^^^
  File "C:\Users\kurba\PycharmProjects\AnotherDjango\venv\Lib\site-packages\django\template\base.py", line 966, in render_annotated
    return self.render(context)
           ^^^^^^^^^^^^^^^^^^^^
  File "C:\Users\kurba\PycharmProjects\AnotherDjango\venv\Lib\site-packages\django\template\loader_tags.py", line 63, in render
    result = block.nodelist.render(context)
             ^^^^^^^^^^^^^^^^^^^^^^^^^^^^^^
  File "C:\Users\kurba\PycharmProjects\AnotherDjango\venv\Lib\site-packages\django\template\base.py", line 1005, in render
    return SafeString("".join([node.render_annotated(context) for node in self]))
                              ^^^^^^^^^^^^^^^^^^^^^^^^^^^^^^^^^^^^^^^^^^^^^^^^^
  File "C:\Users\kurba\PycharmProjects\AnotherDjango\venv\Lib\site-packages\django\template\base.py", line 1005, in <listcomp>
    return SafeString("".join([node.render_annotated(context) for node in self]))
                               ^^^^^^^^^^^^^^^^^^^^^^^^^^^^^^
  File "C:\Users\kurba\PycharmProjects\AnotherDjango\venv\Lib\site-packages\django\template\base.py", line 966, in render_annotated
    return self.render(context)
           ^^^^^^^^^^^^^^^^^^^^
  File "C:\Users\kurba\PycharmProjects\AnotherDjango\venv\Lib\site-packages\django\template\defaulttags.py", line 471, in render
    url = reverse(view_name, args=args, kwargs=kwargs, current_app=current_app)
          ^^^^^^^^^^^^^^^^^^^^^^^^^^^^^^^^^^^^^^^^^^^^^^^^^^^^^^^^^^^^^^^^^^^^^
  File "C:\Users\kurba\PycharmProjects\AnotherDjango\venv\Lib\site-packages\django\urls\base.py", line 88, in reverse
    return resolver._reverse_with_prefix(view, prefix, *args, **kwargs)
           ^^^^^^^^^^^^^^^^^^^^^^^^^^^^^^^^^^^^^^^^^^^^^^^^^^^^^^^^^^^^
  File "C:\Users\kurba\PycharmProjects\AnotherDjango\venv\Lib\site-packages\django\urls\resolvers.py", line 828, in _reverse_with_prefix
    raise NoReverseMatch(msg)
django.urls.exceptions.NoReverseMatch: Reverse for 'imprt_csv' not found. 'imprt_csv' is not a valid view function or pattern name.
INFO level - 2024-01-19 22:43:12,538 shopapp.views: "Logging for info-level is set"
INFO level - 2024-01-25 00:31:38,059 django.utils.autoreload: "C:\Users\kurba\PycharmProjects\AnotherDjango\python_django\mysite\shopapp\views.py changed, reloading."
INFO level - 2024-01-25 00:31:39,255 django.utils.autoreload: "Watching for file changes with StatReloader"
INFO level - 2024-01-25 00:31:41,745 django.utils.autoreload: "C:\Users\kurba\PycharmProjects\AnotherDjango\python_django\mysite\shopapp\views.py changed, reloading."
INFO level - 2024-01-25 00:31:42,414 django.utils.autoreload: "Watching for file changes with StatReloader"
INFO level - 2024-01-25 00:31:44,836 django.utils.autoreload: "C:\Users\kurba\PycharmProjects\AnotherDjango\python_django\mysite\shopapp\views.py changed, reloading."
INFO level - 2024-01-25 00:31:45,548 django.utils.autoreload: "Watching for file changes with StatReloader"
INFO level - 2024-01-25 00:31:47,863 django.utils.autoreload: "C:\Users\kurba\PycharmProjects\AnotherDjango\python_django\mysite\shopapp\views.py changed, reloading."
INFO level - 2024-01-25 00:31:48,536 django.utils.autoreload: "Watching for file changes with StatReloader"
INFO level - 2024-01-25 00:31:55,082 django.utils.autoreload: "C:\Users\kurba\PycharmProjects\AnotherDjango\python_django\mysite\shopapp\views.py changed, reloading."
INFO level - 2024-01-25 00:31:55,721 django.utils.autoreload: "Watching for file changes with StatReloader"
INFO level - 2024-01-25 00:32:17,762 django.utils.autoreload: "C:\Users\kurba\PycharmProjects\AnotherDjango\python_django\mysite\shopapp\views.py changed, reloading."
INFO level - 2024-01-25 00:32:18,531 django.utils.autoreload: "Watching for file changes with StatReloader"
INFO level - 2024-01-25 00:34:03,845 django.utils.autoreload: "C:\Users\kurba\PycharmProjects\AnotherDjango\python_django\mysite\shopapp\views.py changed, reloading."
INFO level - 2024-01-25 00:34:04,607 django.utils.autoreload: "Watching for file changes with StatReloader"
INFO level - 2024-01-25 00:34:30,866 django.utils.autoreload: "C:\Users\kurba\PycharmProjects\AnotherDjango\python_django\mysite\shopapp\views.py changed, reloading."
INFO level - 2024-01-25 00:34:31,575 django.utils.autoreload: "Watching for file changes with StatReloader"
INFO level - 2024-01-25 00:34:39,210 django.utils.autoreload: "C:\Users\kurba\PycharmProjects\AnotherDjango\python_django\mysite\shopapp\views.py changed, reloading."
INFO level - 2024-01-25 00:34:39,975 django.utils.autoreload: "Watching for file changes with StatReloader"
INFO level - 2024-01-25 00:35:40,316 django.utils.autoreload: "C:\Users\kurba\PycharmProjects\AnotherDjango\python_django\mysite\shopapp\views.py changed, reloading."
INFO level - 2024-01-25 00:35:40,986 django.utils.autoreload: "Watching for file changes with StatReloader"
INFO level - 2024-01-25 00:36:08,399 django.utils.autoreload: "C:\Users\kurba\PycharmProjects\AnotherDjango\python_django\mysite\shopapp\urls.py changed, reloading."
INFO level - 2024-01-25 00:36:09,139 django.utils.autoreload: "Watching for file changes with StatReloader"
INFO level - 2024-01-25 00:37:20,914 django.utils.autoreload: "C:\Users\kurba\PycharmProjects\AnotherDjango\python_django\mysite\shopapp\urls.py changed, reloading."
INFO level - 2024-01-25 00:37:21,634 django.utils.autoreload: "Watching for file changes with StatReloader"
INFO level - 2024-01-25 00:37:30,414 django.utils.autoreload: "C:\Users\kurba\PycharmProjects\AnotherDjango\python_django\mysite\shopapp\urls.py changed, reloading."
INFO level - 2024-01-25 00:37:31,068 django.utils.autoreload: "Watching for file changes with StatReloader"
INFO level - 2024-01-25 00:39:01,679 django.utils.autoreload: "C:\Users\kurba\PycharmProjects\AnotherDjango\python_django\mysite\shopapp\views.py changed, reloading."
INFO level - 2024-01-25 00:39:02,419 django.utils.autoreload: "Watching for file changes with StatReloader"
WARNING level - 2024-01-25 00:39:37,787 django.request: "Not Found: /"
ERROR level - 2024-01-25 00:40:02,658 django.request: "Internal Server Error: /ru/shop/users/1/orders/"
Traceback (most recent call last):
  File "C:\Users\kurba\PycharmProjects\AnotherDjango\venv\Lib\site-packages\django\core\handlers\exception.py", line 55, in inner
    response = get_response(request)
               ^^^^^^^^^^^^^^^^^^^^^
  File "C:\Users\kurba\PycharmProjects\AnotherDjango\venv\Lib\site-packages\django\core\handlers\base.py", line 197, in _get_response
    response = wrapped_callback(request, *callback_args, **callback_kwargs)
               ^^^^^^^^^^^^^^^^^^^^^^^^^^^^^^^^^^^^^^^^^^^^^^^^^^^^^^^^^^^^
  File "C:\Users\kurba\PycharmProjects\AnotherDjango\venv\Lib\site-packages\sentry_sdk\integrations\django\views.py", line 84, in sentry_wrapped_callback
    return callback(request, *args, **kwargs)
           ^^^^^^^^^^^^^^^^^^^^^^^^^^^^^^^^^^
  File "C:\Users\kurba\PycharmProjects\AnotherDjango\venv\Lib\site-packages\django\views\generic\base.py", line 104, in view
    return self.dispatch(request, *args, **kwargs)
           ^^^^^^^^^^^^^^^^^^^^^^^^^^^^^^^^^^^^^^^
  File "C:\Users\kurba\PycharmProjects\AnotherDjango\venv\Lib\site-packages\django\contrib\auth\mixins.py", line 135, in dispatch
    return super().dispatch(request, *args, **kwargs)
           ^^^^^^^^^^^^^^^^^^^^^^^^^^^^^^^^^^^^^^^^^^
  File "C:\Users\kurba\PycharmProjects\AnotherDjango\venv\Lib\site-packages\django\views\generic\base.py", line 143, in dispatch
    return handler(request, *args, **kwargs)
           ^^^^^^^^^^^^^^^^^^^^^^^^^^^^^^^^^
TypeError: OrdersExportView.get() got an unexpected keyword argument 'user_id'
INFO level - 2024-01-25 00:41:09,582 django.utils.autoreload: "C:\Users\kurba\PycharmProjects\AnotherDjango\python_django\mysite\shopapp\views.py changed, reloading."
INFO level - 2024-01-25 00:41:10,415 django.utils.autoreload: "Watching for file changes with StatReloader"
ERROR level - 2024-01-25 00:41:10,948 django.request: "Internal Server Error: /ru/shop/users/1/orders/"
Traceback (most recent call last):
  File "C:\Users\kurba\PycharmProjects\AnotherDjango\venv\Lib\site-packages\django\core\handlers\exception.py", line 55, in inner
    response = get_response(request)
               ^^^^^^^^^^^^^^^^^^^^^
  File "C:\Users\kurba\PycharmProjects\AnotherDjango\venv\Lib\site-packages\django\core\handlers\base.py", line 197, in _get_response
    response = wrapped_callback(request, *callback_args, **callback_kwargs)
               ^^^^^^^^^^^^^^^^^^^^^^^^^^^^^^^^^^^^^^^^^^^^^^^^^^^^^^^^^^^^
  File "C:\Users\kurba\PycharmProjects\AnotherDjango\venv\Lib\site-packages\sentry_sdk\integrations\django\views.py", line 84, in sentry_wrapped_callback
    return callback(request, *args, **kwargs)
           ^^^^^^^^^^^^^^^^^^^^^^^^^^^^^^^^^^
  File "C:\Users\kurba\PycharmProjects\AnotherDjango\venv\Lib\site-packages\django\views\generic\base.py", line 104, in view
    return self.dispatch(request, *args, **kwargs)
           ^^^^^^^^^^^^^^^^^^^^^^^^^^^^^^^^^^^^^^^
  File "C:\Users\kurba\PycharmProjects\AnotherDjango\venv\Lib\site-packages\django\contrib\auth\mixins.py", line 135, in dispatch
    return super().dispatch(request, *args, **kwargs)
           ^^^^^^^^^^^^^^^^^^^^^^^^^^^^^^^^^^^^^^^^^^
  File "C:\Users\kurba\PycharmProjects\AnotherDjango\venv\Lib\site-packages\django\views\generic\base.py", line 143, in dispatch
    return handler(request, *args, **kwargs)
           ^^^^^^^^^^^^^^^^^^^^^^^^^^^^^^^^^
TypeError: OrdersExportView.get() got an unexpected keyword argument 'user_id'
ERROR level - 2024-01-25 00:41:46,139 django.request: "Internal Server Error: /ru/shop/users/1/orders/"
Traceback (most recent call last):
  File "C:\Users\kurba\PycharmProjects\AnotherDjango\venv\Lib\site-packages\django\core\handlers\exception.py", line 55, in inner
    response = get_response(request)
               ^^^^^^^^^^^^^^^^^^^^^
  File "C:\Users\kurba\PycharmProjects\AnotherDjango\venv\Lib\site-packages\django\core\handlers\base.py", line 197, in _get_response
    response = wrapped_callback(request, *callback_args, **callback_kwargs)
               ^^^^^^^^^^^^^^^^^^^^^^^^^^^^^^^^^^^^^^^^^^^^^^^^^^^^^^^^^^^^
  File "C:\Users\kurba\PycharmProjects\AnotherDjango\venv\Lib\site-packages\sentry_sdk\integrations\django\views.py", line 84, in sentry_wrapped_callback
    return callback(request, *args, **kwargs)
           ^^^^^^^^^^^^^^^^^^^^^^^^^^^^^^^^^^
  File "C:\Users\kurba\PycharmProjects\AnotherDjango\venv\Lib\site-packages\django\views\generic\base.py", line 104, in view
    return self.dispatch(request, *args, **kwargs)
           ^^^^^^^^^^^^^^^^^^^^^^^^^^^^^^^^^^^^^^^
  File "C:\Users\kurba\PycharmProjects\AnotherDjango\venv\Lib\site-packages\django\contrib\auth\mixins.py", line 135, in dispatch
    return super().dispatch(request, *args, **kwargs)
           ^^^^^^^^^^^^^^^^^^^^^^^^^^^^^^^^^^^^^^^^^^
  File "C:\Users\kurba\PycharmProjects\AnotherDjango\venv\Lib\site-packages\django\views\generic\base.py", line 143, in dispatch
    return handler(request, *args, **kwargs)
           ^^^^^^^^^^^^^^^^^^^^^^^^^^^^^^^^^
TypeError: OrdersExportView.get() got an unexpected keyword argument 'user_id'
INFO level - 2024-01-25 00:42:44,308 django.utils.autoreload: "C:\Users\kurba\PycharmProjects\AnotherDjango\python_django\mysite\shopapp\urls.py changed, reloading."
INFO level - 2024-01-25 00:42:45,170 django.utils.autoreload: "Watching for file changes with StatReloader"
INFO level - 2024-01-25 00:43:07,444 django.utils.autoreload: "C:\Users\kurba\PycharmProjects\AnotherDjango\python_django\mysite\shopapp\views.py changed, reloading."
INFO level - 2024-01-25 00:43:08,340 django.utils.autoreload: "Watching for file changes with StatReloader"
INFO level - 2024-01-25 00:43:54,363 django.utils.autoreload: "C:\Users\kurba\PycharmProjects\AnotherDjango\python_django\mysite\shopapp\views.py changed, reloading."
INFO level - 2024-01-25 00:43:55,195 django.utils.autoreload: "Watching for file changes with StatReloader"
INFO level - 2024-01-25 00:47:00,001 django.utils.autoreload: "C:\Users\kurba\PycharmProjects\AnotherDjango\python_django\mysite\shopapp\views.py changed, reloading."
INFO level - 2024-01-25 00:47:00,756 django.utils.autoreload: "Watching for file changes with StatReloader"
INFO level - 2024-01-25 00:47:10,543 django.utils.autoreload: "C:\Users\kurba\PycharmProjects\AnotherDjango\python_django\mysite\shopapp\views.py changed, reloading."
INFO level - 2024-01-25 00:47:11,167 django.utils.autoreload: "Watching for file changes with StatReloader"
INFO level - 2024-01-25 00:47:59,014 django.utils.autoreload: "C:\Users\kurba\PycharmProjects\AnotherDjango\python_django\mysite\shopapp\views.py changed, reloading."
INFO level - 2024-01-25 00:47:59,731 django.utils.autoreload: "Watching for file changes with StatReloader"
INFO level - 2024-01-25 00:48:17,673 django.utils.autoreload: "C:\Users\kurba\PycharmProjects\AnotherDjango\python_django\mysite\shopapp\views.py changed, reloading."
INFO level - 2024-01-25 00:48:18,328 django.utils.autoreload: "Watching for file changes with StatReloader"
INFO level - 2024-01-25 00:48:52,931 django.utils.autoreload: "C:\Users\kurba\PycharmProjects\AnotherDjango\python_django\mysite\shopapp\views.py changed, reloading."
INFO level - 2024-01-25 00:48:53,616 django.utils.autoreload: "Watching for file changes with StatReloader"
INFO level - 2024-01-25 00:49:32,408 django.utils.autoreload: "C:\Users\kurba\PycharmProjects\AnotherDjango\python_django\mysite\shopapp\views.py changed, reloading."
INFO level - 2024-01-25 00:49:33,223 django.utils.autoreload: "Watching for file changes with StatReloader"
INFO level - 2024-01-25 00:50:53,332 django.utils.autoreload: "C:\Users\kurba\PycharmProjects\AnotherDjango\python_django\mysite\shopapp\views.py changed, reloading."
INFO level - 2024-01-25 00:50:53,998 django.utils.autoreload: "Watching for file changes with StatReloader"
INFO level - 2024-01-25 00:53:20,156 django.utils.autoreload: "C:\Users\kurba\PycharmProjects\AnotherDjango\python_django\mysite\shopapp\views.py changed, reloading."
INFO level - 2024-01-25 00:53:20,929 django.utils.autoreload: "Watching for file changes with StatReloader"
INFO level - 2024-01-25 00:54:20,390 django.utils.autoreload: "C:\Users\kurba\PycharmProjects\AnotherDjango\python_django\mysite\shopapp\views.py changed, reloading."
INFO level - 2024-01-25 00:54:21,201 django.utils.autoreload: "Watching for file changes with StatReloader"
INFO level - 2024-01-25 00:54:49,425 django.utils.autoreload: "C:\Users\kurba\PycharmProjects\AnotherDjango\python_django\mysite\shopapp\views.py changed, reloading."
INFO level - 2024-01-25 00:54:50,141 django.utils.autoreload: "Watching for file changes with StatReloader"
ERROR level - 2024-01-25 00:54:54,091 django.request: "Internal Server Error: /ru/shop/users/1/orders/"
Traceback (most recent call last):
  File "C:\Users\kurba\PycharmProjects\AnotherDjango\venv\Lib\site-packages\django\core\handlers\exception.py", line 55, in inner
    response = get_response(request)
               ^^^^^^^^^^^^^^^^^^^^^
  File "C:\Users\kurba\PycharmProjects\AnotherDjango\venv\Lib\site-packages\django\core\handlers\base.py", line 197, in _get_response
    response = wrapped_callback(request, *callback_args, **callback_kwargs)
               ^^^^^^^^^^^^^^^^^^^^^^^^^^^^^^^^^^^^^^^^^^^^^^^^^^^^^^^^^^^^
  File "C:\Users\kurba\PycharmProjects\AnotherDjango\venv\Lib\site-packages\sentry_sdk\integrations\django\views.py", line 84, in sentry_wrapped_callback
    return callback(request, *args, **kwargs)
           ^^^^^^^^^^^^^^^^^^^^^^^^^^^^^^^^^^
  File "C:\Users\kurba\PycharmProjects\AnotherDjango\venv\Lib\site-packages\django\views\generic\base.py", line 97, in view
    self = cls(**initkwargs)
           ^^^^^^^^^^^^^^^^^
  File "C:\Users\kurba\PycharmProjects\AnotherDjango\python_django\mysite\shopapp\views.py", line 183, in __init__
    self.owner = User.objects.get(pk=self.kwargs['user_id'])
                                     ^^^^^^^^^^^
AttributeError: 'UserOrderListView' object has no attribute 'kwargs'
INFO level - 2024-01-25 00:55:33,243 django.utils.autoreload: "C:\Users\kurba\PycharmProjects\AnotherDjango\python_django\mysite\shopapp\views.py changed, reloading."
INFO level - 2024-01-25 00:55:34,093 django.utils.autoreload: "Watching for file changes with StatReloader"
ERROR level - 2024-01-25 00:55:34,775 django.request: "Internal Server Error: /ru/shop/users/1/orders/"
Traceback (most recent call last):
  File "C:\Users\kurba\PycharmProjects\AnotherDjango\venv\Lib\site-packages\django\core\handlers\exception.py", line 55, in inner
    response = get_response(request)
               ^^^^^^^^^^^^^^^^^^^^^
  File "C:\Users\kurba\PycharmProjects\AnotherDjango\venv\Lib\site-packages\django\core\handlers\base.py", line 197, in _get_response
    response = wrapped_callback(request, *callback_args, **callback_kwargs)
               ^^^^^^^^^^^^^^^^^^^^^^^^^^^^^^^^^^^^^^^^^^^^^^^^^^^^^^^^^^^^
  File "C:\Users\kurba\PycharmProjects\AnotherDjango\venv\Lib\site-packages\sentry_sdk\integrations\django\views.py", line 84, in sentry_wrapped_callback
    return callback(request, *args, **kwargs)
           ^^^^^^^^^^^^^^^^^^^^^^^^^^^^^^^^^^
  File "C:\Users\kurba\PycharmProjects\AnotherDjango\venv\Lib\site-packages\django\views\generic\base.py", line 97, in view
    self = cls(**initkwargs)
           ^^^^^^^^^^^^^^^^^
  File "C:\Users\kurba\PycharmProjects\AnotherDjango\python_django\mysite\shopapp\views.py", line 183, in __init__
    self.owner = User.objects.get(pk=self.kwargs['user_id'])
                                     ^^^^^^^^^^^
AttributeError: 'UserOrderListView' object has no attribute 'kwargs'
ERROR level - 2024-01-25 00:55:34,975 django.request: "Internal Server Error: /ru/shop/users/1/orders/"
Traceback (most recent call last):
  File "C:\Users\kurba\PycharmProjects\AnotherDjango\venv\Lib\site-packages\django\core\handlers\exception.py", line 55, in inner
    response = get_response(request)
               ^^^^^^^^^^^^^^^^^^^^^
  File "C:\Users\kurba\PycharmProjects\AnotherDjango\venv\Lib\site-packages\django\core\handlers\base.py", line 197, in _get_response
    response = wrapped_callback(request, *callback_args, **callback_kwargs)
               ^^^^^^^^^^^^^^^^^^^^^^^^^^^^^^^^^^^^^^^^^^^^^^^^^^^^^^^^^^^^
  File "C:\Users\kurba\PycharmProjects\AnotherDjango\venv\Lib\site-packages\sentry_sdk\integrations\django\views.py", line 84, in sentry_wrapped_callback
    return callback(request, *args, **kwargs)
           ^^^^^^^^^^^^^^^^^^^^^^^^^^^^^^^^^^
  File "C:\Users\kurba\PycharmProjects\AnotherDjango\venv\Lib\site-packages\django\views\generic\base.py", line 97, in view
    self = cls(**initkwargs)
           ^^^^^^^^^^^^^^^^^
  File "C:\Users\kurba\PycharmProjects\AnotherDjango\python_django\mysite\shopapp\views.py", line 183, in __init__
    self.owner = User.objects.get(pk=self.kwargs['user_id'])
                                     ^^^^^^^^^^^
AttributeError: 'UserOrderListView' object has no attribute 'kwargs'
ERROR level - 2024-01-25 00:55:35,173 django.request: "Internal Server Error: /ru/shop/users/1/orders/"
Traceback (most recent call last):
  File "C:\Users\kurba\PycharmProjects\AnotherDjango\venv\Lib\site-packages\django\core\handlers\exception.py", line 55, in inner
    response = get_response(request)
               ^^^^^^^^^^^^^^^^^^^^^
  File "C:\Users\kurba\PycharmProjects\AnotherDjango\venv\Lib\site-packages\django\core\handlers\base.py", line 197, in _get_response
    response = wrapped_callback(request, *callback_args, **callback_kwargs)
               ^^^^^^^^^^^^^^^^^^^^^^^^^^^^^^^^^^^^^^^^^^^^^^^^^^^^^^^^^^^^
  File "C:\Users\kurba\PycharmProjects\AnotherDjango\venv\Lib\site-packages\sentry_sdk\integrations\django\views.py", line 84, in sentry_wrapped_callback
    return callback(request, *args, **kwargs)
           ^^^^^^^^^^^^^^^^^^^^^^^^^^^^^^^^^^
  File "C:\Users\kurba\PycharmProjects\AnotherDjango\venv\Lib\site-packages\django\views\generic\base.py", line 97, in view
    self = cls(**initkwargs)
           ^^^^^^^^^^^^^^^^^
  File "C:\Users\kurba\PycharmProjects\AnotherDjango\python_django\mysite\shopapp\views.py", line 183, in __init__
    self.owner = User.objects.get(pk=self.kwargs['user_id'])
                                     ^^^^^^^^^^^
AttributeError: 'UserOrderListView' object has no attribute 'kwargs'
INFO level - 2024-01-25 00:56:39,969 django.utils.autoreload: "C:\Users\kurba\PycharmProjects\AnotherDjango\python_django\mysite\shopapp\views.py changed, reloading."
INFO level - 2024-01-25 00:56:40,821 django.utils.autoreload: "Watching for file changes with StatReloader"
ERROR level - 2024-01-25 00:56:41,367 django.request: "Internal Server Error: /ru/shop/users/1/orders/"
Traceback (most recent call last):
  File "C:\Users\kurba\PycharmProjects\AnotherDjango\venv\Lib\site-packages\django\core\handlers\exception.py", line 55, in inner
    response = get_response(request)
               ^^^^^^^^^^^^^^^^^^^^^
  File "C:\Users\kurba\PycharmProjects\AnotherDjango\venv\Lib\site-packages\django\core\handlers\base.py", line 197, in _get_response
    response = wrapped_callback(request, *callback_args, **callback_kwargs)
               ^^^^^^^^^^^^^^^^^^^^^^^^^^^^^^^^^^^^^^^^^^^^^^^^^^^^^^^^^^^^
  File "C:\Users\kurba\PycharmProjects\AnotherDjango\venv\Lib\site-packages\sentry_sdk\integrations\django\views.py", line 84, in sentry_wrapped_callback
    return callback(request, *args, **kwargs)
           ^^^^^^^^^^^^^^^^^^^^^^^^^^^^^^^^^^
  File "C:\Users\kurba\PycharmProjects\AnotherDjango\venv\Lib\site-packages\django\views\generic\base.py", line 97, in view
    self = cls(**initkwargs)
           ^^^^^^^^^^^^^^^^^
  File "C:\Users\kurba\PycharmProjects\AnotherDjango\python_django\mysite\shopapp\views.py", line 183, in __init__
    self.owner = User.objects.get(pk=self.kwargs['user_id'])
                                     ^^^^^^^^^^^
AttributeError: 'UserOrderListView' object has no attribute 'kwargs'
ERROR level - 2024-01-25 00:56:41,581 django.request: "Internal Server Error: /ru/shop/users/1/orders/"
Traceback (most recent call last):
  File "C:\Users\kurba\PycharmProjects\AnotherDjango\venv\Lib\site-packages\django\core\handlers\exception.py", line 55, in inner
    response = get_response(request)
               ^^^^^^^^^^^^^^^^^^^^^
  File "C:\Users\kurba\PycharmProjects\AnotherDjango\venv\Lib\site-packages\django\core\handlers\base.py", line 197, in _get_response
    response = wrapped_callback(request, *callback_args, **callback_kwargs)
               ^^^^^^^^^^^^^^^^^^^^^^^^^^^^^^^^^^^^^^^^^^^^^^^^^^^^^^^^^^^^
  File "C:\Users\kurba\PycharmProjects\AnotherDjango\venv\Lib\site-packages\sentry_sdk\integrations\django\views.py", line 84, in sentry_wrapped_callback
    return callback(request, *args, **kwargs)
           ^^^^^^^^^^^^^^^^^^^^^^^^^^^^^^^^^^
  File "C:\Users\kurba\PycharmProjects\AnotherDjango\venv\Lib\site-packages\django\views\generic\base.py", line 97, in view
    self = cls(**initkwargs)
           ^^^^^^^^^^^^^^^^^
  File "C:\Users\kurba\PycharmProjects\AnotherDjango\python_django\mysite\shopapp\views.py", line 183, in __init__
    self.owner = User.objects.get(pk=self.kwargs['user_id'])
                                     ^^^^^^^^^^^
AttributeError: 'UserOrderListView' object has no attribute 'kwargs'
ERROR level - 2024-01-25 00:56:42,082 django.request: "Internal Server Error: /ru/shop/users/1/orders/"
Traceback (most recent call last):
  File "C:\Users\kurba\PycharmProjects\AnotherDjango\venv\Lib\site-packages\django\core\handlers\exception.py", line 55, in inner
    response = get_response(request)
               ^^^^^^^^^^^^^^^^^^^^^
  File "C:\Users\kurba\PycharmProjects\AnotherDjango\venv\Lib\site-packages\django\core\handlers\base.py", line 197, in _get_response
    response = wrapped_callback(request, *callback_args, **callback_kwargs)
               ^^^^^^^^^^^^^^^^^^^^^^^^^^^^^^^^^^^^^^^^^^^^^^^^^^^^^^^^^^^^
  File "C:\Users\kurba\PycharmProjects\AnotherDjango\venv\Lib\site-packages\sentry_sdk\integrations\django\views.py", line 84, in sentry_wrapped_callback
    return callback(request, *args, **kwargs)
           ^^^^^^^^^^^^^^^^^^^^^^^^^^^^^^^^^^
  File "C:\Users\kurba\PycharmProjects\AnotherDjango\venv\Lib\site-packages\django\views\generic\base.py", line 97, in view
    self = cls(**initkwargs)
           ^^^^^^^^^^^^^^^^^
  File "C:\Users\kurba\PycharmProjects\AnotherDjango\python_django\mysite\shopapp\views.py", line 183, in __init__
    self.owner = User.objects.get(pk=self.kwargs['user_id'])
                                     ^^^^^^^^^^^
AttributeError: 'UserOrderListView' object has no attribute 'kwargs'
ERROR level - 2024-01-25 00:56:42,283 django.request: "Internal Server Error: /ru/shop/users/1/orders/"
Traceback (most recent call last):
  File "C:\Users\kurba\PycharmProjects\AnotherDjango\venv\Lib\site-packages\django\core\handlers\exception.py", line 55, in inner
    response = get_response(request)
               ^^^^^^^^^^^^^^^^^^^^^
  File "C:\Users\kurba\PycharmProjects\AnotherDjango\venv\Lib\site-packages\django\core\handlers\base.py", line 197, in _get_response
    response = wrapped_callback(request, *callback_args, **callback_kwargs)
               ^^^^^^^^^^^^^^^^^^^^^^^^^^^^^^^^^^^^^^^^^^^^^^^^^^^^^^^^^^^^
  File "C:\Users\kurba\PycharmProjects\AnotherDjango\venv\Lib\site-packages\sentry_sdk\integrations\django\views.py", line 84, in sentry_wrapped_callback
    return callback(request, *args, **kwargs)
           ^^^^^^^^^^^^^^^^^^^^^^^^^^^^^^^^^^
  File "C:\Users\kurba\PycharmProjects\AnotherDjango\venv\Lib\site-packages\django\views\generic\base.py", line 97, in view
    self = cls(**initkwargs)
           ^^^^^^^^^^^^^^^^^
  File "C:\Users\kurba\PycharmProjects\AnotherDjango\python_django\mysite\shopapp\views.py", line 183, in __init__
    self.owner = User.objects.get(pk=self.kwargs['user_id'])
                                     ^^^^^^^^^^^
AttributeError: 'UserOrderListView' object has no attribute 'kwargs'
INFO level - 2024-01-25 00:57:52,802 django.utils.autoreload: "C:\Users\kurba\PycharmProjects\AnotherDjango\python_django\mysite\shopapp\views.py changed, reloading."
INFO level - 2024-01-25 00:57:53,663 django.utils.autoreload: "Watching for file changes with StatReloader"
ERROR level - 2024-01-25 00:57:54,213 django.request: "Internal Server Error: /ru/shop/users/1/orders/"
Traceback (most recent call last):
  File "C:\Users\kurba\PycharmProjects\AnotherDjango\venv\Lib\site-packages\django\core\handlers\exception.py", line 55, in inner
    response = get_response(request)
               ^^^^^^^^^^^^^^^^^^^^^
  File "C:\Users\kurba\PycharmProjects\AnotherDjango\venv\Lib\site-packages\django\core\handlers\base.py", line 197, in _get_response
    response = wrapped_callback(request, *callback_args, **callback_kwargs)
               ^^^^^^^^^^^^^^^^^^^^^^^^^^^^^^^^^^^^^^^^^^^^^^^^^^^^^^^^^^^^
  File "C:\Users\kurba\PycharmProjects\AnotherDjango\venv\Lib\site-packages\sentry_sdk\integrations\django\views.py", line 84, in sentry_wrapped_callback
    return callback(request, *args, **kwargs)
           ^^^^^^^^^^^^^^^^^^^^^^^^^^^^^^^^^^
  File "C:\Users\kurba\PycharmProjects\AnotherDjango\venv\Lib\site-packages\django\views\generic\base.py", line 104, in view
    return self.dispatch(request, *args, **kwargs)
           ^^^^^^^^^^^^^^^^^^^^^^^^^^^^^^^^^^^^^^^
  File "C:\Users\kurba\PycharmProjects\AnotherDjango\venv\Lib\site-packages\django\views\generic\base.py", line 143, in dispatch
    return handler(request, *args, **kwargs)
           ^^^^^^^^^^^^^^^^^^^^^^^^^^^^^^^^^
  File "C:\Users\kurba\PycharmProjects\AnotherDjango\venv\Lib\site-packages\django\views\generic\list.py", line 154, in get
    self.object_list = self.get_queryset()
                       ^^^^^^^^^^^^^^^^^^^
  File "C:\Users\kurba\PycharmProjects\AnotherDjango\python_django\mysite\shopapp\views.py", line 187, in get_queryset
    queryset = Order.objects.filter(user=self.owner).select_related("user").prefetch_related("products")
                                         ^^^^^^^^^^
AttributeError: 'UserOrderListView' object has no attribute 'owner'
ERROR level - 2024-01-25 00:57:54,959 django.request: "Internal Server Error: /ru/shop/users/1/orders/"
Traceback (most recent call last):
  File "C:\Users\kurba\PycharmProjects\AnotherDjango\venv\Lib\site-packages\django\core\handlers\exception.py", line 55, in inner
    response = get_response(request)
               ^^^^^^^^^^^^^^^^^^^^^
  File "C:\Users\kurba\PycharmProjects\AnotherDjango\venv\Lib\site-packages\django\core\handlers\base.py", line 197, in _get_response
    response = wrapped_callback(request, *callback_args, **callback_kwargs)
               ^^^^^^^^^^^^^^^^^^^^^^^^^^^^^^^^^^^^^^^^^^^^^^^^^^^^^^^^^^^^
  File "C:\Users\kurba\PycharmProjects\AnotherDjango\venv\Lib\site-packages\sentry_sdk\integrations\django\views.py", line 84, in sentry_wrapped_callback
    return callback(request, *args, **kwargs)
           ^^^^^^^^^^^^^^^^^^^^^^^^^^^^^^^^^^
  File "C:\Users\kurba\PycharmProjects\AnotherDjango\venv\Lib\site-packages\django\views\generic\base.py", line 104, in view
    return self.dispatch(request, *args, **kwargs)
           ^^^^^^^^^^^^^^^^^^^^^^^^^^^^^^^^^^^^^^^
  File "C:\Users\kurba\PycharmProjects\AnotherDjango\venv\Lib\site-packages\django\views\generic\base.py", line 143, in dispatch
    return handler(request, *args, **kwargs)
           ^^^^^^^^^^^^^^^^^^^^^^^^^^^^^^^^^
  File "C:\Users\kurba\PycharmProjects\AnotherDjango\venv\Lib\site-packages\django\views\generic\list.py", line 154, in get
    self.object_list = self.get_queryset()
                       ^^^^^^^^^^^^^^^^^^^
  File "C:\Users\kurba\PycharmProjects\AnotherDjango\python_django\mysite\shopapp\views.py", line 187, in get_queryset
    queryset = Order.objects.filter(user=self.owner).select_related("user").prefetch_related("products")
                                         ^^^^^^^^^^
AttributeError: 'UserOrderListView' object has no attribute 'owner'
ERROR level - 2024-01-25 00:57:55,131 django.request: "Internal Server Error: /ru/shop/users/1/orders/"
Traceback (most recent call last):
  File "C:\Users\kurba\PycharmProjects\AnotherDjango\venv\Lib\site-packages\django\core\handlers\exception.py", line 55, in inner
    response = get_response(request)
               ^^^^^^^^^^^^^^^^^^^^^
  File "C:\Users\kurba\PycharmProjects\AnotherDjango\venv\Lib\site-packages\django\core\handlers\base.py", line 197, in _get_response
    response = wrapped_callback(request, *callback_args, **callback_kwargs)
               ^^^^^^^^^^^^^^^^^^^^^^^^^^^^^^^^^^^^^^^^^^^^^^^^^^^^^^^^^^^^
  File "C:\Users\kurba\PycharmProjects\AnotherDjango\venv\Lib\site-packages\sentry_sdk\integrations\django\views.py", line 84, in sentry_wrapped_callback
    return callback(request, *args, **kwargs)
           ^^^^^^^^^^^^^^^^^^^^^^^^^^^^^^^^^^
  File "C:\Users\kurba\PycharmProjects\AnotherDjango\venv\Lib\site-packages\django\views\generic\base.py", line 104, in view
    return self.dispatch(request, *args, **kwargs)
           ^^^^^^^^^^^^^^^^^^^^^^^^^^^^^^^^^^^^^^^
  File "C:\Users\kurba\PycharmProjects\AnotherDjango\venv\Lib\site-packages\django\views\generic\base.py", line 143, in dispatch
    return handler(request, *args, **kwargs)
           ^^^^^^^^^^^^^^^^^^^^^^^^^^^^^^^^^
  File "C:\Users\kurba\PycharmProjects\AnotherDjango\venv\Lib\site-packages\django\views\generic\list.py", line 154, in get
    self.object_list = self.get_queryset()
                       ^^^^^^^^^^^^^^^^^^^
  File "C:\Users\kurba\PycharmProjects\AnotherDjango\python_django\mysite\shopapp\views.py", line 187, in get_queryset
    queryset = Order.objects.filter(user=self.owner).select_related("user").prefetch_related("products")
                                         ^^^^^^^^^^
AttributeError: 'UserOrderListView' object has no attribute 'owner'
INFO level - 2024-01-25 00:58:05,630 django.utils.autoreload: "C:\Users\kurba\PycharmProjects\AnotherDjango\python_django\mysite\shopapp\views.py changed, reloading."
INFO level - 2024-01-25 00:58:06,490 django.utils.autoreload: "Watching for file changes with StatReloader"
INFO level - 2024-01-25 00:58:51,551 django.utils.autoreload: "C:\Users\kurba\PycharmProjects\AnotherDjango\python_django\mysite\shopapp\views.py changed, reloading."
INFO level - 2024-01-25 00:58:52,349 django.utils.autoreload: "Watching for file changes with StatReloader"
INFO level - 2024-01-25 01:11:58,369 django.utils.autoreload: "C:\Users\kurba\PycharmProjects\AnotherDjango\python_django\mysite\shopapp\views.py changed, reloading."
INFO level - 2024-01-25 01:11:59,264 django.utils.autoreload: "Watching for file changes with StatReloader"
WARNING level - 2024-01-25 01:13:30,461 django.request: "Forbidden (Permission denied): /ru/shop/orders/1/"
Traceback (most recent call last):
  File "C:\Users\kurba\PycharmProjects\AnotherDjango\venv\Lib\site-packages\django\core\handlers\exception.py", line 55, in inner
    response = get_response(request)
               ^^^^^^^^^^^^^^^^^^^^^
  File "C:\Users\kurba\PycharmProjects\AnotherDjango\venv\Lib\site-packages\django\core\handlers\base.py", line 197, in _get_response
    response = wrapped_callback(request, *callback_args, **callback_kwargs)
               ^^^^^^^^^^^^^^^^^^^^^^^^^^^^^^^^^^^^^^^^^^^^^^^^^^^^^^^^^^^^
  File "C:\Users\kurba\PycharmProjects\AnotherDjango\venv\Lib\site-packages\sentry_sdk\integrations\django\views.py", line 84, in sentry_wrapped_callback
    return callback(request, *args, **kwargs)
           ^^^^^^^^^^^^^^^^^^^^^^^^^^^^^^^^^^
  File "C:\Users\kurba\PycharmProjects\AnotherDjango\venv\Lib\site-packages\django\views\generic\base.py", line 104, in view
    return self.dispatch(request, *args, **kwargs)
           ^^^^^^^^^^^^^^^^^^^^^^^^^^^^^^^^^^^^^^^
  File "C:\Users\kurba\PycharmProjects\AnotherDjango\venv\Lib\site-packages\django\contrib\auth\mixins.py", line 108, in dispatch
    return self.handle_no_permission()
           ^^^^^^^^^^^^^^^^^^^^^^^^^^^
  File "C:\Users\kurba\PycharmProjects\AnotherDjango\venv\Lib\site-packages\django\contrib\auth\mixins.py", line 48, in handle_no_permission
    raise PermissionDenied(self.get_permission_denied_message())
django.core.exceptions.PermissionDenied
INFO level - 2024-01-25 01:18:36,679 django.utils.autoreload: "C:\Users\kurba\PycharmProjects\AnotherDjango\python_django\mysite\shopapp\views.py changed, reloading."
INFO level - 2024-01-25 01:18:37,712 django.utils.autoreload: "Watching for file changes with StatReloader"
ERROR level - 2024-01-25 01:18:45,264 django.request: "Internal Server Error: /ru/shop/users/20/orders/"
Traceback (most recent call last):
  File "C:\Users\kurba\PycharmProjects\AnotherDjango\venv\Lib\site-packages\django\core\handlers\exception.py", line 55, in inner
    response = get_response(request)
               ^^^^^^^^^^^^^^^^^^^^^
  File "C:\Users\kurba\PycharmProjects\AnotherDjango\venv\Lib\site-packages\django\core\handlers\base.py", line 197, in _get_response
    response = wrapped_callback(request, *callback_args, **callback_kwargs)
               ^^^^^^^^^^^^^^^^^^^^^^^^^^^^^^^^^^^^^^^^^^^^^^^^^^^^^^^^^^^^
  File "C:\Users\kurba\PycharmProjects\AnotherDjango\venv\Lib\site-packages\sentry_sdk\integrations\django\views.py", line 84, in sentry_wrapped_callback
    return callback(request, *args, **kwargs)
           ^^^^^^^^^^^^^^^^^^^^^^^^^^^^^^^^^^
  File "C:\Users\kurba\PycharmProjects\AnotherDjango\venv\Lib\site-packages\django\views\generic\base.py", line 104, in view
    return self.dispatch(request, *args, **kwargs)
           ^^^^^^^^^^^^^^^^^^^^^^^^^^^^^^^^^^^^^^^
  File "C:\Users\kurba\PycharmProjects\AnotherDjango\venv\Lib\site-packages\django\views\generic\base.py", line 143, in dispatch
    return handler(request, *args, **kwargs)
           ^^^^^^^^^^^^^^^^^^^^^^^^^^^^^^^^^
  File "C:\Users\kurba\PycharmProjects\AnotherDjango\venv\Lib\site-packages\django\views\generic\list.py", line 174, in get
    context = self.get_context_data()
              ^^^^^^^^^^^^^^^^^^^^^^^
  File "C:\Users\kurba\PycharmProjects\AnotherDjango\python_django\mysite\shopapp\views.py", line 191, in get_context_data
    context['owner'] = self.owner
                       ^^^^^^^^^^
AttributeError: 'UserOrderListView' object has no attribute 'owner'
INFO level - 2024-01-25 01:19:21,343 django.utils.autoreload: "C:\Users\kurba\PycharmProjects\AnotherDjango\python_django\mysite\shopapp\views.py changed, reloading."
INFO level - 2024-01-25 01:19:22,185 django.utils.autoreload: "Watching for file changes with StatReloader"
ERROR level - 2024-01-25 01:19:22,947 django.request: "Internal Server Error: /ru/shop/users/20/orders/"
Traceback (most recent call last):
  File "C:\Users\kurba\PycharmProjects\AnotherDjango\venv\Lib\site-packages\django\core\handlers\exception.py", line 55, in inner
    response = get_response(request)
               ^^^^^^^^^^^^^^^^^^^^^
  File "C:\Users\kurba\PycharmProjects\AnotherDjango\venv\Lib\site-packages\django\core\handlers\base.py", line 197, in _get_response
    response = wrapped_callback(request, *callback_args, **callback_kwargs)
               ^^^^^^^^^^^^^^^^^^^^^^^^^^^^^^^^^^^^^^^^^^^^^^^^^^^^^^^^^^^^
  File "C:\Users\kurba\PycharmProjects\AnotherDjango\venv\Lib\site-packages\sentry_sdk\integrations\django\views.py", line 84, in sentry_wrapped_callback
    return callback(request, *args, **kwargs)
           ^^^^^^^^^^^^^^^^^^^^^^^^^^^^^^^^^^
  File "C:\Users\kurba\PycharmProjects\AnotherDjango\venv\Lib\site-packages\django\views\generic\base.py", line 104, in view
    return self.dispatch(request, *args, **kwargs)
           ^^^^^^^^^^^^^^^^^^^^^^^^^^^^^^^^^^^^^^^
  File "C:\Users\kurba\PycharmProjects\AnotherDjango\venv\Lib\site-packages\django\views\generic\base.py", line 143, in dispatch
    return handler(request, *args, **kwargs)
           ^^^^^^^^^^^^^^^^^^^^^^^^^^^^^^^^^
  File "C:\Users\kurba\PycharmProjects\AnotherDjango\venv\Lib\site-packages\django\views\generic\list.py", line 154, in get
    self.object_list = self.get_queryset()
                       ^^^^^^^^^^^^^^^^^^^
  File "C:\Users\kurba\PycharmProjects\AnotherDjango\python_django\mysite\shopapp\views.py", line 182, in get_queryset
    self.owner = User.objects.get(pk=self.kwargs['user_id'])
                 ^^^^^^^^^^^^^^^^^^^^^^^^^^^^^^^^^^^^^^^^^^^
  File "C:\Users\kurba\PycharmProjects\AnotherDjango\venv\Lib\site-packages\django\db\models\manager.py", line 87, in manager_method
    return getattr(self.get_queryset(), name)(*args, **kwargs)
           ^^^^^^^^^^^^^^^^^^^^^^^^^^^^^^^^^^^^^^^^^^^^^^^^^^^
  File "C:\Users\kurba\PycharmProjects\AnotherDjango\venv\Lib\site-packages\django\db\models\query.py", line 637, in get
    raise self.model.DoesNotExist(
django.contrib.auth.models.User.DoesNotExist: User matching query does not exist.
ERROR level - 2024-01-25 01:19:23,240 django.request: "Internal Server Error: /ru/shop/users/20/orders/"
Traceback (most recent call last):
  File "C:\Users\kurba\PycharmProjects\AnotherDjango\venv\Lib\site-packages\django\core\handlers\exception.py", line 55, in inner
    response = get_response(request)
               ^^^^^^^^^^^^^^^^^^^^^
  File "C:\Users\kurba\PycharmProjects\AnotherDjango\venv\Lib\site-packages\django\core\handlers\base.py", line 197, in _get_response
    response = wrapped_callback(request, *callback_args, **callback_kwargs)
               ^^^^^^^^^^^^^^^^^^^^^^^^^^^^^^^^^^^^^^^^^^^^^^^^^^^^^^^^^^^^
  File "C:\Users\kurba\PycharmProjects\AnotherDjango\venv\Lib\site-packages\sentry_sdk\integrations\django\views.py", line 84, in sentry_wrapped_callback
    return callback(request, *args, **kwargs)
           ^^^^^^^^^^^^^^^^^^^^^^^^^^^^^^^^^^
  File "C:\Users\kurba\PycharmProjects\AnotherDjango\venv\Lib\site-packages\django\views\generic\base.py", line 104, in view
    return self.dispatch(request, *args, **kwargs)
           ^^^^^^^^^^^^^^^^^^^^^^^^^^^^^^^^^^^^^^^
  File "C:\Users\kurba\PycharmProjects\AnotherDjango\venv\Lib\site-packages\django\views\generic\base.py", line 143, in dispatch
    return handler(request, *args, **kwargs)
           ^^^^^^^^^^^^^^^^^^^^^^^^^^^^^^^^^
  File "C:\Users\kurba\PycharmProjects\AnotherDjango\venv\Lib\site-packages\django\views\generic\list.py", line 154, in get
    self.object_list = self.get_queryset()
                       ^^^^^^^^^^^^^^^^^^^
  File "C:\Users\kurba\PycharmProjects\AnotherDjango\python_django\mysite\shopapp\views.py", line 182, in get_queryset
    self.owner = User.objects.get(pk=self.kwargs['user_id'])
                 ^^^^^^^^^^^^^^^^^^^^^^^^^^^^^^^^^^^^^^^^^^^
  File "C:\Users\kurba\PycharmProjects\AnotherDjango\venv\Lib\site-packages\django\db\models\manager.py", line 87, in manager_method
    return getattr(self.get_queryset(), name)(*args, **kwargs)
           ^^^^^^^^^^^^^^^^^^^^^^^^^^^^^^^^^^^^^^^^^^^^^^^^^^^
  File "C:\Users\kurba\PycharmProjects\AnotherDjango\venv\Lib\site-packages\django\db\models\query.py", line 637, in get
    raise self.model.DoesNotExist(
django.contrib.auth.models.User.DoesNotExist: User matching query does not exist.
ERROR level - 2024-01-25 01:19:23,406 django.request: "Internal Server Error: /ru/shop/users/20/orders/"
Traceback (most recent call last):
  File "C:\Users\kurba\PycharmProjects\AnotherDjango\venv\Lib\site-packages\django\core\handlers\exception.py", line 55, in inner
    response = get_response(request)
               ^^^^^^^^^^^^^^^^^^^^^
  File "C:\Users\kurba\PycharmProjects\AnotherDjango\venv\Lib\site-packages\django\core\handlers\base.py", line 197, in _get_response
    response = wrapped_callback(request, *callback_args, **callback_kwargs)
               ^^^^^^^^^^^^^^^^^^^^^^^^^^^^^^^^^^^^^^^^^^^^^^^^^^^^^^^^^^^^
  File "C:\Users\kurba\PycharmProjects\AnotherDjango\venv\Lib\site-packages\sentry_sdk\integrations\django\views.py", line 84, in sentry_wrapped_callback
    return callback(request, *args, **kwargs)
           ^^^^^^^^^^^^^^^^^^^^^^^^^^^^^^^^^^
  File "C:\Users\kurba\PycharmProjects\AnotherDjango\venv\Lib\site-packages\django\views\generic\base.py", line 104, in view
    return self.dispatch(request, *args, **kwargs)
           ^^^^^^^^^^^^^^^^^^^^^^^^^^^^^^^^^^^^^^^
  File "C:\Users\kurba\PycharmProjects\AnotherDjango\venv\Lib\site-packages\django\views\generic\base.py", line 143, in dispatch
    return handler(request, *args, **kwargs)
           ^^^^^^^^^^^^^^^^^^^^^^^^^^^^^^^^^
  File "C:\Users\kurba\PycharmProjects\AnotherDjango\venv\Lib\site-packages\django\views\generic\list.py", line 154, in get
    self.object_list = self.get_queryset()
                       ^^^^^^^^^^^^^^^^^^^
  File "C:\Users\kurba\PycharmProjects\AnotherDjango\python_django\mysite\shopapp\views.py", line 182, in get_queryset
    self.owner = User.objects.get(pk=self.kwargs['user_id'])
                 ^^^^^^^^^^^^^^^^^^^^^^^^^^^^^^^^^^^^^^^^^^^
  File "C:\Users\kurba\PycharmProjects\AnotherDjango\venv\Lib\site-packages\django\db\models\manager.py", line 87, in manager_method
    return getattr(self.get_queryset(), name)(*args, **kwargs)
           ^^^^^^^^^^^^^^^^^^^^^^^^^^^^^^^^^^^^^^^^^^^^^^^^^^^
  File "C:\Users\kurba\PycharmProjects\AnotherDjango\venv\Lib\site-packages\django\db\models\query.py", line 637, in get
    raise self.model.DoesNotExist(
django.contrib.auth.models.User.DoesNotExist: User matching query does not exist.
INFO level - 2024-01-25 01:25:02,474 django.utils.autoreload: "C:\Users\kurba\PycharmProjects\AnotherDjango\python_django\mysite\shopapp\views.py changed, reloading."
INFO level - 2024-01-25 01:25:03,349 django.utils.autoreload: "Watching for file changes with StatReloader"
ERROR level - 2024-01-25 01:25:09,725 django.request: "Internal Server Error: /ru/shop/users/20/orders/"
Traceback (most recent call last):
  File "C:\Users\kurba\PycharmProjects\AnotherDjango\venv\Lib\site-packages\django\core\handlers\exception.py", line 55, in inner
    response = get_response(request)
               ^^^^^^^^^^^^^^^^^^^^^
  File "C:\Users\kurba\PycharmProjects\AnotherDjango\venv\Lib\site-packages\django\core\handlers\base.py", line 197, in _get_response
    response = wrapped_callback(request, *callback_args, **callback_kwargs)
               ^^^^^^^^^^^^^^^^^^^^^^^^^^^^^^^^^^^^^^^^^^^^^^^^^^^^^^^^^^^^
  File "C:\Users\kurba\PycharmProjects\AnotherDjango\venv\Lib\site-packages\sentry_sdk\integrations\django\views.py", line 84, in sentry_wrapped_callback
    return callback(request, *args, **kwargs)
           ^^^^^^^^^^^^^^^^^^^^^^^^^^^^^^^^^^
  File "C:\Users\kurba\PycharmProjects\AnotherDjango\venv\Lib\site-packages\django\views\generic\base.py", line 104, in view
    return self.dispatch(request, *args, **kwargs)
           ^^^^^^^^^^^^^^^^^^^^^^^^^^^^^^^^^^^^^^^
  File "C:\Users\kurba\PycharmProjects\AnotherDjango\venv\Lib\site-packages\django\views\generic\base.py", line 143, in dispatch
    return handler(request, *args, **kwargs)
           ^^^^^^^^^^^^^^^^^^^^^^^^^^^^^^^^^
  File "C:\Users\kurba\PycharmProjects\AnotherDjango\venv\Lib\site-packages\django\views\generic\list.py", line 154, in get
    self.object_list = self.get_queryset()
                       ^^^^^^^^^^^^^^^^^^^
  File "C:\Users\kurba\PycharmProjects\AnotherDjango\python_django\mysite\shopapp\views.py", line 182, in get_queryset
    self.owner = User.objects.get(pk=self.kwargs['user_id'])
                 ^^^^^^^^^^^^^^^^^^^^^^^^^^^^^^^^^^^^^^^^^^^
  File "C:\Users\kurba\PycharmProjects\AnotherDjango\venv\Lib\site-packages\django\db\models\manager.py", line 87, in manager_method
    return getattr(self.get_queryset(), name)(*args, **kwargs)
           ^^^^^^^^^^^^^^^^^^^^^^^^^^^^^^^^^^^^^^^^^^^^^^^^^^^
  File "C:\Users\kurba\PycharmProjects\AnotherDjango\venv\Lib\site-packages\django\db\models\query.py", line 637, in get
    raise self.model.DoesNotExist(
django.contrib.auth.models.User.DoesNotExist: User matching query does not exist.
INFO level - 2024-01-25 01:27:25,216 django.utils.autoreload: "C:\Users\kurba\PycharmProjects\AnotherDjango\python_django\mysite\shopapp\views.py changed, reloading."
INFO level - 2024-01-25 01:27:25,984 django.utils.autoreload: "Watching for file changes with StatReloader"
ERROR level - 2024-01-25 01:27:27,971 django.request: "Internal Server Error: /ru/shop/users/20/orders/"
Traceback (most recent call last):
  File "C:\Users\kurba\PycharmProjects\AnotherDjango\venv\Lib\site-packages\django\core\handlers\exception.py", line 55, in inner
    response = get_response(request)
               ^^^^^^^^^^^^^^^^^^^^^
  File "C:\Users\kurba\PycharmProjects\AnotherDjango\venv\Lib\site-packages\django\core\handlers\base.py", line 197, in _get_response
    response = wrapped_callback(request, *callback_args, **callback_kwargs)
               ^^^^^^^^^^^^^^^^^^^^^^^^^^^^^^^^^^^^^^^^^^^^^^^^^^^^^^^^^^^^
  File "C:\Users\kurba\PycharmProjects\AnotherDjango\venv\Lib\site-packages\sentry_sdk\integrations\django\views.py", line 84, in sentry_wrapped_callback
    return callback(request, *args, **kwargs)
           ^^^^^^^^^^^^^^^^^^^^^^^^^^^^^^^^^^
  File "C:\Users\kurba\PycharmProjects\AnotherDjango\venv\Lib\site-packages\django\views\generic\base.py", line 104, in view
    return self.dispatch(request, *args, **kwargs)
           ^^^^^^^^^^^^^^^^^^^^^^^^^^^^^^^^^^^^^^^
  File "C:\Users\kurba\PycharmProjects\AnotherDjango\venv\Lib\site-packages\django\views\generic\base.py", line 143, in dispatch
    return handler(request, *args, **kwargs)
           ^^^^^^^^^^^^^^^^^^^^^^^^^^^^^^^^^
  File "C:\Users\kurba\PycharmProjects\AnotherDjango\venv\Lib\site-packages\django\views\generic\list.py", line 154, in get
    self.object_list = self.get_queryset()
                       ^^^^^^^^^^^^^^^^^^^
  File "C:\Users\kurba\PycharmProjects\AnotherDjango\python_django\mysite\shopapp\views.py", line 182, in get_queryset
    self.owner = User.objects.get(pk=self.kwargs['user_id'])
                 ^^^^^^^^^^^^^^^^^^^^^^^^^^^^^^^^^^^^^^^^^^^
  File "C:\Users\kurba\PycharmProjects\AnotherDjango\venv\Lib\site-packages\django\db\models\manager.py", line 87, in manager_method
    return getattr(self.get_queryset(), name)(*args, **kwargs)
           ^^^^^^^^^^^^^^^^^^^^^^^^^^^^^^^^^^^^^^^^^^^^^^^^^^^
  File "C:\Users\kurba\PycharmProjects\AnotherDjango\venv\Lib\site-packages\django\db\models\query.py", line 637, in get
    raise self.model.DoesNotExist(
django.contrib.auth.models.User.DoesNotExist: User matching query does not exist.
ERROR level - 2024-01-25 01:27:28,636 django.request: "Internal Server Error: /ru/shop/users/20/orders/"
Traceback (most recent call last):
  File "C:\Users\kurba\PycharmProjects\AnotherDjango\venv\Lib\site-packages\django\core\handlers\exception.py", line 55, in inner
    response = get_response(request)
               ^^^^^^^^^^^^^^^^^^^^^
  File "C:\Users\kurba\PycharmProjects\AnotherDjango\venv\Lib\site-packages\django\core\handlers\base.py", line 197, in _get_response
    response = wrapped_callback(request, *callback_args, **callback_kwargs)
               ^^^^^^^^^^^^^^^^^^^^^^^^^^^^^^^^^^^^^^^^^^^^^^^^^^^^^^^^^^^^
  File "C:\Users\kurba\PycharmProjects\AnotherDjango\venv\Lib\site-packages\sentry_sdk\integrations\django\views.py", line 84, in sentry_wrapped_callback
    return callback(request, *args, **kwargs)
           ^^^^^^^^^^^^^^^^^^^^^^^^^^^^^^^^^^
  File "C:\Users\kurba\PycharmProjects\AnotherDjango\venv\Lib\site-packages\django\views\generic\base.py", line 104, in view
    return self.dispatch(request, *args, **kwargs)
           ^^^^^^^^^^^^^^^^^^^^^^^^^^^^^^^^^^^^^^^
  File "C:\Users\kurba\PycharmProjects\AnotherDjango\venv\Lib\site-packages\django\views\generic\base.py", line 143, in dispatch
    return handler(request, *args, **kwargs)
           ^^^^^^^^^^^^^^^^^^^^^^^^^^^^^^^^^
  File "C:\Users\kurba\PycharmProjects\AnotherDjango\venv\Lib\site-packages\django\views\generic\list.py", line 154, in get
    self.object_list = self.get_queryset()
                       ^^^^^^^^^^^^^^^^^^^
  File "C:\Users\kurba\PycharmProjects\AnotherDjango\python_django\mysite\shopapp\views.py", line 182, in get_queryset
    self.owner = User.objects.get(pk=self.kwargs['user_id'])
                 ^^^^^^^^^^^^^^^^^^^^^^^^^^^^^^^^^^^^^^^^^^^
  File "C:\Users\kurba\PycharmProjects\AnotherDjango\venv\Lib\site-packages\django\db\models\manager.py", line 87, in manager_method
    return getattr(self.get_queryset(), name)(*args, **kwargs)
           ^^^^^^^^^^^^^^^^^^^^^^^^^^^^^^^^^^^^^^^^^^^^^^^^^^^
  File "C:\Users\kurba\PycharmProjects\AnotherDjango\venv\Lib\site-packages\django\db\models\query.py", line 637, in get
    raise self.model.DoesNotExist(
django.contrib.auth.models.User.DoesNotExist: User matching query does not exist.
INFO level - 2024-01-25 01:28:28,812 django.utils.autoreload: "C:\Users\kurba\PycharmProjects\AnotherDjango\python_django\mysite\shopapp\views.py changed, reloading."
INFO level - 2024-01-25 01:28:29,608 django.utils.autoreload: "Watching for file changes with StatReloader"
ERROR level - 2024-01-25 01:28:30,240 django.request: "Internal Server Error: /ru/shop/users/20/orders/"
Traceback (most recent call last):
  File "C:\Users\kurba\PycharmProjects\AnotherDjango\venv\Lib\site-packages\django\core\handlers\exception.py", line 55, in inner
    response = get_response(request)
               ^^^^^^^^^^^^^^^^^^^^^
  File "C:\Users\kurba\PycharmProjects\AnotherDjango\venv\Lib\site-packages\django\core\handlers\base.py", line 197, in _get_response
    response = wrapped_callback(request, *callback_args, **callback_kwargs)
               ^^^^^^^^^^^^^^^^^^^^^^^^^^^^^^^^^^^^^^^^^^^^^^^^^^^^^^^^^^^^
  File "C:\Users\kurba\PycharmProjects\AnotherDjango\venv\Lib\site-packages\sentry_sdk\integrations\django\views.py", line 84, in sentry_wrapped_callback
    return callback(request, *args, **kwargs)
           ^^^^^^^^^^^^^^^^^^^^^^^^^^^^^^^^^^
  File "C:\Users\kurba\PycharmProjects\AnotherDjango\venv\Lib\site-packages\django\views\generic\base.py", line 104, in view
    return self.dispatch(request, *args, **kwargs)
           ^^^^^^^^^^^^^^^^^^^^^^^^^^^^^^^^^^^^^^^
  File "C:\Users\kurba\PycharmProjects\AnotherDjango\venv\Lib\site-packages\django\views\generic\base.py", line 143, in dispatch
    return handler(request, *args, **kwargs)
           ^^^^^^^^^^^^^^^^^^^^^^^^^^^^^^^^^
  File "C:\Users\kurba\PycharmProjects\AnotherDjango\venv\Lib\site-packages\django\views\generic\list.py", line 154, in get
    self.object_list = self.get_queryset()
                       ^^^^^^^^^^^^^^^^^^^
  File "C:\Users\kurba\PycharmProjects\AnotherDjango\python_django\mysite\shopapp\views.py", line 182, in get_queryset
    self.owner = User.objects.get(pk=self.kwargs['user_id'])
                 ^^^^^^^^^^^^^^^^^^^^^^^^^^^^^^^^^^^^^^^^^^^
  File "C:\Users\kurba\PycharmProjects\AnotherDjango\venv\Lib\site-packages\django\db\models\manager.py", line 87, in manager_method
    return getattr(self.get_queryset(), name)(*args, **kwargs)
           ^^^^^^^^^^^^^^^^^^^^^^^^^^^^^^^^^^^^^^^^^^^^^^^^^^^
  File "C:\Users\kurba\PycharmProjects\AnotherDjango\venv\Lib\site-packages\django\db\models\query.py", line 637, in get
    raise self.model.DoesNotExist(
django.contrib.auth.models.User.DoesNotExist: User matching query does not exist.
ERROR level - 2024-01-25 01:28:30,776 django.request: "Internal Server Error: /ru/shop/users/20/orders/"
Traceback (most recent call last):
  File "C:\Users\kurba\PycharmProjects\AnotherDjango\venv\Lib\site-packages\django\core\handlers\exception.py", line 55, in inner
    response = get_response(request)
               ^^^^^^^^^^^^^^^^^^^^^
  File "C:\Users\kurba\PycharmProjects\AnotherDjango\venv\Lib\site-packages\django\core\handlers\base.py", line 197, in _get_response
    response = wrapped_callback(request, *callback_args, **callback_kwargs)
               ^^^^^^^^^^^^^^^^^^^^^^^^^^^^^^^^^^^^^^^^^^^^^^^^^^^^^^^^^^^^
  File "C:\Users\kurba\PycharmProjects\AnotherDjango\venv\Lib\site-packages\sentry_sdk\integrations\django\views.py", line 84, in sentry_wrapped_callback
    return callback(request, *args, **kwargs)
           ^^^^^^^^^^^^^^^^^^^^^^^^^^^^^^^^^^
  File "C:\Users\kurba\PycharmProjects\AnotherDjango\venv\Lib\site-packages\django\views\generic\base.py", line 104, in view
    return self.dispatch(request, *args, **kwargs)
           ^^^^^^^^^^^^^^^^^^^^^^^^^^^^^^^^^^^^^^^
  File "C:\Users\kurba\PycharmProjects\AnotherDjango\venv\Lib\site-packages\django\views\generic\base.py", line 143, in dispatch
    return handler(request, *args, **kwargs)
           ^^^^^^^^^^^^^^^^^^^^^^^^^^^^^^^^^
  File "C:\Users\kurba\PycharmProjects\AnotherDjango\venv\Lib\site-packages\django\views\generic\list.py", line 154, in get
    self.object_list = self.get_queryset()
                       ^^^^^^^^^^^^^^^^^^^
  File "C:\Users\kurba\PycharmProjects\AnotherDjango\python_django\mysite\shopapp\views.py", line 182, in get_queryset
    self.owner = User.objects.get(pk=self.kwargs['user_id'])
                 ^^^^^^^^^^^^^^^^^^^^^^^^^^^^^^^^^^^^^^^^^^^
  File "C:\Users\kurba\PycharmProjects\AnotherDjango\venv\Lib\site-packages\django\db\models\manager.py", line 87, in manager_method
    return getattr(self.get_queryset(), name)(*args, **kwargs)
           ^^^^^^^^^^^^^^^^^^^^^^^^^^^^^^^^^^^^^^^^^^^^^^^^^^^
  File "C:\Users\kurba\PycharmProjects\AnotherDjango\venv\Lib\site-packages\django\db\models\query.py", line 637, in get
    raise self.model.DoesNotExist(
django.contrib.auth.models.User.DoesNotExist: User matching query does not exist.
INFO level - 2024-01-25 01:31:52,944 django.utils.autoreload: "C:\Users\kurba\PycharmProjects\AnotherDjango\python_django\mysite\shopapp\views.py changed, reloading."
INFO level - 2024-01-25 01:31:54,848 django.utils.autoreload: "Watching for file changes with StatReloader"
INFO level - 2024-01-25 01:33:25,433 django.utils.autoreload: "C:\Users\kurba\PycharmProjects\AnotherDjango\python_django\mysite\shopapp\views.py changed, reloading."
INFO level - 2024-01-25 01:33:26,684 django.utils.autoreload: "Watching for file changes with StatReloader"
ERROR level - 2024-01-25 01:33:27,549 django.request: "Internal Server Error: /ru/shop/users/5/orders/"
Traceback (most recent call last):
  File "C:\Users\kurba\PycharmProjects\AnotherDjango\venv\Lib\site-packages\django\core\handlers\exception.py", line 55, in inner
    response = get_response(request)
               ^^^^^^^^^^^^^^^^^^^^^
  File "C:\Users\kurba\PycharmProjects\AnotherDjango\venv\Lib\site-packages\django\core\handlers\base.py", line 197, in _get_response
    response = wrapped_callback(request, *callback_args, **callback_kwargs)
               ^^^^^^^^^^^^^^^^^^^^^^^^^^^^^^^^^^^^^^^^^^^^^^^^^^^^^^^^^^^^
  File "C:\Users\kurba\PycharmProjects\AnotherDjango\venv\Lib\site-packages\sentry_sdk\integrations\django\views.py", line 84, in sentry_wrapped_callback
    return callback(request, *args, **kwargs)
           ^^^^^^^^^^^^^^^^^^^^^^^^^^^^^^^^^^
  File "C:\Users\kurba\PycharmProjects\AnotherDjango\venv\Lib\site-packages\django\views\generic\base.py", line 104, in view
    return self.dispatch(request, *args, **kwargs)
           ^^^^^^^^^^^^^^^^^^^^^^^^^^^^^^^^^^^^^^^
  File "C:\Users\kurba\PycharmProjects\AnotherDjango\venv\Lib\site-packages\django\views\generic\base.py", line 143, in dispatch
    return handler(request, *args, **kwargs)
           ^^^^^^^^^^^^^^^^^^^^^^^^^^^^^^^^^
  File "C:\Users\kurba\PycharmProjects\AnotherDjango\python_django\mysite\shopapp\views.py", line 194, in get
    if not self.owner:
           ^^^^^^^^^^
AttributeError: 'UserOrderListView' object has no attribute 'owner'
INFO level - 2024-01-25 01:33:51,785 django.utils.autoreload: "C:\Users\kurba\PycharmProjects\AnotherDjango\python_django\mysite\shopapp\views.py changed, reloading."
INFO level - 2024-01-25 01:33:53,081 django.utils.autoreload: "Watching for file changes with StatReloader"
ERROR level - 2024-01-25 01:33:53,857 django.request: "Internal Server Error: /ru/shop/users/5/orders/"
Traceback (most recent call last):
  File "C:\Users\kurba\PycharmProjects\AnotherDjango\venv\Lib\site-packages\django\core\handlers\exception.py", line 55, in inner
    response = get_response(request)
               ^^^^^^^^^^^^^^^^^^^^^
  File "C:\Users\kurba\PycharmProjects\AnotherDjango\venv\Lib\site-packages\django\core\handlers\base.py", line 197, in _get_response
    response = wrapped_callback(request, *callback_args, **callback_kwargs)
               ^^^^^^^^^^^^^^^^^^^^^^^^^^^^^^^^^^^^^^^^^^^^^^^^^^^^^^^^^^^^
  File "C:\Users\kurba\PycharmProjects\AnotherDjango\venv\Lib\site-packages\sentry_sdk\integrations\django\views.py", line 84, in sentry_wrapped_callback
    return callback(request, *args, **kwargs)
           ^^^^^^^^^^^^^^^^^^^^^^^^^^^^^^^^^^
  File "C:\Users\kurba\PycharmProjects\AnotherDjango\venv\Lib\site-packages\django\views\generic\base.py", line 104, in view
    return self.dispatch(request, *args, **kwargs)
           ^^^^^^^^^^^^^^^^^^^^^^^^^^^^^^^^^^^^^^^
  File "C:\Users\kurba\PycharmProjects\AnotherDjango\venv\Lib\site-packages\django\views\generic\base.py", line 143, in dispatch
    return handler(request, *args, **kwargs)
           ^^^^^^^^^^^^^^^^^^^^^^^^^^^^^^^^^
  File "C:\Users\kurba\PycharmProjects\AnotherDjango\python_django\mysite\shopapp\views.py", line 182, in get
    if not self.owner:
           ^^^^^^^^^^
AttributeError: 'UserOrderListView' object has no attribute 'owner'
ERROR level - 2024-01-25 01:33:56,820 django.request: "Internal Server Error: /ru/shop/users/5/orders/"
Traceback (most recent call last):
  File "C:\Users\kurba\PycharmProjects\AnotherDjango\venv\Lib\site-packages\django\core\handlers\exception.py", line 55, in inner
    response = get_response(request)
               ^^^^^^^^^^^^^^^^^^^^^
  File "C:\Users\kurba\PycharmProjects\AnotherDjango\venv\Lib\site-packages\django\core\handlers\base.py", line 197, in _get_response
    response = wrapped_callback(request, *callback_args, **callback_kwargs)
               ^^^^^^^^^^^^^^^^^^^^^^^^^^^^^^^^^^^^^^^^^^^^^^^^^^^^^^^^^^^^
  File "C:\Users\kurba\PycharmProjects\AnotherDjango\venv\Lib\site-packages\sentry_sdk\integrations\django\views.py", line 84, in sentry_wrapped_callback
    return callback(request, *args, **kwargs)
           ^^^^^^^^^^^^^^^^^^^^^^^^^^^^^^^^^^
  File "C:\Users\kurba\PycharmProjects\AnotherDjango\venv\Lib\site-packages\django\views\generic\base.py", line 104, in view
    return self.dispatch(request, *args, **kwargs)
           ^^^^^^^^^^^^^^^^^^^^^^^^^^^^^^^^^^^^^^^
  File "C:\Users\kurba\PycharmProjects\AnotherDjango\venv\Lib\site-packages\django\views\generic\base.py", line 143, in dispatch
    return handler(request, *args, **kwargs)
           ^^^^^^^^^^^^^^^^^^^^^^^^^^^^^^^^^
  File "C:\Users\kurba\PycharmProjects\AnotherDjango\python_django\mysite\shopapp\views.py", line 182, in get
    if not self.owner:
           ^^^^^^^^^^
AttributeError: 'UserOrderListView' object has no attribute 'owner'
INFO level - 2024-01-25 01:34:12,746 django.utils.autoreload: "C:\Users\kurba\PycharmProjects\AnotherDjango\python_django\mysite\shopapp\views.py changed, reloading."
INFO level - 2024-01-25 01:34:13,987 django.utils.autoreload: "Watching for file changes with StatReloader"
INFO level - 2024-01-25 01:35:17,133 django.utils.autoreload: "C:\Users\kurba\PycharmProjects\AnotherDjango\python_django\mysite\shopapp\views.py changed, reloading."
INFO level - 2024-01-25 01:35:18,304 django.utils.autoreload: "Watching for file changes with StatReloader"
WARNING level - 2024-01-25 01:35:19,056 django.request: "Not Found: /ru/shop/users/5/orders/"
INFO level - 2024-01-25 01:35:47,228 django.utils.autoreload: "C:\Users\kurba\PycharmProjects\AnotherDjango\python_django\mysite\shopapp\views.py changed, reloading."
INFO level - 2024-01-25 01:35:48,343 django.utils.autoreload: "Watching for file changes with StatReloader"
ERROR level - 2024-01-25 01:35:53,982 django.request: "Internal Server Error: /ru/shop/users/20/orders/"
Traceback (most recent call last):
  File "C:\Users\kurba\PycharmProjects\AnotherDjango\venv\Lib\site-packages\django\core\handlers\exception.py", line 55, in inner
    response = get_response(request)
               ^^^^^^^^^^^^^^^^^^^^^
  File "C:\Users\kurba\PycharmProjects\AnotherDjango\venv\Lib\site-packages\django\core\handlers\base.py", line 197, in _get_response
    response = wrapped_callback(request, *callback_args, **callback_kwargs)
               ^^^^^^^^^^^^^^^^^^^^^^^^^^^^^^^^^^^^^^^^^^^^^^^^^^^^^^^^^^^^
  File "C:\Users\kurba\PycharmProjects\AnotherDjango\venv\Lib\site-packages\sentry_sdk\integrations\django\views.py", line 84, in sentry_wrapped_callback
    return callback(request, *args, **kwargs)
           ^^^^^^^^^^^^^^^^^^^^^^^^^^^^^^^^^^
  File "C:\Users\kurba\PycharmProjects\AnotherDjango\venv\Lib\site-packages\django\views\generic\base.py", line 104, in view
    return self.dispatch(request, *args, **kwargs)
           ^^^^^^^^^^^^^^^^^^^^^^^^^^^^^^^^^^^^^^^
  File "C:\Users\kurba\PycharmProjects\AnotherDjango\venv\Lib\site-packages\django\views\generic\base.py", line 143, in dispatch
    return handler(request, *args, **kwargs)
           ^^^^^^^^^^^^^^^^^^^^^^^^^^^^^^^^^
  File "C:\Users\kurba\PycharmProjects\AnotherDjango\venv\Lib\site-packages\django\views\generic\list.py", line 154, in get
    self.object_list = self.get_queryset()
                       ^^^^^^^^^^^^^^^^^^^
  File "C:\Users\kurba\PycharmProjects\AnotherDjango\python_django\mysite\shopapp\views.py", line 187, in get_queryset
    self.owner = User.objects.get(pk=self.kwargs['user_id'])
                 ^^^^^^^^^^^^^^^^^^^^^^^^^^^^^^^^^^^^^^^^^^^
  File "C:\Users\kurba\PycharmProjects\AnotherDjango\venv\Lib\site-packages\django\db\models\manager.py", line 87, in manager_method
    return getattr(self.get_queryset(), name)(*args, **kwargs)
           ^^^^^^^^^^^^^^^^^^^^^^^^^^^^^^^^^^^^^^^^^^^^^^^^^^^
  File "C:\Users\kurba\PycharmProjects\AnotherDjango\venv\Lib\site-packages\django\db\models\query.py", line 637, in get
    raise self.model.DoesNotExist(
django.contrib.auth.models.User.DoesNotExist: User matching query does not exist.
INFO level - 2024-01-25 01:36:32,043 django.utils.autoreload: "C:\Users\kurba\PycharmProjects\AnotherDjango\python_django\mysite\shopapp\views.py changed, reloading."
INFO level - 2024-01-25 01:36:33,406 django.utils.autoreload: "Watching for file changes with StatReloader"
ERROR level - 2024-01-25 01:36:34,222 django.request: "Internal Server Error: /ru/shop/users/20/orders/"
Traceback (most recent call last):
  File "C:\Users\kurba\PycharmProjects\AnotherDjango\venv\Lib\site-packages\django\core\handlers\exception.py", line 55, in inner
    response = get_response(request)
               ^^^^^^^^^^^^^^^^^^^^^
  File "C:\Users\kurba\PycharmProjects\AnotherDjango\venv\Lib\site-packages\django\core\handlers\base.py", line 197, in _get_response
    response = wrapped_callback(request, *callback_args, **callback_kwargs)
               ^^^^^^^^^^^^^^^^^^^^^^^^^^^^^^^^^^^^^^^^^^^^^^^^^^^^^^^^^^^^
  File "C:\Users\kurba\PycharmProjects\AnotherDjango\venv\Lib\site-packages\sentry_sdk\integrations\django\views.py", line 84, in sentry_wrapped_callback
    return callback(request, *args, **kwargs)
           ^^^^^^^^^^^^^^^^^^^^^^^^^^^^^^^^^^
  File "C:\Users\kurba\PycharmProjects\AnotherDjango\venv\Lib\site-packages\django\views\generic\base.py", line 104, in view
    return self.dispatch(request, *args, **kwargs)
           ^^^^^^^^^^^^^^^^^^^^^^^^^^^^^^^^^^^^^^^
  File "C:\Users\kurba\PycharmProjects\AnotherDjango\venv\Lib\site-packages\django\views\generic\base.py", line 143, in dispatch
    return handler(request, *args, **kwargs)
           ^^^^^^^^^^^^^^^^^^^^^^^^^^^^^^^^^
  File "C:\Users\kurba\PycharmProjects\AnotherDjango\venv\Lib\site-packages\django\views\generic\list.py", line 154, in get
    self.object_list = self.get_queryset()
                       ^^^^^^^^^^^^^^^^^^^
  File "C:\Users\kurba\PycharmProjects\AnotherDjango\python_django\mysite\shopapp\views.py", line 187, in get_queryset
    self.owner = User.objects.get(pk=self.kwargs['user_id'])
                 ^^^^^^^^^^^^^^^^^^^^^^^^^^^^^^^^^^^^^^^^^^^
  File "C:\Users\kurba\PycharmProjects\AnotherDjango\venv\Lib\site-packages\django\db\models\manager.py", line 87, in manager_method
    return getattr(self.get_queryset(), name)(*args, **kwargs)
           ^^^^^^^^^^^^^^^^^^^^^^^^^^^^^^^^^^^^^^^^^^^^^^^^^^^
  File "C:\Users\kurba\PycharmProjects\AnotherDjango\venv\Lib\site-packages\django\db\models\query.py", line 637, in get
    raise self.model.DoesNotExist(
django.contrib.auth.models.User.DoesNotExist: User matching query does not exist.
ERROR level - 2024-01-25 01:36:50,466 django.request: "Internal Server Error: /ru/shop/users/12/orders/"
Traceback (most recent call last):
  File "C:\Users\kurba\PycharmProjects\AnotherDjango\venv\Lib\site-packages\django\core\handlers\exception.py", line 55, in inner
    response = get_response(request)
               ^^^^^^^^^^^^^^^^^^^^^
  File "C:\Users\kurba\PycharmProjects\AnotherDjango\venv\Lib\site-packages\django\core\handlers\base.py", line 197, in _get_response
    response = wrapped_callback(request, *callback_args, **callback_kwargs)
               ^^^^^^^^^^^^^^^^^^^^^^^^^^^^^^^^^^^^^^^^^^^^^^^^^^^^^^^^^^^^
  File "C:\Users\kurba\PycharmProjects\AnotherDjango\venv\Lib\site-packages\sentry_sdk\integrations\django\views.py", line 84, in sentry_wrapped_callback
    return callback(request, *args, **kwargs)
           ^^^^^^^^^^^^^^^^^^^^^^^^^^^^^^^^^^
  File "C:\Users\kurba\PycharmProjects\AnotherDjango\venv\Lib\site-packages\django\views\generic\base.py", line 104, in view
    return self.dispatch(request, *args, **kwargs)
           ^^^^^^^^^^^^^^^^^^^^^^^^^^^^^^^^^^^^^^^
  File "C:\Users\kurba\PycharmProjects\AnotherDjango\venv\Lib\site-packages\django\views\generic\base.py", line 143, in dispatch
    return handler(request, *args, **kwargs)
           ^^^^^^^^^^^^^^^^^^^^^^^^^^^^^^^^^
  File "C:\Users\kurba\PycharmProjects\AnotherDjango\venv\Lib\site-packages\django\views\generic\list.py", line 154, in get
    self.object_list = self.get_queryset()
                       ^^^^^^^^^^^^^^^^^^^
  File "C:\Users\kurba\PycharmProjects\AnotherDjango\python_django\mysite\shopapp\views.py", line 187, in get_queryset
    self.owner = User.objects.get(pk=self.kwargs['user_id'])
                 ^^^^^^^^^^^^^^^^^^^^^^^^^^^^^^^^^^^^^^^^^^^
  File "C:\Users\kurba\PycharmProjects\AnotherDjango\venv\Lib\site-packages\django\db\models\manager.py", line 87, in manager_method
    return getattr(self.get_queryset(), name)(*args, **kwargs)
           ^^^^^^^^^^^^^^^^^^^^^^^^^^^^^^^^^^^^^^^^^^^^^^^^^^^
  File "C:\Users\kurba\PycharmProjects\AnotherDjango\venv\Lib\site-packages\django\db\models\query.py", line 637, in get
    raise self.model.DoesNotExist(
django.contrib.auth.models.User.DoesNotExist: User matching query does not exist.
ERROR level - 2024-01-25 01:36:55,033 django.request: "Internal Server Error: /ru/shop/users/13/orders/"
Traceback (most recent call last):
  File "C:\Users\kurba\PycharmProjects\AnotherDjango\venv\Lib\site-packages\django\core\handlers\exception.py", line 55, in inner
    response = get_response(request)
               ^^^^^^^^^^^^^^^^^^^^^
  File "C:\Users\kurba\PycharmProjects\AnotherDjango\venv\Lib\site-packages\django\core\handlers\base.py", line 197, in _get_response
    response = wrapped_callback(request, *callback_args, **callback_kwargs)
               ^^^^^^^^^^^^^^^^^^^^^^^^^^^^^^^^^^^^^^^^^^^^^^^^^^^^^^^^^^^^
  File "C:\Users\kurba\PycharmProjects\AnotherDjango\venv\Lib\site-packages\sentry_sdk\integrations\django\views.py", line 84, in sentry_wrapped_callback
    return callback(request, *args, **kwargs)
           ^^^^^^^^^^^^^^^^^^^^^^^^^^^^^^^^^^
  File "C:\Users\kurba\PycharmProjects\AnotherDjango\venv\Lib\site-packages\django\views\generic\base.py", line 104, in view
    return self.dispatch(request, *args, **kwargs)
           ^^^^^^^^^^^^^^^^^^^^^^^^^^^^^^^^^^^^^^^
  File "C:\Users\kurba\PycharmProjects\AnotherDjango\venv\Lib\site-packages\django\views\generic\base.py", line 143, in dispatch
    return handler(request, *args, **kwargs)
           ^^^^^^^^^^^^^^^^^^^^^^^^^^^^^^^^^
  File "C:\Users\kurba\PycharmProjects\AnotherDjango\venv\Lib\site-packages\django\views\generic\list.py", line 154, in get
    self.object_list = self.get_queryset()
                       ^^^^^^^^^^^^^^^^^^^
  File "C:\Users\kurba\PycharmProjects\AnotherDjango\python_django\mysite\shopapp\views.py", line 187, in get_queryset
    self.owner = User.objects.get(pk=self.kwargs['user_id'])
                 ^^^^^^^^^^^^^^^^^^^^^^^^^^^^^^^^^^^^^^^^^^^
  File "C:\Users\kurba\PycharmProjects\AnotherDjango\venv\Lib\site-packages\django\db\models\manager.py", line 87, in manager_method
    return getattr(self.get_queryset(), name)(*args, **kwargs)
           ^^^^^^^^^^^^^^^^^^^^^^^^^^^^^^^^^^^^^^^^^^^^^^^^^^^
  File "C:\Users\kurba\PycharmProjects\AnotherDjango\venv\Lib\site-packages\django\db\models\query.py", line 637, in get
    raise self.model.DoesNotExist(
django.contrib.auth.models.User.DoesNotExist: User matching query does not exist.
INFO level - 2024-01-25 01:38:15,568 django.utils.autoreload: "C:\Users\kurba\PycharmProjects\AnotherDjango\python_django\mysite\shopapp\views.py changed, reloading."
INFO level - 2024-01-25 01:38:16,763 django.utils.autoreload: "Watching for file changes with StatReloader"
INFO level - 2024-01-25 01:39:07,013 django.utils.autoreload: "C:\Users\kurba\PycharmProjects\AnotherDjango\python_django\mysite\shopapp\views.py changed, reloading."
INFO level - 2024-01-25 01:39:08,544 django.utils.autoreload: "Watching for file changes with StatReloader"
ERROR level - 2024-01-25 01:39:09,229 django.request: "Internal Server Error: /ru/shop/users/13/orders/"
Traceback (most recent call last):
  File "C:\Users\kurba\PycharmProjects\AnotherDjango\venv\Lib\site-packages\django\core\handlers\exception.py", line 55, in inner
    response = get_response(request)
               ^^^^^^^^^^^^^^^^^^^^^
  File "C:\Users\kurba\PycharmProjects\AnotherDjango\venv\Lib\site-packages\django\core\handlers\base.py", line 197, in _get_response
    response = wrapped_callback(request, *callback_args, **callback_kwargs)
               ^^^^^^^^^^^^^^^^^^^^^^^^^^^^^^^^^^^^^^^^^^^^^^^^^^^^^^^^^^^^
  File "C:\Users\kurba\PycharmProjects\AnotherDjango\venv\Lib\site-packages\sentry_sdk\integrations\django\views.py", line 84, in sentry_wrapped_callback
    return callback(request, *args, **kwargs)
           ^^^^^^^^^^^^^^^^^^^^^^^^^^^^^^^^^^
  File "C:\Users\kurba\PycharmProjects\AnotherDjango\venv\Lib\site-packages\django\views\generic\base.py", line 104, in view
    return self.dispatch(request, *args, **kwargs)
           ^^^^^^^^^^^^^^^^^^^^^^^^^^^^^^^^^^^^^^^
  File "C:\Users\kurba\PycharmProjects\AnotherDjango\venv\Lib\site-packages\django\views\generic\base.py", line 143, in dispatch
    return handler(request, *args, **kwargs)
           ^^^^^^^^^^^^^^^^^^^^^^^^^^^^^^^^^
  File "C:\Users\kurba\PycharmProjects\AnotherDjango\python_django\mysite\shopapp\views.py", line 182, in get
    response = super().get(request, *args, **kwargs)
               ^^^^^^^^^^^^^^^^^^^^^^^^^^^^^^^^^^^^^
  File "C:\Users\kurba\PycharmProjects\AnotherDjango\venv\Lib\site-packages\django\views\generic\list.py", line 154, in get
    self.object_list = self.get_queryset()
                       ^^^^^^^^^^^^^^^^^^^
  File "C:\Users\kurba\PycharmProjects\AnotherDjango\python_django\mysite\shopapp\views.py", line 186, in get_queryset
    self.owner = User.objects.get(pk=self.kwargs['user_id'])
                 ^^^^^^^^^^^^^^^^^^^^^^^^^^^^^^^^^^^^^^^^^^^
  File "C:\Users\kurba\PycharmProjects\AnotherDjango\venv\Lib\site-packages\django\db\models\manager.py", line 87, in manager_method
    return getattr(self.get_queryset(), name)(*args, **kwargs)
           ^^^^^^^^^^^^^^^^^^^^^^^^^^^^^^^^^^^^^^^^^^^^^^^^^^^
  File "C:\Users\kurba\PycharmProjects\AnotherDjango\venv\Lib\site-packages\django\db\models\query.py", line 637, in get
    raise self.model.DoesNotExist(
django.contrib.auth.models.User.DoesNotExist: User matching query does not exist.
ERROR level - 2024-01-25 01:39:09,761 django.request: "Internal Server Error: /ru/shop/users/13/orders/"
Traceback (most recent call last):
  File "C:\Users\kurba\PycharmProjects\AnotherDjango\venv\Lib\site-packages\django\core\handlers\exception.py", line 55, in inner
    response = get_response(request)
               ^^^^^^^^^^^^^^^^^^^^^
  File "C:\Users\kurba\PycharmProjects\AnotherDjango\venv\Lib\site-packages\django\core\handlers\base.py", line 197, in _get_response
    response = wrapped_callback(request, *callback_args, **callback_kwargs)
               ^^^^^^^^^^^^^^^^^^^^^^^^^^^^^^^^^^^^^^^^^^^^^^^^^^^^^^^^^^^^
  File "C:\Users\kurba\PycharmProjects\AnotherDjango\venv\Lib\site-packages\sentry_sdk\integrations\django\views.py", line 84, in sentry_wrapped_callback
    return callback(request, *args, **kwargs)
           ^^^^^^^^^^^^^^^^^^^^^^^^^^^^^^^^^^
  File "C:\Users\kurba\PycharmProjects\AnotherDjango\venv\Lib\site-packages\django\views\generic\base.py", line 104, in view
    return self.dispatch(request, *args, **kwargs)
           ^^^^^^^^^^^^^^^^^^^^^^^^^^^^^^^^^^^^^^^
  File "C:\Users\kurba\PycharmProjects\AnotherDjango\venv\Lib\site-packages\django\views\generic\base.py", line 143, in dispatch
    return handler(request, *args, **kwargs)
           ^^^^^^^^^^^^^^^^^^^^^^^^^^^^^^^^^
  File "C:\Users\kurba\PycharmProjects\AnotherDjango\python_django\mysite\shopapp\views.py", line 182, in get
    response = super().get(request, *args, **kwargs)
               ^^^^^^^^^^^^^^^^^^^^^^^^^^^^^^^^^^^^^
  File "C:\Users\kurba\PycharmProjects\AnotherDjango\venv\Lib\site-packages\django\views\generic\list.py", line 154, in get
    self.object_list = self.get_queryset()
                       ^^^^^^^^^^^^^^^^^^^
  File "C:\Users\kurba\PycharmProjects\AnotherDjango\python_django\mysite\shopapp\views.py", line 186, in get_queryset
    self.owner = User.objects.get(pk=self.kwargs['user_id'])
                 ^^^^^^^^^^^^^^^^^^^^^^^^^^^^^^^^^^^^^^^^^^^
  File "C:\Users\kurba\PycharmProjects\AnotherDjango\venv\Lib\site-packages\django\db\models\manager.py", line 87, in manager_method
    return getattr(self.get_queryset(), name)(*args, **kwargs)
           ^^^^^^^^^^^^^^^^^^^^^^^^^^^^^^^^^^^^^^^^^^^^^^^^^^^
  File "C:\Users\kurba\PycharmProjects\AnotherDjango\venv\Lib\site-packages\django\db\models\query.py", line 637, in get
    raise self.model.DoesNotExist(
django.contrib.auth.models.User.DoesNotExist: User matching query does not exist.
INFO level - 2024-01-25 01:39:58,336 django.utils.autoreload: "C:\Users\kurba\PycharmProjects\AnotherDjango\python_django\mysite\shopapp\views.py changed, reloading."
INFO level - 2024-01-25 01:39:59,474 django.utils.autoreload: "Watching for file changes with StatReloader"
ERROR level - 2024-01-25 01:40:00,227 django.request: "Internal Server Error: /ru/shop/users/13/orders/"
Traceback (most recent call last):
  File "C:\Users\kurba\PycharmProjects\AnotherDjango\venv\Lib\site-packages\django\core\handlers\exception.py", line 55, in inner
    response = get_response(request)
               ^^^^^^^^^^^^^^^^^^^^^
  File "C:\Users\kurba\PycharmProjects\AnotherDjango\venv\Lib\site-packages\django\core\handlers\base.py", line 197, in _get_response
    response = wrapped_callback(request, *callback_args, **callback_kwargs)
               ^^^^^^^^^^^^^^^^^^^^^^^^^^^^^^^^^^^^^^^^^^^^^^^^^^^^^^^^^^^^
  File "C:\Users\kurba\PycharmProjects\AnotherDjango\venv\Lib\site-packages\sentry_sdk\integrations\django\views.py", line 84, in sentry_wrapped_callback
    return callback(request, *args, **kwargs)
           ^^^^^^^^^^^^^^^^^^^^^^^^^^^^^^^^^^
  File "C:\Users\kurba\PycharmProjects\AnotherDjango\venv\Lib\site-packages\django\views\generic\base.py", line 104, in view
    return self.dispatch(request, *args, **kwargs)
           ^^^^^^^^^^^^^^^^^^^^^^^^^^^^^^^^^^^^^^^
  File "C:\Users\kurba\PycharmProjects\AnotherDjango\venv\Lib\site-packages\django\views\generic\base.py", line 143, in dispatch
    return handler(request, *args, **kwargs)
           ^^^^^^^^^^^^^^^^^^^^^^^^^^^^^^^^^
  File "C:\Users\kurba\PycharmProjects\AnotherDjango\python_django\mysite\shopapp\views.py", line 182, in get
    response = super().get(request, *args, **kwargs)
               ^^^^^^^^^^^^^^^^^^^^^^^^^^^^^^^^^^^^^
  File "C:\Users\kurba\PycharmProjects\AnotherDjango\venv\Lib\site-packages\django\views\generic\list.py", line 154, in get
    self.object_list = self.get_queryset()
                       ^^^^^^^^^^^^^^^^^^^
  File "C:\Users\kurba\PycharmProjects\AnotherDjango\python_django\mysite\shopapp\views.py", line 187, in get_queryset
    self.owner = User.objects.get(pk=self.kwargs['user_id'])
                 ^^^^^^^^^^^^^^^^^^^^^^^^^^^^^^^^^^^^^^^^^^^
  File "C:\Users\kurba\PycharmProjects\AnotherDjango\venv\Lib\site-packages\django\db\models\manager.py", line 87, in manager_method
    return getattr(self.get_queryset(), name)(*args, **kwargs)
           ^^^^^^^^^^^^^^^^^^^^^^^^^^^^^^^^^^^^^^^^^^^^^^^^^^^
  File "C:\Users\kurba\PycharmProjects\AnotherDjango\venv\Lib\site-packages\django\db\models\query.py", line 637, in get
    raise self.model.DoesNotExist(
django.contrib.auth.models.User.DoesNotExist: User matching query does not exist.
INFO level - 2024-01-25 01:40:25,207 django.utils.autoreload: "C:\Users\kurba\PycharmProjects\AnotherDjango\python_django\mysite\shopapp\views.py changed, reloading."
INFO level - 2024-01-25 01:40:26,305 django.utils.autoreload: "Watching for file changes with StatReloader"
ERROR level - 2024-01-25 01:40:27,033 django.request: "Internal Server Error: /ru/shop/users/13/orders/"
Traceback (most recent call last):
  File "C:\Users\kurba\PycharmProjects\AnotherDjango\venv\Lib\site-packages\django\core\handlers\exception.py", line 55, in inner
    response = get_response(request)
               ^^^^^^^^^^^^^^^^^^^^^
  File "C:\Users\kurba\PycharmProjects\AnotherDjango\venv\Lib\site-packages\django\core\handlers\base.py", line 197, in _get_response
    response = wrapped_callback(request, *callback_args, **callback_kwargs)
               ^^^^^^^^^^^^^^^^^^^^^^^^^^^^^^^^^^^^^^^^^^^^^^^^^^^^^^^^^^^^
  File "C:\Users\kurba\PycharmProjects\AnotherDjango\venv\Lib\site-packages\sentry_sdk\integrations\django\views.py", line 84, in sentry_wrapped_callback
    return callback(request, *args, **kwargs)
           ^^^^^^^^^^^^^^^^^^^^^^^^^^^^^^^^^^
  File "C:\Users\kurba\PycharmProjects\AnotherDjango\venv\Lib\site-packages\django\views\generic\base.py", line 104, in view
    return self.dispatch(request, *args, **kwargs)
           ^^^^^^^^^^^^^^^^^^^^^^^^^^^^^^^^^^^^^^^
  File "C:\Users\kurba\PycharmProjects\AnotherDjango\venv\Lib\site-packages\django\views\generic\base.py", line 143, in dispatch
    return handler(request, *args, **kwargs)
           ^^^^^^^^^^^^^^^^^^^^^^^^^^^^^^^^^
  File "C:\Users\kurba\PycharmProjects\AnotherDjango\python_django\mysite\shopapp\views.py", line 182, in get
    response = super().get(request, *args, **kwargs)
               ^^^^^^^^^^^^^^^^^^^^^^^^^^^^^^^^^^^^^
  File "C:\Users\kurba\PycharmProjects\AnotherDjango\venv\Lib\site-packages\django\views\generic\list.py", line 154, in get
    self.object_list = self.get_queryset()
                       ^^^^^^^^^^^^^^^^^^^
  File "C:\Users\kurba\PycharmProjects\AnotherDjango\python_django\mysite\shopapp\views.py", line 187, in get_queryset
    self.owner = User.objects.get(pk=self.kwargs['user_id'])
                 ^^^^^^^^^^^^^^^^^^^^^^^^^^^^^^^^^^^^^^^^^^^
  File "C:\Users\kurba\PycharmProjects\AnotherDjango\venv\Lib\site-packages\django\db\models\manager.py", line 87, in manager_method
    return getattr(self.get_queryset(), name)(*args, **kwargs)
           ^^^^^^^^^^^^^^^^^^^^^^^^^^^^^^^^^^^^^^^^^^^^^^^^^^^
  File "C:\Users\kurba\PycharmProjects\AnotherDjango\venv\Lib\site-packages\django\db\models\query.py", line 637, in get
    raise self.model.DoesNotExist(
django.contrib.auth.models.User.DoesNotExist: User matching query does not exist.
INFO level - 2024-01-25 01:40:30,077 django.utils.autoreload: "C:\Users\kurba\PycharmProjects\AnotherDjango\python_django\mysite\shopapp\views.py changed, reloading."
INFO level - 2024-01-25 01:40:31,267 django.utils.autoreload: "Watching for file changes with StatReloader"
ERROR level - 2024-01-25 01:40:32,041 django.request: "Internal Server Error: /ru/shop/users/13/orders/"
Traceback (most recent call last):
  File "C:\Users\kurba\PycharmProjects\AnotherDjango\venv\Lib\site-packages\django\core\handlers\exception.py", line 55, in inner
    response = get_response(request)
               ^^^^^^^^^^^^^^^^^^^^^
  File "C:\Users\kurba\PycharmProjects\AnotherDjango\venv\Lib\site-packages\django\core\handlers\base.py", line 197, in _get_response
    response = wrapped_callback(request, *callback_args, **callback_kwargs)
               ^^^^^^^^^^^^^^^^^^^^^^^^^^^^^^^^^^^^^^^^^^^^^^^^^^^^^^^^^^^^
  File "C:\Users\kurba\PycharmProjects\AnotherDjango\venv\Lib\site-packages\sentry_sdk\integrations\django\views.py", line 84, in sentry_wrapped_callback
    return callback(request, *args, **kwargs)
           ^^^^^^^^^^^^^^^^^^^^^^^^^^^^^^^^^^
  File "C:\Users\kurba\PycharmProjects\AnotherDjango\venv\Lib\site-packages\django\views\generic\base.py", line 104, in view
    return self.dispatch(request, *args, **kwargs)
           ^^^^^^^^^^^^^^^^^^^^^^^^^^^^^^^^^^^^^^^
  File "C:\Users\kurba\PycharmProjects\AnotherDjango\venv\Lib\site-packages\django\views\generic\base.py", line 143, in dispatch
    return handler(request, *args, **kwargs)
           ^^^^^^^^^^^^^^^^^^^^^^^^^^^^^^^^^
  File "C:\Users\kurba\PycharmProjects\AnotherDjango\python_django\mysite\shopapp\views.py", line 182, in get
    response = super().get(request, *args, **kwargs)
               ^^^^^^^^^^^^^^^^^^^^^^^^^^^^^^^^^^^^^
  File "C:\Users\kurba\PycharmProjects\AnotherDjango\venv\Lib\site-packages\django\views\generic\list.py", line 154, in get
    self.object_list = self.get_queryset()
                       ^^^^^^^^^^^^^^^^^^^
  File "C:\Users\kurba\PycharmProjects\AnotherDjango\python_django\mysite\shopapp\views.py", line 187, in get_queryset
    self.owner = User.objects.get(pk=self.kwargs['user_id'])
                 ^^^^^^^^^^^^^^^^^^^^^^^^^^^^^^^^^^^^^^^^^^^
  File "C:\Users\kurba\PycharmProjects\AnotherDjango\venv\Lib\site-packages\django\db\models\manager.py", line 87, in manager_method
    return getattr(self.get_queryset(), name)(*args, **kwargs)
           ^^^^^^^^^^^^^^^^^^^^^^^^^^^^^^^^^^^^^^^^^^^^^^^^^^^
  File "C:\Users\kurba\PycharmProjects\AnotherDjango\venv\Lib\site-packages\django\db\models\query.py", line 637, in get
    raise self.model.DoesNotExist(
django.contrib.auth.models.User.DoesNotExist: User matching query does not exist.
WARNING level - 2024-01-25 01:40:35,265 django.request: "Not Found: /ru/shop/users/5/orders/"
WARNING level - 2024-01-25 01:40:37,482 django.request: "Not Found: /ru/shop/users/5/orders/"
INFO level - 2024-01-25 01:41:03,150 django.utils.autoreload: "C:\Users\kurba\PycharmProjects\AnotherDjango\python_django\mysite\shopapp\views.py changed, reloading."
INFO level - 2024-01-25 01:41:04,427 django.utils.autoreload: "Watching for file changes with StatReloader"
WARNING level - 2024-01-25 01:41:05,594 django.request: "Not Found: /ru/shop/users/5/orders/"
INFO level - 2024-01-25 01:41:13,498 django.utils.autoreload: "C:\Users\kurba\PycharmProjects\AnotherDjango\python_django\mysite\shopapp\views.py changed, reloading."
INFO level - 2024-01-25 01:41:14,623 django.utils.autoreload: "Watching for file changes with StatReloader"
ERROR level - 2024-01-25 01:41:19,011 django.request: "Internal Server Error: /ru/shop/users/20/orders/"
Traceback (most recent call last):
  File "C:\Users\kurba\PycharmProjects\AnotherDjango\venv\Lib\site-packages\django\core\handlers\exception.py", line 55, in inner
    response = get_response(request)
               ^^^^^^^^^^^^^^^^^^^^^
  File "C:\Users\kurba\PycharmProjects\AnotherDjango\venv\Lib\site-packages\django\core\handlers\base.py", line 197, in _get_response
    response = wrapped_callback(request, *callback_args, **callback_kwargs)
               ^^^^^^^^^^^^^^^^^^^^^^^^^^^^^^^^^^^^^^^^^^^^^^^^^^^^^^^^^^^^
  File "C:\Users\kurba\PycharmProjects\AnotherDjango\venv\Lib\site-packages\sentry_sdk\integrations\django\views.py", line 84, in sentry_wrapped_callback
    return callback(request, *args, **kwargs)
           ^^^^^^^^^^^^^^^^^^^^^^^^^^^^^^^^^^
  File "C:\Users\kurba\PycharmProjects\AnotherDjango\venv\Lib\site-packages\django\views\generic\base.py", line 104, in view
    return self.dispatch(request, *args, **kwargs)
           ^^^^^^^^^^^^^^^^^^^^^^^^^^^^^^^^^^^^^^^
  File "C:\Users\kurba\PycharmProjects\AnotherDjango\venv\Lib\site-packages\django\views\generic\base.py", line 143, in dispatch
    return handler(request, *args, **kwargs)
           ^^^^^^^^^^^^^^^^^^^^^^^^^^^^^^^^^
  File "C:\Users\kurba\PycharmProjects\AnotherDjango\python_django\mysite\shopapp\views.py", line 182, in get
    response = super().get(request, *args, **kwargs)
               ^^^^^^^^^^^^^^^^^^^^^^^^^^^^^^^^^^^^^
  File "C:\Users\kurba\PycharmProjects\AnotherDjango\venv\Lib\site-packages\django\views\generic\list.py", line 154, in get
    self.object_list = self.get_queryset()
                       ^^^^^^^^^^^^^^^^^^^
  File "C:\Users\kurba\PycharmProjects\AnotherDjango\python_django\mysite\shopapp\views.py", line 188, in get_queryset
    self.owner = User.objects.get(pk=self.kwargs['user_id'])
                 ^^^^^^^^^^^^^^^^^^^^^^^^^^^^^^^^^^^^^^^^^^^
  File "C:\Users\kurba\PycharmProjects\AnotherDjango\venv\Lib\site-packages\django\db\models\manager.py", line 87, in manager_method
    return getattr(self.get_queryset(), name)(*args, **kwargs)
           ^^^^^^^^^^^^^^^^^^^^^^^^^^^^^^^^^^^^^^^^^^^^^^^^^^^
  File "C:\Users\kurba\PycharmProjects\AnotherDjango\venv\Lib\site-packages\django\db\models\query.py", line 637, in get
    raise self.model.DoesNotExist(
django.contrib.auth.models.User.DoesNotExist: User matching query does not exist.
ERROR level - 2024-01-25 01:41:21,080 django.request: "Internal Server Error: /ru/shop/users/20/orders/"
Traceback (most recent call last):
  File "C:\Users\kurba\PycharmProjects\AnotherDjango\venv\Lib\site-packages\django\core\handlers\exception.py", line 55, in inner
    response = get_response(request)
               ^^^^^^^^^^^^^^^^^^^^^
  File "C:\Users\kurba\PycharmProjects\AnotherDjango\venv\Lib\site-packages\django\core\handlers\base.py", line 197, in _get_response
    response = wrapped_callback(request, *callback_args, **callback_kwargs)
               ^^^^^^^^^^^^^^^^^^^^^^^^^^^^^^^^^^^^^^^^^^^^^^^^^^^^^^^^^^^^
  File "C:\Users\kurba\PycharmProjects\AnotherDjango\venv\Lib\site-packages\sentry_sdk\integrations\django\views.py", line 84, in sentry_wrapped_callback
    return callback(request, *args, **kwargs)
           ^^^^^^^^^^^^^^^^^^^^^^^^^^^^^^^^^^
  File "C:\Users\kurba\PycharmProjects\AnotherDjango\venv\Lib\site-packages\django\views\generic\base.py", line 104, in view
    return self.dispatch(request, *args, **kwargs)
           ^^^^^^^^^^^^^^^^^^^^^^^^^^^^^^^^^^^^^^^
  File "C:\Users\kurba\PycharmProjects\AnotherDjango\venv\Lib\site-packages\django\views\generic\base.py", line 143, in dispatch
    return handler(request, *args, **kwargs)
           ^^^^^^^^^^^^^^^^^^^^^^^^^^^^^^^^^
  File "C:\Users\kurba\PycharmProjects\AnotherDjango\python_django\mysite\shopapp\views.py", line 182, in get
    response = super().get(request, *args, **kwargs)
               ^^^^^^^^^^^^^^^^^^^^^^^^^^^^^^^^^^^^^
  File "C:\Users\kurba\PycharmProjects\AnotherDjango\venv\Lib\site-packages\django\views\generic\list.py", line 154, in get
    self.object_list = self.get_queryset()
                       ^^^^^^^^^^^^^^^^^^^
  File "C:\Users\kurba\PycharmProjects\AnotherDjango\python_django\mysite\shopapp\views.py", line 188, in get_queryset
    self.owner = User.objects.get(pk=self.kwargs['user_id'])
                 ^^^^^^^^^^^^^^^^^^^^^^^^^^^^^^^^^^^^^^^^^^^
  File "C:\Users\kurba\PycharmProjects\AnotherDjango\venv\Lib\site-packages\django\db\models\manager.py", line 87, in manager_method
    return getattr(self.get_queryset(), name)(*args, **kwargs)
           ^^^^^^^^^^^^^^^^^^^^^^^^^^^^^^^^^^^^^^^^^^^^^^^^^^^
  File "C:\Users\kurba\PycharmProjects\AnotherDjango\venv\Lib\site-packages\django\db\models\query.py", line 637, in get
    raise self.model.DoesNotExist(
django.contrib.auth.models.User.DoesNotExist: User matching query does not exist.
INFO level - 2024-01-25 01:43:58,659 django.utils.autoreload: "C:\Users\kurba\PycharmProjects\AnotherDjango\python_django\mysite\shopapp\views.py changed, reloading."
INFO level - 2024-01-25 01:43:59,782 django.utils.autoreload: "Watching for file changes with StatReloader"
INFO level - 2024-01-25 01:44:43,104 django.utils.autoreload: "C:\Users\kurba\PycharmProjects\AnotherDjango\python_django\mysite\shopapp\views.py changed, reloading."
INFO level - 2024-01-25 01:44:44,190 django.utils.autoreload: "Watching for file changes with StatReloader"
WARNING level - 2024-01-25 01:44:45,463 django.request: "Not Found: /ru/shop/users/20/orders/"
WARNING level - 2024-01-25 01:44:45,566 django.request: "Not Found: /ru/shop/users/20/orders/"
WARNING level - 2024-01-25 01:44:45,805 django.request: "Not Found: /ru/shop/users/20/orders/"
INFO level - 2024-01-25 01:45:43,419 django.utils.autoreload: "C:\Users\kurba\PycharmProjects\AnotherDjango\python_django\mysite\shopapp\views.py changed, reloading."
INFO level - 2024-01-25 01:45:44,565 django.utils.autoreload: "Watching for file changes with StatReloader"
WARNING level - 2024-01-25 01:45:45,777 django.request: "Not Found: /ru/shop/users/20/orders/"
WARNING level - 2024-01-25 01:45:46,766 django.request: "Not Found: /ru/shop/users/20/orders/"
WARNING level - 2024-01-25 01:46:08,952 django.request: "Not Found: /ru/shop/users/11/orders/"
INFO level - 2024-01-25 01:46:22,891 django.utils.autoreload: "C:\Users\kurba\PycharmProjects\AnotherDjango\python_django\mysite\shopapp\views.py changed, reloading."
INFO level - 2024-01-25 01:46:24,080 django.utils.autoreload: "Watching for file changes with StatReloader"
WARNING level - 2024-01-25 01:46:37,481 django.request: "Not Found: /ru/shop/users/11/orders/"
INFO level - 2024-01-25 01:46:45,703 django.utils.autoreload: "C:\Users\kurba\PycharmProjects\AnotherDjango\python_django\mysite\shopapp\views.py changed, reloading."
INFO level - 2024-01-25 01:46:47,001 django.utils.autoreload: "Watching for file changes with StatReloader"
WARNING level - 2024-01-25 01:46:47,890 django.request: "Not Found: /ru/shop/users/11/orders/"
WARNING level - 2024-01-25 01:46:56,710 django.request: "Not Found: /ru/shop/users/11/orders/"
INFO level - 2024-01-25 01:47:19,200 django.utils.autoreload: "C:\Users\kurba\PycharmProjects\AnotherDjango\python_django\mysite\shopapp\views.py changed, reloading."
INFO level - 2024-01-25 01:47:20,515 django.utils.autoreload: "Watching for file changes with StatReloader"
WARNING level - 2024-01-25 01:47:21,217 django.request: "Not Found: /ru/shop/users/11/orders/"
WARNING level - 2024-01-25 01:47:35,014 django.request: "Not Found: /ru/shop/users/11/orders/"
WARNING level - 2024-01-25 01:47:36,239 django.request: "Not Found: /ru/shop/users/11/orders/"
INFO level - 2024-01-25 01:53:32,495 django.utils.autoreload: "C:\Users\kurba\PycharmProjects\AnotherDjango\python_django\mysite\shopapp\views.py changed, reloading."
INFO level - 2024-01-25 01:53:33,627 django.utils.autoreload: "Watching for file changes with StatReloader"
WARNING level - 2024-01-25 01:54:45,257 django.request: "Not Found: /ru/shop/users/11/orders/"
WARNING level - 2024-01-25 01:54:46,522 django.request: "Not Found: /ru/shop/users/11/orders/"
WARNING level - 2024-01-25 01:57:37,668 django.request: "Not Found: /ru/shop/users/11/orders/"
INFO level - 2024-01-25 17:25:01,294 django.utils.autoreload: "C:\Users\kurba\PycharmProjects\AnotherDjango\python_django\mysite\shopapp\views.py changed, reloading."
INFO level - 2024-01-25 17:25:02,321 django.utils.autoreload: "Watching for file changes with StatReloader"
INFO level - 2024-01-25 17:27:30,931 django.utils.autoreload: "C:\Users\kurba\PycharmProjects\AnotherDjango\python_django\mysite\shopapp\views.py changed, reloading."
INFO level - 2024-01-25 17:27:31,684 django.utils.autoreload: "Watching for file changes with StatReloader"
INFO level - 2024-01-25 17:55:27,467 django.utils.autoreload: "C:\Users\kurba\PycharmProjects\AnotherDjango\python_django\mysite\shopapp\views.py changed, reloading."
INFO level - 2024-01-25 17:55:28,197 django.utils.autoreload: "Watching for file changes with StatReloader"
INFO level - 2024-01-25 17:56:41,241 django.utils.autoreload: "C:\Users\kurba\PycharmProjects\AnotherDjango\python_django\mysite\shopapp\urls.py changed, reloading."
INFO level - 2024-01-25 17:56:41,973 django.utils.autoreload: "Watching for file changes with StatReloader"
ERROR level - 2024-01-25 17:56:48,042 django.request: "Internal Server Error: /ru/shop/users/8/orders/export/"
Traceback (most recent call last):
  File "C:\Users\kurba\PycharmProjects\AnotherDjango\venv\Lib\site-packages\django\core\handlers\exception.py", line 55, in inner
    response = get_response(request)
               ^^^^^^^^^^^^^^^^^^^^^
  File "C:\Users\kurba\PycharmProjects\AnotherDjango\venv\Lib\site-packages\django\core\handlers\base.py", line 197, in _get_response
    response = wrapped_callback(request, *callback_args, **callback_kwargs)
               ^^^^^^^^^^^^^^^^^^^^^^^^^^^^^^^^^^^^^^^^^^^^^^^^^^^^^^^^^^^^
  File "C:\Users\kurba\PycharmProjects\AnotherDjango\venv\Lib\site-packages\sentry_sdk\integrations\django\views.py", line 84, in sentry_wrapped_callback
    return callback(request, *args, **kwargs)
           ^^^^^^^^^^^^^^^^^^^^^^^^^^^^^^^^^^
TypeError: user_orders_export() got an unexpected keyword argument 'user_id'
INFO level - 2024-01-25 17:59:49,581 django.utils.autoreload: "C:\Users\kurba\PycharmProjects\AnotherDjango\python_django\mysite\shopapp\views.py changed, reloading."
INFO level - 2024-01-25 17:59:50,377 django.utils.autoreload: "Watching for file changes with StatReloader"
INFO level - 2024-01-25 18:00:25,957 django.utils.autoreload: "C:\Users\kurba\PycharmProjects\AnotherDjango\python_django\mysite\shopapp\views.py changed, reloading."
INFO level - 2024-01-25 18:00:26,680 django.utils.autoreload: "Watching for file changes with StatReloader"
ERROR level - 2024-01-25 18:00:52,349 django.request: "Internal Server Error: /ru/shop/users/8/orders/export/"
Traceback (most recent call last):
  File "C:\Users\kurba\PycharmProjects\AnotherDjango\venv\Lib\site-packages\django\core\handlers\exception.py", line 55, in inner
    response = get_response(request)
               ^^^^^^^^^^^^^^^^^^^^^
  File "C:\Users\kurba\PycharmProjects\AnotherDjango\venv\Lib\site-packages\django\core\handlers\base.py", line 197, in _get_response
    response = wrapped_callback(request, *callback_args, **callback_kwargs)
               ^^^^^^^^^^^^^^^^^^^^^^^^^^^^^^^^^^^^^^^^^^^^^^^^^^^^^^^^^^^^
  File "C:\Users\kurba\PycharmProjects\AnotherDjango\venv\Lib\site-packages\sentry_sdk\integrations\django\views.py", line 84, in sentry_wrapped_callback
    return callback(request, *args, **kwargs)
           ^^^^^^^^^^^^^^^^^^^^^^^^^^^^^^^^^^
  File "C:\Users\kurba\PycharmProjects\AnotherDjango\python_django\mysite\shopapp\views.py", line 201, in user_orders_export
    return JsonResponse(owner)
           ^^^^^^^^^^^^^^^^^^^
  File "C:\Users\kurba\PycharmProjects\AnotherDjango\venv\Lib\site-packages\django\http\response.py", line 724, in __init__
    raise TypeError(
TypeError: In order to allow non-dict objects to be serialized set the safe parameter to False.
INFO level - 2024-01-25 18:01:21,250 django.utils.autoreload: "C:\Users\kurba\PycharmProjects\AnotherDjango\python_django\mysite\shopapp\views.py changed, reloading."
INFO level - 2024-01-25 18:01:22,333 django.utils.autoreload: "Watching for file changes with StatReloader"
INFO level - 2024-01-25 18:02:10,512 django.utils.autoreload: "C:\Users\kurba\PycharmProjects\AnotherDjango\python_django\mysite\shopapp\views.py changed, reloading."
INFO level - 2024-01-25 18:02:11,314 django.utils.autoreload: "Watching for file changes with StatReloader"
INFO level - 2024-01-25 18:02:19,998 django.utils.autoreload: "C:\Users\kurba\PycharmProjects\AnotherDjango\python_django\mysite\shopapp\views.py changed, reloading."
INFO level - 2024-01-25 18:02:20,739 django.utils.autoreload: "Watching for file changes with StatReloader"
INFO level - 2024-01-25 21:14:02,929 django.utils.autoreload: "C:\Users\kurba\PycharmProjects\AnotherDjango\python_django\mysite\shopapp\views.py changed, reloading."
INFO level - 2024-01-25 21:14:03,797 django.utils.autoreload: "Watching for file changes with StatReloader"
INFO level - 2024-01-25 21:14:26,766 django.utils.autoreload: "C:\Users\kurba\PycharmProjects\AnotherDjango\python_django\mysite\shopapp\views.py changed, reloading."
INFO level - 2024-01-25 21:14:27,335 django.utils.autoreload: "Watching for file changes with StatReloader"
INFO level - 2024-01-25 21:15:44,679 django.utils.autoreload: "C:\Users\kurba\PycharmProjects\AnotherDjango\python_django\mysite\shopapp\views.py changed, reloading."
INFO level - 2024-01-25 21:15:45,260 django.utils.autoreload: "Watching for file changes with StatReloader"
INFO level - 2024-01-25 21:16:44,808 django.utils.autoreload: "C:\Users\kurba\PycharmProjects\AnotherDjango\python_django\mysite\shopapp\views.py changed, reloading."
INFO level - 2024-01-25 21:16:45,421 django.utils.autoreload: "Watching for file changes with StatReloader"
INFO level - 2024-01-25 21:18:18,534 django.utils.autoreload: "C:\Users\kurba\PycharmProjects\AnotherDjango\python_django\mysite\shopapp\views.py changed, reloading."
INFO level - 2024-01-25 21:18:19,131 django.utils.autoreload: "Watching for file changes with StatReloader"
INFO level - 2024-01-25 21:20:14,628 django.utils.autoreload: "C:\Users\kurba\PycharmProjects\AnotherDjango\python_django\mysite\shopapp\views.py changed, reloading."
INFO level - 2024-01-25 21:20:15,257 django.utils.autoreload: "Watching for file changes with StatReloader"
ERROR level - 2024-01-25 21:20:20,467 django.request: "Internal Server Error: /ru/shop/users/8/orders/export/"
Traceback (most recent call last):
  File "C:\Users\kurba\PycharmProjects\AnotherDjango\venv\Lib\site-packages\rest_framework\fields.py", line 446, in get_attribute
    return get_attribute(instance, self.source_attrs)
           ^^^^^^^^^^^^^^^^^^^^^^^^^^^^^^^^^^^^^^^^^^
  File "C:\Users\kurba\PycharmProjects\AnotherDjango\venv\Lib\site-packages\rest_framework\fields.py", line 96, in get_attribute
    instance = getattr(instance, attr)
               ^^^^^^^^^^^^^^^^^^^^^^^
AttributeError: 'QuerySet' object has no attribute 'user'

During handling of the above exception, another exception occurred:

Traceback (most recent call last):
  File "C:\Users\kurba\PycharmProjects\AnotherDjango\venv\Lib\site-packages\django\core\handlers\exception.py", line 55, in inner
    response = get_response(request)
               ^^^^^^^^^^^^^^^^^^^^^
  File "C:\Users\kurba\PycharmProjects\AnotherDjango\venv\Lib\site-packages\django\core\handlers\base.py", line 197, in _get_response
    response = wrapped_callback(request, *callback_args, **callback_kwargs)
               ^^^^^^^^^^^^^^^^^^^^^^^^^^^^^^^^^^^^^^^^^^^^^^^^^^^^^^^^^^^^
  File "C:\Users\kurba\PycharmProjects\AnotherDjango\venv\Lib\site-packages\sentry_sdk\integrations\django\views.py", line 84, in sentry_wrapped_callback
    return callback(request, *args, **kwargs)
           ^^^^^^^^^^^^^^^^^^^^^^^^^^^^^^^^^^
  File "C:\Users\kurba\PycharmProjects\AnotherDjango\python_django\mysite\shopapp\views.py", line 202, in user_orders_export
    return JsonResponse(serializer.data)
                        ^^^^^^^^^^^^^^^
  File "C:\Users\kurba\PycharmProjects\AnotherDjango\venv\Lib\site-packages\rest_framework\serializers.py", line 555, in data
    ret = super().data
          ^^^^^^^^^^^^
  File "C:\Users\kurba\PycharmProjects\AnotherDjango\venv\Lib\site-packages\rest_framework\serializers.py", line 253, in data
    self._data = self.to_representation(self.instance)
                 ^^^^^^^^^^^^^^^^^^^^^^^^^^^^^^^^^^^^^
  File "C:\Users\kurba\PycharmProjects\AnotherDjango\venv\Lib\site-packages\rest_framework\serializers.py", line 509, in to_representation
    attribute = field.get_attribute(instance)
                ^^^^^^^^^^^^^^^^^^^^^^^^^^^^^
  File "C:\Users\kurba\PycharmProjects\AnotherDjango\venv\Lib\site-packages\rest_framework\relations.py", line 190, in get_attribute
    return super().get_attribute(instance)
           ^^^^^^^^^^^^^^^^^^^^^^^^^^^^^^^
  File "C:\Users\kurba\PycharmProjects\AnotherDjango\venv\Lib\site-packages\rest_framework\fields.py", line 479, in get_attribute
    raise type(exc)(msg)
AttributeError: Got AttributeError when attempting to get a value for field `user` on serializer `OrderSerializer`.
The serializer field might be named incorrectly and not match any attribute or key on the `QuerySet` instance.
Original exception text was: 'QuerySet' object has no attribute 'user'.
INFO level - 2024-01-25 21:22:06,562 django.utils.autoreload: "C:\Users\kurba\PycharmProjects\AnotherDjango\python_django\mysite\shopapp\views.py changed, reloading."
INFO level - 2024-01-25 21:22:07,218 django.utils.autoreload: "Watching for file changes with StatReloader"
ERROR level - 2024-01-25 21:22:07,678 django.request: "Internal Server Error: /ru/shop/users/8/orders/export/"
Traceback (most recent call last):
  File "C:\Users\kurba\PycharmProjects\AnotherDjango\venv\Lib\site-packages\rest_framework\fields.py", line 446, in get_attribute
    return get_attribute(instance, self.source_attrs)
           ^^^^^^^^^^^^^^^^^^^^^^^^^^^^^^^^^^^^^^^^^^
  File "C:\Users\kurba\PycharmProjects\AnotherDjango\venv\Lib\site-packages\rest_framework\fields.py", line 96, in get_attribute
    instance = getattr(instance, attr)
               ^^^^^^^^^^^^^^^^^^^^^^^
AttributeError: 'QuerySet' object has no attribute 'user'

During handling of the above exception, another exception occurred:

Traceback (most recent call last):
  File "C:\Users\kurba\PycharmProjects\AnotherDjango\venv\Lib\site-packages\django\core\handlers\exception.py", line 55, in inner
    response = get_response(request)
               ^^^^^^^^^^^^^^^^^^^^^
  File "C:\Users\kurba\PycharmProjects\AnotherDjango\venv\Lib\site-packages\django\core\handlers\base.py", line 197, in _get_response
    response = wrapped_callback(request, *callback_args, **callback_kwargs)
               ^^^^^^^^^^^^^^^^^^^^^^^^^^^^^^^^^^^^^^^^^^^^^^^^^^^^^^^^^^^^
  File "C:\Users\kurba\PycharmProjects\AnotherDjango\venv\Lib\site-packages\sentry_sdk\integrations\django\views.py", line 84, in sentry_wrapped_callback
    return callback(request, *args, **kwargs)
           ^^^^^^^^^^^^^^^^^^^^^^^^^^^^^^^^^^
  File "C:\Users\kurba\PycharmProjects\AnotherDjango\python_django\mysite\shopapp\views.py", line 202, in user_orders_export
    return JsonResponse(serializer.data)
                        ^^^^^^^^^^^^^^^
  File "C:\Users\kurba\PycharmProjects\AnotherDjango\venv\Lib\site-packages\rest_framework\serializers.py", line 555, in data
    ret = super().data
          ^^^^^^^^^^^^
  File "C:\Users\kurba\PycharmProjects\AnotherDjango\venv\Lib\site-packages\rest_framework\serializers.py", line 253, in data
    self._data = self.to_representation(self.instance)
                 ^^^^^^^^^^^^^^^^^^^^^^^^^^^^^^^^^^^^^
  File "C:\Users\kurba\PycharmProjects\AnotherDjango\venv\Lib\site-packages\rest_framework\serializers.py", line 509, in to_representation
    attribute = field.get_attribute(instance)
                ^^^^^^^^^^^^^^^^^^^^^^^^^^^^^
  File "C:\Users\kurba\PycharmProjects\AnotherDjango\venv\Lib\site-packages\rest_framework\relations.py", line 190, in get_attribute
    return super().get_attribute(instance)
           ^^^^^^^^^^^^^^^^^^^^^^^^^^^^^^^
  File "C:\Users\kurba\PycharmProjects\AnotherDjango\venv\Lib\site-packages\rest_framework\fields.py", line 479, in get_attribute
    raise type(exc)(msg)
AttributeError: Got AttributeError when attempting to get a value for field `user` on serializer `OrderSerializer`.
The serializer field might be named incorrectly and not match any attribute or key on the `QuerySet` instance.
Original exception text was: 'QuerySet' object has no attribute 'user'.
ERROR level - 2024-01-25 21:22:09,754 django.request: "Internal Server Error: /ru/shop/users/8/orders/export/"
Traceback (most recent call last):
  File "C:\Users\kurba\PycharmProjects\AnotherDjango\venv\Lib\site-packages\rest_framework\fields.py", line 446, in get_attribute
    return get_attribute(instance, self.source_attrs)
           ^^^^^^^^^^^^^^^^^^^^^^^^^^^^^^^^^^^^^^^^^^
  File "C:\Users\kurba\PycharmProjects\AnotherDjango\venv\Lib\site-packages\rest_framework\fields.py", line 96, in get_attribute
    instance = getattr(instance, attr)
               ^^^^^^^^^^^^^^^^^^^^^^^
AttributeError: 'QuerySet' object has no attribute 'user'

During handling of the above exception, another exception occurred:

Traceback (most recent call last):
  File "C:\Users\kurba\PycharmProjects\AnotherDjango\venv\Lib\site-packages\django\core\handlers\exception.py", line 55, in inner
    response = get_response(request)
               ^^^^^^^^^^^^^^^^^^^^^
  File "C:\Users\kurba\PycharmProjects\AnotherDjango\venv\Lib\site-packages\django\core\handlers\base.py", line 197, in _get_response
    response = wrapped_callback(request, *callback_args, **callback_kwargs)
               ^^^^^^^^^^^^^^^^^^^^^^^^^^^^^^^^^^^^^^^^^^^^^^^^^^^^^^^^^^^^
  File "C:\Users\kurba\PycharmProjects\AnotherDjango\venv\Lib\site-packages\sentry_sdk\integrations\django\views.py", line 84, in sentry_wrapped_callback
    return callback(request, *args, **kwargs)
           ^^^^^^^^^^^^^^^^^^^^^^^^^^^^^^^^^^
  File "C:\Users\kurba\PycharmProjects\AnotherDjango\python_django\mysite\shopapp\views.py", line 202, in user_orders_export
    return JsonResponse(serializer.data)
                        ^^^^^^^^^^^^^^^
  File "C:\Users\kurba\PycharmProjects\AnotherDjango\venv\Lib\site-packages\rest_framework\serializers.py", line 555, in data
    ret = super().data
          ^^^^^^^^^^^^
  File "C:\Users\kurba\PycharmProjects\AnotherDjango\venv\Lib\site-packages\rest_framework\serializers.py", line 253, in data
    self._data = self.to_representation(self.instance)
                 ^^^^^^^^^^^^^^^^^^^^^^^^^^^^^^^^^^^^^
  File "C:\Users\kurba\PycharmProjects\AnotherDjango\venv\Lib\site-packages\rest_framework\serializers.py", line 509, in to_representation
    attribute = field.get_attribute(instance)
                ^^^^^^^^^^^^^^^^^^^^^^^^^^^^^
  File "C:\Users\kurba\PycharmProjects\AnotherDjango\venv\Lib\site-packages\rest_framework\relations.py", line 190, in get_attribute
    return super().get_attribute(instance)
           ^^^^^^^^^^^^^^^^^^^^^^^^^^^^^^^
  File "C:\Users\kurba\PycharmProjects\AnotherDjango\venv\Lib\site-packages\rest_framework\fields.py", line 479, in get_attribute
    raise type(exc)(msg)
AttributeError: Got AttributeError when attempting to get a value for field `user` on serializer `OrderSerializer`.
The serializer field might be named incorrectly and not match any attribute or key on the `QuerySet` instance.
Original exception text was: 'QuerySet' object has no attribute 'user'.
INFO level - 2024-01-25 21:24:16,808 django.utils.autoreload: "C:\Users\kurba\PycharmProjects\AnotherDjango\python_django\mysite\shopapp\views.py changed, reloading."
INFO level - 2024-01-25 21:24:17,470 django.utils.autoreload: "Watching for file changes with StatReloader"
ERROR level - 2024-01-25 21:24:18,075 django.request: "Internal Server Error: /ru/shop/users/8/orders/export/"
Traceback (most recent call last):
  File "C:\Users\kurba\PycharmProjects\AnotherDjango\venv\Lib\site-packages\rest_framework\fields.py", line 446, in get_attribute
    return get_attribute(instance, self.source_attrs)
           ^^^^^^^^^^^^^^^^^^^^^^^^^^^^^^^^^^^^^^^^^^
  File "C:\Users\kurba\PycharmProjects\AnotherDjango\venv\Lib\site-packages\rest_framework\fields.py", line 96, in get_attribute
    instance = getattr(instance, attr)
               ^^^^^^^^^^^^^^^^^^^^^^^
AttributeError: 'QuerySet' object has no attribute 'user'

During handling of the above exception, another exception occurred:

Traceback (most recent call last):
  File "C:\Users\kurba\PycharmProjects\AnotherDjango\venv\Lib\site-packages\django\core\handlers\exception.py", line 55, in inner
    response = get_response(request)
               ^^^^^^^^^^^^^^^^^^^^^
  File "C:\Users\kurba\PycharmProjects\AnotherDjango\venv\Lib\site-packages\django\core\handlers\base.py", line 197, in _get_response
    response = wrapped_callback(request, *callback_args, **callback_kwargs)
               ^^^^^^^^^^^^^^^^^^^^^^^^^^^^^^^^^^^^^^^^^^^^^^^^^^^^^^^^^^^^
  File "C:\Users\kurba\PycharmProjects\AnotherDjango\venv\Lib\site-packages\sentry_sdk\integrations\django\views.py", line 84, in sentry_wrapped_callback
    return callback(request, *args, **kwargs)
           ^^^^^^^^^^^^^^^^^^^^^^^^^^^^^^^^^^
  File "C:\Users\kurba\PycharmProjects\AnotherDjango\python_django\mysite\shopapp\views.py", line 202, in user_orders_export
    return JsonResponse(serializer.data)
                        ^^^^^^^^^^^^^^^
  File "C:\Users\kurba\PycharmProjects\AnotherDjango\venv\Lib\site-packages\rest_framework\serializers.py", line 555, in data
    ret = super().data
          ^^^^^^^^^^^^
  File "C:\Users\kurba\PycharmProjects\AnotherDjango\venv\Lib\site-packages\rest_framework\serializers.py", line 253, in data
    self._data = self.to_representation(self.instance)
                 ^^^^^^^^^^^^^^^^^^^^^^^^^^^^^^^^^^^^^
  File "C:\Users\kurba\PycharmProjects\AnotherDjango\venv\Lib\site-packages\rest_framework\serializers.py", line 509, in to_representation
    attribute = field.get_attribute(instance)
                ^^^^^^^^^^^^^^^^^^^^^^^^^^^^^
  File "C:\Users\kurba\PycharmProjects\AnotherDjango\venv\Lib\site-packages\rest_framework\relations.py", line 190, in get_attribute
    return super().get_attribute(instance)
           ^^^^^^^^^^^^^^^^^^^^^^^^^^^^^^^
  File "C:\Users\kurba\PycharmProjects\AnotherDjango\venv\Lib\site-packages\rest_framework\fields.py", line 479, in get_attribute
    raise type(exc)(msg)
AttributeError: Got AttributeError when attempting to get a value for field `user` on serializer `OrderSerializer`.
The serializer field might be named incorrectly and not match any attribute or key on the `QuerySet` instance.
Original exception text was: 'QuerySet' object has no attribute 'user'.
INFO level - 2024-01-25 21:24:38,579 django.utils.autoreload: "C:\Users\kurba\PycharmProjects\AnotherDjango\python_django\mysite\shopapp\views.py changed, reloading."
INFO level - 2024-01-25 21:24:39,313 django.utils.autoreload: "Watching for file changes with StatReloader"
INFO level - 2024-01-25 21:24:55,217 django.utils.autoreload: "C:\Users\kurba\PycharmProjects\AnotherDjango\python_django\mysite\shopapp\views.py changed, reloading."
INFO level - 2024-01-25 21:24:55,956 django.utils.autoreload: "Watching for file changes with StatReloader"
INFO level - 2024-01-25 21:25:55,455 django.utils.autoreload: "C:\Users\kurba\PycharmProjects\AnotherDjango\python_django\mysite\shopapp\views.py changed, reloading."
INFO level - 2024-01-25 21:25:56,213 django.utils.autoreload: "Watching for file changes with StatReloader"
INFO level - 2024-01-25 21:26:38,028 django.utils.autoreload: "C:\Users\kurba\PycharmProjects\AnotherDjango\python_django\mysite\shopapp\views.py changed, reloading."
INFO level - 2024-01-25 21:26:38,729 django.utils.autoreload: "Watching for file changes with StatReloader"
INFO level - 2024-01-25 21:28:11,201 django.utils.autoreload: "C:\Users\kurba\PycharmProjects\AnotherDjango\python_django\mysite\shopapp\views.py changed, reloading."
INFO level - 2024-01-25 21:28:11,916 django.utils.autoreload: "Watching for file changes with StatReloader"
ERROR level - 2024-01-25 21:28:12,444 django.request: "Internal Server Error: /ru/shop/users/8/orders/export/"
Traceback (most recent call last):
  File "C:\Users\kurba\PycharmProjects\AnotherDjango\venv\Lib\site-packages\rest_framework\fields.py", line 446, in get_attribute
    return get_attribute(instance, self.source_attrs)
           ^^^^^^^^^^^^^^^^^^^^^^^^^^^^^^^^^^^^^^^^^^
  File "C:\Users\kurba\PycharmProjects\AnotherDjango\venv\Lib\site-packages\rest_framework\fields.py", line 96, in get_attribute
    instance = getattr(instance, attr)
               ^^^^^^^^^^^^^^^^^^^^^^^
AttributeError: 'QuerySet' object has no attribute 'user'

During handling of the above exception, another exception occurred:

Traceback (most recent call last):
  File "C:\Users\kurba\PycharmProjects\AnotherDjango\venv\Lib\site-packages\django\core\handlers\exception.py", line 55, in inner
    response = get_response(request)
               ^^^^^^^^^^^^^^^^^^^^^
  File "C:\Users\kurba\PycharmProjects\AnotherDjango\venv\Lib\site-packages\django\core\handlers\base.py", line 197, in _get_response
    response = wrapped_callback(request, *callback_args, **callback_kwargs)
               ^^^^^^^^^^^^^^^^^^^^^^^^^^^^^^^^^^^^^^^^^^^^^^^^^^^^^^^^^^^^
  File "C:\Users\kurba\PycharmProjects\AnotherDjango\venv\Lib\site-packages\sentry_sdk\integrations\django\views.py", line 84, in sentry_wrapped_callback
    return callback(request, *args, **kwargs)
           ^^^^^^^^^^^^^^^^^^^^^^^^^^^^^^^^^^
  File "C:\Users\kurba\PycharmProjects\AnotherDjango\python_django\mysite\shopapp\views.py", line 204, in user_orders_export
    return JsonResponse(serializer.data)
                        ^^^^^^^^^^^^^^^
  File "C:\Users\kurba\PycharmProjects\AnotherDjango\venv\Lib\site-packages\rest_framework\serializers.py", line 555, in data
    ret = super().data
          ^^^^^^^^^^^^
  File "C:\Users\kurba\PycharmProjects\AnotherDjango\venv\Lib\site-packages\rest_framework\serializers.py", line 253, in data
    self._data = self.to_representation(self.instance)
                 ^^^^^^^^^^^^^^^^^^^^^^^^^^^^^^^^^^^^^
  File "C:\Users\kurba\PycharmProjects\AnotherDjango\venv\Lib\site-packages\rest_framework\serializers.py", line 509, in to_representation
    attribute = field.get_attribute(instance)
                ^^^^^^^^^^^^^^^^^^^^^^^^^^^^^
  File "C:\Users\kurba\PycharmProjects\AnotherDjango\venv\Lib\site-packages\rest_framework\relations.py", line 190, in get_attribute
    return super().get_attribute(instance)
           ^^^^^^^^^^^^^^^^^^^^^^^^^^^^^^^
  File "C:\Users\kurba\PycharmProjects\AnotherDjango\venv\Lib\site-packages\rest_framework\fields.py", line 479, in get_attribute
    raise type(exc)(msg)
AttributeError: Got AttributeError when attempting to get a value for field `user` on serializer `OrderSerializer`.
The serializer field might be named incorrectly and not match any attribute or key on the `QuerySet` instance.
Original exception text was: 'QuerySet' object has no attribute 'user'.
INFO level - 2024-01-25 21:29:21,087 django.utils.autoreload: "C:\Users\kurba\PycharmProjects\AnotherDjango\python_django\mysite\shopapp\serializers.py changed, reloading."
INFO level - 2024-01-25 21:29:21,780 django.utils.autoreload: "Watching for file changes with StatReloader"
ERROR level - 2024-01-25 21:29:22,357 django.request: "Internal Server Error: /ru/shop/users/8/orders/export/"
Traceback (most recent call last):
  File "C:\Users\kurba\PycharmProjects\AnotherDjango\venv\Lib\site-packages\rest_framework\relations.py", line 539, in get_attribute
    relationship = get_attribute(instance, self.source_attrs)
                   ^^^^^^^^^^^^^^^^^^^^^^^^^^^^^^^^^^^^^^^^^^
  File "C:\Users\kurba\PycharmProjects\AnotherDjango\venv\Lib\site-packages\rest_framework\fields.py", line 96, in get_attribute
    instance = getattr(instance, attr)
               ^^^^^^^^^^^^^^^^^^^^^^^
AttributeError: 'QuerySet' object has no attribute 'products'

During handling of the above exception, another exception occurred:

Traceback (most recent call last):
  File "C:\Users\kurba\PycharmProjects\AnotherDjango\venv\Lib\site-packages\django\core\handlers\exception.py", line 55, in inner
    response = get_response(request)
               ^^^^^^^^^^^^^^^^^^^^^
  File "C:\Users\kurba\PycharmProjects\AnotherDjango\venv\Lib\site-packages\django\core\handlers\base.py", line 197, in _get_response
    response = wrapped_callback(request, *callback_args, **callback_kwargs)
               ^^^^^^^^^^^^^^^^^^^^^^^^^^^^^^^^^^^^^^^^^^^^^^^^^^^^^^^^^^^^
  File "C:\Users\kurba\PycharmProjects\AnotherDjango\venv\Lib\site-packages\sentry_sdk\integrations\django\views.py", line 84, in sentry_wrapped_callback
    return callback(request, *args, **kwargs)
           ^^^^^^^^^^^^^^^^^^^^^^^^^^^^^^^^^^
  File "C:\Users\kurba\PycharmProjects\AnotherDjango\python_django\mysite\shopapp\views.py", line 204, in user_orders_export
    return JsonResponse(serializer.data)
                        ^^^^^^^^^^^^^^^
  File "C:\Users\kurba\PycharmProjects\AnotherDjango\venv\Lib\site-packages\rest_framework\serializers.py", line 555, in data
    ret = super().data
          ^^^^^^^^^^^^
  File "C:\Users\kurba\PycharmProjects\AnotherDjango\venv\Lib\site-packages\rest_framework\serializers.py", line 253, in data
    self._data = self.to_representation(self.instance)
                 ^^^^^^^^^^^^^^^^^^^^^^^^^^^^^^^^^^^^^
  File "C:\Users\kurba\PycharmProjects\AnotherDjango\venv\Lib\site-packages\rest_framework\serializers.py", line 509, in to_representation
    attribute = field.get_attribute(instance)
                ^^^^^^^^^^^^^^^^^^^^^^^^^^^^^
  File "C:\Users\kurba\PycharmProjects\AnotherDjango\venv\Lib\site-packages\rest_framework\relations.py", line 560, in get_attribute
    raise type(exc)(msg)
AttributeError: Got AttributeError when attempting to get a value for field `products` on serializer `OrderSerializer`.
The serializer field might be named incorrectly and not match any attribute or key on the `QuerySet` instance.
Original exception text was: 'QuerySet' object has no attribute 'products'.
INFO level - 2024-01-25 21:30:20,892 django.utils.autoreload: "C:\Users\kurba\PycharmProjects\AnotherDjango\python_django\mysite\shopapp\serializers.py changed, reloading."
INFO level - 2024-01-25 21:30:21,674 django.utils.autoreload: "Watching for file changes with StatReloader"
INFO level - 2024-01-25 21:31:06,547 django.utils.autoreload: "C:\Users\kurba\PycharmProjects\AnotherDjango\python_django\mysite\shopapp\serializers.py changed, reloading."
INFO level - 2024-01-25 21:31:07,339 django.utils.autoreload: "Watching for file changes with StatReloader"
INFO level - 2024-01-25 21:32:25,338 django.utils.autoreload: "C:\Users\kurba\PycharmProjects\AnotherDjango\python_django\mysite\shopapp\views.py changed, reloading."
INFO level - 2024-01-25 21:32:25,966 django.utils.autoreload: "Watching for file changes with StatReloader"
INFO level - 2024-01-25 21:34:22,353 django.utils.autoreload: "C:\Users\kurba\PycharmProjects\AnotherDjango\python_django\mysite\shopapp\serializers.py changed, reloading."
INFO level - 2024-01-25 21:34:23,018 django.utils.autoreload: "Watching for file changes with StatReloader"
INFO level - 2024-01-25 21:34:59,183 django.utils.autoreload: "C:\Users\kurba\PycharmProjects\AnotherDjango\python_django\mysite\shopapp\serializers.py changed, reloading."
INFO level - 2024-01-25 21:34:59,895 django.utils.autoreload: "Watching for file changes with StatReloader"
INFO level - 2024-01-25 21:35:02,283 django.utils.autoreload: "C:\Users\kurba\PycharmProjects\AnotherDjango\python_django\mysite\shopapp\serializers.py changed, reloading."
INFO level - 2024-01-25 21:35:02,875 django.utils.autoreload: "Watching for file changes with StatReloader"
INFO level - 2024-01-25 21:35:29,930 django.utils.autoreload: "C:\Users\kurba\PycharmProjects\AnotherDjango\python_django\mysite\shopapp\serializers.py changed, reloading."
INFO level - 2024-01-25 21:35:30,530 django.utils.autoreload: "Watching for file changes with StatReloader"
INFO level - 2024-01-25 21:35:58,662 django.utils.autoreload: "C:\Users\kurba\PycharmProjects\AnotherDjango\python_django\mysite\shopapp\serializers.py changed, reloading."
INFO level - 2024-01-25 21:35:59,297 django.utils.autoreload: "Watching for file changes with StatReloader"
INFO level - 2024-01-25 21:36:35,729 django.utils.autoreload: "C:\Users\kurba\PycharmProjects\AnotherDjango\python_django\mysite\shopapp\serializers.py changed, reloading."
INFO level - 2024-01-25 21:36:36,328 django.utils.autoreload: "Watching for file changes with StatReloader"
INFO level - 2024-01-25 21:37:01,541 django.utils.autoreload: "C:\Users\kurba\PycharmProjects\AnotherDjango\python_django\mysite\shopapp\serializers.py changed, reloading."
INFO level - 2024-01-25 21:37:02,198 django.utils.autoreload: "Watching for file changes with StatReloader"
INFO level - 2024-01-25 21:37:29,491 django.utils.autoreload: "C:\Users\kurba\PycharmProjects\AnotherDjango\python_django\mysite\shopapp\serializers.py changed, reloading."
INFO level - 2024-01-25 21:37:30,083 django.utils.autoreload: "Watching for file changes with StatReloader"
INFO level - 2024-01-25 21:38:24,415 django.utils.autoreload: "C:\Users\kurba\PycharmProjects\AnotherDjango\python_django\mysite\shopapp\serializers.py changed, reloading."
INFO level - 2024-01-25 21:38:25,098 django.utils.autoreload: "Watching for file changes with StatReloader"
INFO level - 2024-01-25 21:43:21,269 django.utils.autoreload: "C:\Users\kurba\PycharmProjects\AnotherDjango\python_django\mysite\shopapp\views.py changed, reloading."
INFO level - 2024-01-25 21:43:21,834 django.utils.autoreload: "Watching for file changes with StatReloader"
INFO level - 2024-01-25 21:44:47,746 django.utils.autoreload: "C:\Users\kurba\PycharmProjects\AnotherDjango\python_django\mysite\shopapp\views.py changed, reloading."
INFO level - 2024-01-25 21:44:48,326 django.utils.autoreload: "Watching for file changes with StatReloader"
INFO level - 2024-01-25 21:45:16,621 django.utils.autoreload: "C:\Users\kurba\PycharmProjects\AnotherDjango\python_django\mysite\shopapp\views.py changed, reloading."
INFO level - 2024-01-25 21:45:17,191 django.utils.autoreload: "Watching for file changes with StatReloader"
INFO level - 2024-01-25 21:49:16,422 django.utils.autoreload: "C:\Users\kurba\PycharmProjects\AnotherDjango\python_django\mysite\shopapp\views.py changed, reloading."
INFO level - 2024-01-25 21:49:17,040 django.utils.autoreload: "Watching for file changes with StatReloader"
ERROR level - 2024-01-25 21:49:22,470 django.request: "Internal Server Error: /ru/shop/users/1/orders/export/"
Traceback (most recent call last):
  File "C:\Users\kurba\PycharmProjects\AnotherDjango\venv\Lib\site-packages\django\core\handlers\exception.py", line 55, in inner
    response = get_response(request)
               ^^^^^^^^^^^^^^^^^^^^^
  File "C:\Users\kurba\PycharmProjects\AnotherDjango\venv\Lib\site-packages\django\core\handlers\base.py", line 197, in _get_response
    response = wrapped_callback(request, *callback_args, **callback_kwargs)
               ^^^^^^^^^^^^^^^^^^^^^^^^^^^^^^^^^^^^^^^^^^^^^^^^^^^^^^^^^^^^
  File "C:\Users\kurba\PycharmProjects\AnotherDjango\venv\Lib\site-packages\sentry_sdk\integrations\django\views.py", line 84, in sentry_wrapped_callback
    return callback(request, *args, **kwargs)
           ^^^^^^^^^^^^^^^^^^^^^^^^^^^^^^^^^^
  File "C:\Users\kurba\PycharmProjects\AnotherDjango\python_django\mysite\shopapp\views.py", line 205, in user_orders_export
    return JsonResponse(serialized)
           ^^^^^^^^^^^^^^^^^^^^^^^^
  File "C:\Users\kurba\PycharmProjects\AnotherDjango\venv\Lib\site-packages\django\http\response.py", line 724, in __init__
    raise TypeError(
TypeError: In order to allow non-dict objects to be serialized set the safe parameter to False.
INFO level - 2024-01-25 21:52:14,839 django.utils.autoreload: "C:\Users\kurba\PycharmProjects\AnotherDjango\python_django\mysite\shopapp\views.py changed, reloading."
INFO level - 2024-01-25 21:52:15,538 django.utils.autoreload: "Watching for file changes with StatReloader"
INFO level - 2024-01-25 21:52:17,838 django.utils.autoreload: "C:\Users\kurba\PycharmProjects\AnotherDjango\python_django\mysite\shopapp\views.py changed, reloading."
INFO level - 2024-01-25 21:52:18,422 django.utils.autoreload: "Watching for file changes with StatReloader"
INFO level - 2024-01-25 21:53:31,295 django.utils.autoreload: "C:\Users\kurba\PycharmProjects\AnotherDjango\python_django\mysite\shopapp\views.py changed, reloading."
INFO level - 2024-01-25 21:53:32,055 django.utils.autoreload: "Watching for file changes with StatReloader"
INFO level - 2024-01-25 21:53:45,913 django.utils.autoreload: "C:\Users\kurba\PycharmProjects\AnotherDjango\python_django\mysite\shopapp\views.py changed, reloading."
INFO level - 2024-01-25 21:53:46,538 django.utils.autoreload: "Watching for file changes with StatReloader"
INFO level - 2024-01-25 21:54:09,506 django.utils.autoreload: "C:\Users\kurba\PycharmProjects\AnotherDjango\python_django\mysite\shopapp\views.py changed, reloading."
INFO level - 2024-01-25 21:54:10,137 django.utils.autoreload: "Watching for file changes with StatReloader"
INFO level - 2024-01-25 21:55:07,560 django.utils.autoreload: "C:\Users\kurba\PycharmProjects\AnotherDjango\python_django\mysite\shopapp\views.py changed, reloading."
INFO level - 2024-01-25 21:55:08,343 django.utils.autoreload: "Watching for file changes with StatReloader"
INFO level - 2024-01-25 21:55:56,696 django.utils.autoreload: "C:\Users\kurba\PycharmProjects\AnotherDjango\python_django\mysite\shopapp\views.py changed, reloading."
INFO level - 2024-01-25 21:55:57,442 django.utils.autoreload: "Watching for file changes with StatReloader"
INFO level - 2024-01-25 21:57:03,898 django.utils.autoreload: "C:\Users\kurba\PycharmProjects\AnotherDjango\python_django\mysite\shopapp\views.py changed, reloading."
INFO level - 2024-01-25 21:57:04,530 django.utils.autoreload: "Watching for file changes with StatReloader"
WARNING level - 2024-01-25 22:05:39,570 django.request: "Not Found: /ru/shop/users/11/orders/export/"
INFO level - 2024-01-25 22:08:12,612 django.utils.autoreload: "C:\Users\kurba\PycharmProjects\AnotherDjango\python_django\mysite\shopapp\views.py changed, reloading."
INFO level - 2024-01-25 22:08:13,218 django.utils.autoreload: "Watching for file changes with StatReloader"
INFO level - 2024-01-25 22:12:39,707 django.utils.autoreload: "C:\Users\kurba\PycharmProjects\AnotherDjango\python_django\mysite\shopapp\views.py changed, reloading."
INFO level - 2024-01-25 22:12:40,389 django.utils.autoreload: "Watching for file changes with StatReloader"
WARNING level - 2024-01-25 22:12:54,752 django.request: "Not Found: /ru/shop/users/11/orders/export/"
WARNING level - 2024-01-25 22:14:08,666 django.request: "Not Found: /ru/shop/users/11/orders/export/"
INFO level - 2024-01-25 22:15:45,228 django.utils.autoreload: "C:\Users\kurba\PycharmProjects\AnotherDjango\python_django\mysite\shopapp\views.py changed, reloading."
INFO level - 2024-01-25 22:15:45,988 django.utils.autoreload: "Watching for file changes with StatReloader"
INFO level - 2024-01-25 22:18:57,580 django.utils.autoreload: "C:\Users\kurba\PycharmProjects\AnotherDjango\python_django\mysite\shopapp\views.py changed, reloading."
INFO level - 2024-01-25 22:18:58,315 django.utils.autoreload: "Watching for file changes with StatReloader"
WARNING level - 2024-01-25 22:22:51,814 django.request: "Not Found: /ru/shop/users/11/orders/export/"
WARNING level - 2024-01-25 22:22:56,722 django.request: "Not Found: /ru/shop/users/11/orders/"
WARNING level - 2024-01-25 22:22:57,297 django.request: "Not Found: /ru/shop/users/11/orders/"
INFO level - 2024-01-25 22:23:17,577 django.utils.autoreload: "C:\Users\kurba\PycharmProjects\AnotherDjango\python_django\mysite\shopapp\views.py changed, reloading."
INFO level - 2024-01-25 22:23:18,270 django.utils.autoreload: "Watching for file changes with StatReloader"
INFO level - 2024-01-25 22:25:51,133 django.utils.autoreload: "C:\Users\kurba\PycharmProjects\AnotherDjango\python_django\mysite\shopapp\serializers.py changed, reloading."
INFO level - 2024-01-25 22:25:51,736 django.utils.autoreload: "Watching for file changes with StatReloader"
